 * Running on http://0.0.0.0:5000/ (Press CTRL+C to quit)
 * Restarting with stat
 * Debugger is active!
 * Debugger PIN: 135-965-059
106.51.138.58 - - [04/Jun/2017 01:12:39] "GET / HTTP/1.1" 200 -
 * Detected change in '/var/www/apps/restserver/app/user/controllers.py', reloading
 * Restarting with stat
 * Debugger is active!
 * Debugger PIN: 135-965-059
 * Detected change in '/var/www/apps/restserver/app/__init__.py', reloading
 * Restarting with stat
Traceback (most recent call last):
  File "run.py", line 1, in <module>
    from app import app
  File "/var/www/apps/restserver/app/__init__.py", line 5, in <module>
    app.config.from_object('config')
NameError: name 'app' is not defined
 * Running on http://0.0.0.0:5000/ (Press CTRL+C to quit)
 * Restarting with stat
 * Debugger is active!
 * Debugger PIN: 135-965-059
 * Detected change in '/var/www/apps/restserver/app/__init__.py', reloading
 * Restarting with stat
 * Debugger is active!
 * Debugger PIN: 135-965-059
 * Detected change in '/var/www/apps/restserver/app/user/controllers.py', reloading
 * Restarting with stat
 * Debugger is active!
 * Debugger PIN: 135-965-059
106.51.138.58 - - [04/Jun/2017 05:36:18] "GET / HTTP/1.1" 500 -
Traceback (most recent call last):
  File "/home/kallme/.local/lib/python3.5/site-packages/flask/app.py", line 1997, in __call__
    return self.wsgi_app(environ, start_response)
  File "/home/kallme/.local/lib/python3.5/site-packages/flask/app.py", line 1985, in wsgi_app
    response = self.handle_exception(e)
  File "/home/kallme/.local/lib/python3.5/site-packages/flask/app.py", line 1540, in handle_exception
    reraise(exc_type, exc_value, tb)
  File "/home/kallme/.local/lib/python3.5/site-packages/flask/_compat.py", line 33, in reraise
    raise value
  File "/home/kallme/.local/lib/python3.5/site-packages/flask/app.py", line 1982, in wsgi_app
    response = self.full_dispatch_request()
  File "/home/kallme/.local/lib/python3.5/site-packages/flask/app.py", line 1614, in full_dispatch_request
    rv = self.handle_user_exception(e)
  File "/home/kallme/.local/lib/python3.5/site-packages/flask/app.py", line 1517, in handle_user_exception
    reraise(exc_type, exc_value, tb)
  File "/home/kallme/.local/lib/python3.5/site-packages/flask/_compat.py", line 33, in reraise
    raise value
  File "/home/kallme/.local/lib/python3.5/site-packages/flask/app.py", line 1612, in full_dispatch_request
    rv = self.dispatch_request()
  File "/home/kallme/.local/lib/python3.5/site-packages/flask/app.py", line 1598, in dispatch_request
    return self.view_functions[rule.endpoint](**req.view_args)
  File "/var/www/apps/restserver/app/user/controllers.py", line 9, in index
    conn = mysql.connect()
NameError: name 'mysql' is not defined
106.51.138.58 - - [04/Jun/2017 05:36:18] "GET /?__debugger__=yes&cmd=resource&f=style.css HTTP/1.1" 200 -
106.51.138.58 - - [04/Jun/2017 05:36:18] "GET /?__debugger__=yes&cmd=resource&f=jquery.js HTTP/1.1" 200 -
106.51.138.58 - - [04/Jun/2017 05:36:19] "GET /?__debugger__=yes&cmd=resource&f=debugger.js HTTP/1.1" 200 -
 * Detected change in '/var/www/apps/restserver/app/user/controllers.py', reloading
 * Restarting with stat
 * Debugger is active!
 * Debugger PIN: 135-965-059
106.51.138.58 - - [04/Jun/2017 05:38:56] "GET /?__debugger__=yes&cmd=resource&f=ubuntu.ttf HTTP/1.1" 200 -
106.51.138.58 - - [04/Jun/2017 05:38:57] "GET /?__debugger__=yes&cmd=resource&f=console.png HTTP/1.1" 200 -
106.51.138.58 - - [04/Jun/2017 05:38:57] "GET /?__debugger__=yes&cmd=resource&f=console.png HTTP/1.1" 200 -
 * Detected change in '/var/www/apps/restserver/app/__init__.py', reloading
 * Restarting with stat
 * Debugger is active!
 * Debugger PIN: 135-965-059
 * Detected change in '/var/www/apps/restserver/app/__init__.py', reloading
 * Restarting with stat
 * Debugger is active!
 * Debugger PIN: 135-965-059
106.51.138.58 - - [04/Jun/2017 05:46:15] "GET / HTTP/1.1" 500 -
Traceback (most recent call last):
  File "/home/kallme/.local/lib/python3.5/site-packages/flask/app.py", line 1997, in __call__
    return self.wsgi_app(environ, start_response)
  File "/home/kallme/.local/lib/python3.5/site-packages/flask/app.py", line 1985, in wsgi_app
    response = self.handle_exception(e)
  File "/home/kallme/.local/lib/python3.5/site-packages/flask/app.py", line 1540, in handle_exception
    reraise(exc_type, exc_value, tb)
  File "/home/kallme/.local/lib/python3.5/site-packages/flask/_compat.py", line 33, in reraise
    raise value
  File "/home/kallme/.local/lib/python3.5/site-packages/flask/app.py", line 1982, in wsgi_app
    response = self.full_dispatch_request()
  File "/home/kallme/.local/lib/python3.5/site-packages/flask/app.py", line 1614, in full_dispatch_request
    rv = self.handle_user_exception(e)
  File "/home/kallme/.local/lib/python3.5/site-packages/flask/app.py", line 1517, in handle_user_exception
    reraise(exc_type, exc_value, tb)
  File "/home/kallme/.local/lib/python3.5/site-packages/flask/_compat.py", line 33, in reraise
    raise value
  File "/home/kallme/.local/lib/python3.5/site-packages/flask/app.py", line 1612, in full_dispatch_request
    rv = self.dispatch_request()
  File "/home/kallme/.local/lib/python3.5/site-packages/flask/app.py", line 1598, in dispatch_request
    return self.view_functions[rule.endpoint](**req.view_args)
  File "/var/www/apps/restserver/app/user/controllers.py", line 9, in index
    conn = mysql.connect()
NameError: name 'mysql' is not defined
106.51.138.58 - - [04/Jun/2017 05:46:16] "GET /?__debugger__=yes&cmd=resource&f=debugger.js HTTP/1.1" 200 -
106.51.138.58 - - [04/Jun/2017 05:46:16] "GET /?__debugger__=yes&cmd=resource&f=jquery.js HTTP/1.1" 200 -
106.51.138.58 - - [04/Jun/2017 05:46:55] "GET /?__debugger__=yes&cmd=resource&f=style.css HTTP/1.1" 200 -
106.51.138.58 - - [04/Jun/2017 05:46:55] "GET / HTTP/1.1" 500 -
Traceback (most recent call last):
  File "/home/kallme/.local/lib/python3.5/site-packages/flask/app.py", line 1997, in __call__
    return self.wsgi_app(environ, start_response)
  File "/home/kallme/.local/lib/python3.5/site-packages/flask/app.py", line 1985, in wsgi_app
    response = self.handle_exception(e)
  File "/home/kallme/.local/lib/python3.5/site-packages/flask/app.py", line 1540, in handle_exception
    reraise(exc_type, exc_value, tb)
  File "/home/kallme/.local/lib/python3.5/site-packages/flask/_compat.py", line 33, in reraise
    raise value
  File "/home/kallme/.local/lib/python3.5/site-packages/flask/app.py", line 1982, in wsgi_app
    response = self.full_dispatch_request()
  File "/home/kallme/.local/lib/python3.5/site-packages/flask/app.py", line 1614, in full_dispatch_request
    rv = self.handle_user_exception(e)
  File "/home/kallme/.local/lib/python3.5/site-packages/flask/app.py", line 1517, in handle_user_exception
    reraise(exc_type, exc_value, tb)
  File "/home/kallme/.local/lib/python3.5/site-packages/flask/_compat.py", line 33, in reraise
    raise value
  File "/home/kallme/.local/lib/python3.5/site-packages/flask/app.py", line 1612, in full_dispatch_request
    rv = self.dispatch_request()
  File "/home/kallme/.local/lib/python3.5/site-packages/flask/app.py", line 1598, in dispatch_request
    return self.view_functions[rule.endpoint](**req.view_args)
  File "/var/www/apps/restserver/app/user/controllers.py", line 9, in index
    conn = mysql.connect()
NameError: name 'mysql' is not defined
106.51.138.58 - - [04/Jun/2017 05:46:56] "GET /?__debugger__=yes&cmd=resource&f=debugger.js HTTP/1.1" 200 -
106.51.138.58 - - [04/Jun/2017 05:46:56] "GET /?__debugger__=yes&cmd=resource&f=style.css HTTP/1.1" 200 -
106.51.138.58 - - [04/Jun/2017 05:46:56] "GET /?__debugger__=yes&cmd=resource&f=jquery.js HTTP/1.1" 200 -
106.51.138.58 - - [04/Jun/2017 05:46:58] "GET /?__debugger__=yes&cmd=resource&f=ubuntu.ttf HTTP/1.1" 200 -
106.51.138.58 - - [04/Jun/2017 05:46:58] "GET /?__debugger__=yes&cmd=resource&f=console.png HTTP/1.1" 200 -
106.51.138.58 - - [04/Jun/2017 05:49:42] "GET /agent/ HTTP/1.1" 200 -
106.51.138.58 - - [04/Jun/2017 05:49:42] "GET / HTTP/1.1" 500 -
Traceback (most recent call last):
  File "/home/kallme/.local/lib/python3.5/site-packages/flask/app.py", line 1997, in __call__
    return self.wsgi_app(environ, start_response)
  File "/home/kallme/.local/lib/python3.5/site-packages/flask/app.py", line 1985, in wsgi_app
    response = self.handle_exception(e)
  File "/home/kallme/.local/lib/python3.5/site-packages/flask/app.py", line 1540, in handle_exception
    reraise(exc_type, exc_value, tb)
  File "/home/kallme/.local/lib/python3.5/site-packages/flask/_compat.py", line 33, in reraise
    raise value
  File "/home/kallme/.local/lib/python3.5/site-packages/flask/app.py", line 1982, in wsgi_app
    response = self.full_dispatch_request()
  File "/home/kallme/.local/lib/python3.5/site-packages/flask/app.py", line 1614, in full_dispatch_request
    rv = self.handle_user_exception(e)
  File "/home/kallme/.local/lib/python3.5/site-packages/flask/app.py", line 1517, in handle_user_exception
    reraise(exc_type, exc_value, tb)
  File "/home/kallme/.local/lib/python3.5/site-packages/flask/_compat.py", line 33, in reraise
    raise value
  File "/home/kallme/.local/lib/python3.5/site-packages/flask/app.py", line 1612, in full_dispatch_request
    rv = self.dispatch_request()
  File "/home/kallme/.local/lib/python3.5/site-packages/flask/app.py", line 1598, in dispatch_request
    return self.view_functions[rule.endpoint](**req.view_args)
  File "/var/www/apps/restserver/app/user/controllers.py", line 9, in index
    conn = mysql.connect()
NameError: name 'mysql' is not defined
106.51.138.58 - - [04/Jun/2017 05:49:43] "GET /?__debugger__=yes&cmd=resource&f=jquery.js HTTP/1.1" 200 -
106.51.138.58 - - [04/Jun/2017 05:49:44] "GET /?__debugger__=yes&cmd=resource&f=style.css HTTP/1.1" 200 -
106.51.138.58 - - [04/Jun/2017 05:49:44] "GET /?__debugger__=yes&cmd=resource&f=debugger.js HTTP/1.1" 200 -
106.51.138.58 - - [04/Jun/2017 05:49:45] "GET /?__debugger__=yes&cmd=resource&f=ubuntu.ttf HTTP/1.1" 200 -
106.51.138.58 - - [04/Jun/2017 05:49:46] "GET /?__debugger__=yes&cmd=resource&f=console.png HTTP/1.1" 200 -
 * Detected change in '/var/www/apps/restserver/app/user/controllers.py', reloading
 * Restarting with stat
 * Debugger is active!
 * Debugger PIN: 135-965-059
106.51.138.58 - - [04/Jun/2017 05:50:30] "GET / HTTP/1.1" 200 -
 * Detected change in '/var/www/apps/restserver/app/user/controllers.py', reloading
 * Restarting with stat
 * Debugger is active!
 * Debugger PIN: 135-965-059
 * Detected change in '/var/www/apps/restserver/app/agent/__init__.py', reloading
 * Restarting with stat
 * Debugger is active!
 * Debugger PIN: 135-965-059
 * Detected change in '/var/www/apps/restserver/app/__init__.py', reloading
 * Restarting with stat
 * Debugger is active!
 * Debugger PIN: 135-965-059
 * Detected change in '/var/www/apps/restserver/app/__init__.py', reloading
 * Restarting with stat
 * Debugger is active!
 * Debugger PIN: 135-965-059
 * Detected change in '/var/www/apps/restserver/app/__init__.py', reloading
 * Restarting with stat
 * Debugger is active!
 * Debugger PIN: 135-965-059
106.51.138.58 - - [04/Jun/2017 06:45:24] "GET / HTTP/1.1" 200 -
 * Detected change in '/var/www/apps/restserver/app/user/controllers.py', reloading
 * Restarting with stat
Traceback (most recent call last):
  File "run.py", line 1, in <module>
    from app import app
  File "/var/www/apps/restserver/app/__init__.py", line 4, in <module>
    from app.user.controllers import user
  File "/var/www/apps/restserver/app/user/controllers.py", line 13
    return "user" 
                 ^
TabError: inconsistent use of tabs and spaces in indentation
Traceback (most recent call last):
  File "run.py", line 1, in <module>
    from app import app
  File "/var/www/apps/restserver/app/__init__.py", line 4, in <module>
    from app.user.controllers import user
  File "/var/www/apps/restserver/app/user/controllers.py", line 3, in <module>
    from . models import *
  File "/var/www/apps/restserver/app/user/models.py", line 8
    return "test"	
                 ^
TabError: inconsistent use of tabs and spaces in indentation
Traceback (most recent call last):
  File "run.py", line 1, in <module>
    from app import app
  File "/var/www/apps/restserver/app/__init__.py", line 4, in <module>
    from app.user.controllers import user
  File "/var/www/apps/restserver/app/user/controllers.py", line 3, in <module>
    from . models import *
  File "/var/www/apps/restserver/app/user/models.py", line 8
    return "test"	
                 ^
TabError: inconsistent use of tabs and spaces in indentation
 * Running on http://0.0.0.0:5000/ (Press CTRL+C to quit)
 * Restarting with stat
 * Debugger is active!
 * Debugger PIN: 135-965-059
103.227.96.138 - - [10/Jun/2017 02:32:25] "GET /user/adduser HTTP/1.1" 500 -
Traceback (most recent call last):
  File "/home/kallme/.local/lib/python3.5/site-packages/flask/app.py", line 1997, in __call__
    return self.wsgi_app(environ, start_response)
  File "/home/kallme/.local/lib/python3.5/site-packages/flask/app.py", line 1985, in wsgi_app
    response = self.handle_exception(e)
  File "/home/kallme/.local/lib/python3.5/site-packages/flask/app.py", line 1540, in handle_exception
    reraise(exc_type, exc_value, tb)
  File "/home/kallme/.local/lib/python3.5/site-packages/flask/_compat.py", line 33, in reraise
    raise value
  File "/home/kallme/.local/lib/python3.5/site-packages/flask/app.py", line 1982, in wsgi_app
    response = self.full_dispatch_request()
  File "/home/kallme/.local/lib/python3.5/site-packages/flask/app.py", line 1615, in full_dispatch_request
    return self.finalize_request(rv)
  File "/home/kallme/.local/lib/python3.5/site-packages/flask/app.py", line 1630, in finalize_request
    response = self.make_response(rv)
  File "/home/kallme/.local/lib/python3.5/site-packages/flask/app.py", line 1725, in make_response
    raise ValueError('View function did not return a response')
ValueError: View function did not return a response
103.227.96.138 - - [10/Jun/2017 02:32:26] "GET /user/adduser?__debugger__=yes&cmd=resource&f=style.css HTTP/1.1" 200 -
103.227.96.138 - - [10/Jun/2017 02:32:26] "GET /user/adduser?__debugger__=yes&cmd=resource&f=jquery.js HTTP/1.1" 200 -
103.227.96.138 - - [10/Jun/2017 02:32:27] "GET /user/adduser?__debugger__=yes&cmd=resource&f=debugger.js HTTP/1.1" 200 -
103.227.96.138 - - [10/Jun/2017 02:32:29] "GET /user/adduser?__debugger__=yes&cmd=resource&f=ubuntu.ttf HTTP/1.1" 200 -
103.227.96.138 - - [10/Jun/2017 02:32:30] "GET /user/adduser?__debugger__=yes&cmd=resource&f=console.png HTTP/1.1" 200 -
 * Detected change in '/var/www/apps/restserver/app/user/models.py', reloading
test
 * Restarting with stat
 * Debugger is active!
 * Debugger PIN: 135-965-059
103.227.96.138 - - [10/Jun/2017 02:35:35] "GET /user/adduser HTTP/1.1" 500 -
Traceback (most recent call last):
  File "/home/kallme/.local/lib/python3.5/site-packages/flask/app.py", line 1997, in __call__
    return self.wsgi_app(environ, start_response)
  File "/home/kallme/.local/lib/python3.5/site-packages/flask/app.py", line 1985, in wsgi_app
    response = self.handle_exception(e)
  File "/home/kallme/.local/lib/python3.5/site-packages/flask/app.py", line 1540, in handle_exception
    reraise(exc_type, exc_value, tb)
  File "/home/kallme/.local/lib/python3.5/site-packages/flask/_compat.py", line 33, in reraise
    raise value
  File "/home/kallme/.local/lib/python3.5/site-packages/flask/app.py", line 1982, in wsgi_app
    response = self.full_dispatch_request()
  File "/home/kallme/.local/lib/python3.5/site-packages/flask/app.py", line 1615, in full_dispatch_request
    return self.finalize_request(rv)
  File "/home/kallme/.local/lib/python3.5/site-packages/flask/app.py", line 1630, in finalize_request
    response = self.make_response(rv)
  File "/home/kallme/.local/lib/python3.5/site-packages/flask/app.py", line 1725, in make_response
    raise ValueError('View function did not return a response')
ValueError: View function did not return a response
103.227.96.138 - - [10/Jun/2017 02:35:35] "GET /user/adduser HTTP/1.1" 500 -
Traceback (most recent call last):
  File "/home/kallme/.local/lib/python3.5/site-packages/flask/app.py", line 1997, in __call__
    return self.wsgi_app(environ, start_response)
  File "/home/kallme/.local/lib/python3.5/site-packages/flask/app.py", line 1985, in wsgi_app
    response = self.handle_exception(e)
  File "/home/kallme/.local/lib/python3.5/site-packages/flask/app.py", line 1540, in handle_exception
    reraise(exc_type, exc_value, tb)
  File "/home/kallme/.local/lib/python3.5/site-packages/flask/_compat.py", line 33, in reraise
    raise value
  File "/home/kallme/.local/lib/python3.5/site-packages/flask/app.py", line 1982, in wsgi_app
    response = self.full_dispatch_request()
  File "/home/kallme/.local/lib/python3.5/site-packages/flask/app.py", line 1615, in full_dispatch_request
    return self.finalize_request(rv)
  File "/home/kallme/.local/lib/python3.5/site-packages/flask/app.py", line 1630, in finalize_request
    response = self.make_response(rv)
  File "/home/kallme/.local/lib/python3.5/site-packages/flask/app.py", line 1725, in make_response
    raise ValueError('View function did not return a response')
ValueError: View function did not return a response
103.227.96.138 - - [10/Jun/2017 02:35:36] "GET /user/adduser?__debugger__=yes&cmd=resource&f=style.css HTTP/1.1" 200 -
103.227.96.138 - - [10/Jun/2017 02:35:37] "GET /user/adduser?__debugger__=yes&cmd=resource&f=jquery.js HTTP/1.1" 200 -
103.227.96.138 - - [10/Jun/2017 02:35:38] "GET /user/adduser?__debugger__=yes&cmd=resource&f=debugger.js HTTP/1.1" 200 -
103.227.96.138 - - [10/Jun/2017 02:35:40] "GET /user/adduser?__debugger__=yes&cmd=resource&f=ubuntu.ttf HTTP/1.1" 200 -
103.227.96.138 - - [10/Jun/2017 02:35:41] "GET /user/adduser?__debugger__=yes&cmd=resource&f=console.png HTTP/1.1" 200 -
 * Detected change in '/var/www/apps/restserver/app/user/models.py', reloading
 * Restarting with stat
 * Debugger is active!
 * Debugger PIN: 135-965-059
103.227.96.138 - - [10/Jun/2017 02:37:18] "GET /user/adduser HTTP/1.1" 500 -
Traceback (most recent call last):
  File "/home/kallme/.local/lib/python3.5/site-packages/flask/app.py", line 1997, in __call__
    return self.wsgi_app(environ, start_response)
  File "/home/kallme/.local/lib/python3.5/site-packages/flask/app.py", line 1985, in wsgi_app
    response = self.handle_exception(e)
  File "/home/kallme/.local/lib/python3.5/site-packages/flask/app.py", line 1540, in handle_exception
    reraise(exc_type, exc_value, tb)
  File "/home/kallme/.local/lib/python3.5/site-packages/flask/_compat.py", line 33, in reraise
    raise value
  File "/home/kallme/.local/lib/python3.5/site-packages/flask/app.py", line 1982, in wsgi_app
    response = self.full_dispatch_request()
  File "/home/kallme/.local/lib/python3.5/site-packages/flask/app.py", line 1615, in full_dispatch_request
    return self.finalize_request(rv)
  File "/home/kallme/.local/lib/python3.5/site-packages/flask/app.py", line 1630, in finalize_request
    response = self.make_response(rv)
  File "/home/kallme/.local/lib/python3.5/site-packages/flask/app.py", line 1725, in make_response
    raise ValueError('View function did not return a response')
ValueError: View function did not return a response
103.227.96.138 - - [10/Jun/2017 02:37:20] "GET /user/adduser?__debugger__=yes&cmd=resource&f=style.css HTTP/1.1" 200 -
103.227.96.138 - - [10/Jun/2017 02:37:20] "GET /user/adduser?__debugger__=yes&cmd=resource&f=jquery.js HTTP/1.1" 200 -
103.227.96.138 - - [10/Jun/2017 02:37:21] "GET /user/adduser?__debugger__=yes&cmd=resource&f=debugger.js HTTP/1.1" 200 -
103.227.96.138 - - [10/Jun/2017 02:37:22] "GET /user/adduser?__debugger__=yes&cmd=resource&f=ubuntu.ttf HTTP/1.1" 200 -
103.227.96.138 - - [10/Jun/2017 02:37:33] "GET /user/adduser?__debugger__=yes&cmd=resource&f=console.png HTTP/1.1" 200 -
103.227.96.138 - - [10/Jun/2017 02:37:37] "GET /user/adduser?__debugger__=yes&cmd=resource&f=console.png HTTP/1.1" 200 -
 * Detected change in '/var/www/apps/restserver/app/user/models.py', reloading
 * Restarting with stat
 * Debugger is active!
 * Debugger PIN: 135-965-059
 * Detected change in '/var/www/apps/restserver/connection.py', reloading
 * Restarting with stat
 * Debugger is active!
 * Debugger PIN: 135-965-059
 * Detected change in '/var/www/apps/restserver/app/user/models.py', reloading
 * Restarting with stat
 * Debugger is active!
 * Debugger PIN: 135-965-059
103.227.96.138 - - [10/Jun/2017 02:42:50] "GET /user/adduser HTTP/1.1" 500 -
Traceback (most recent call last):
  File "/home/kallme/.local/lib/python3.5/site-packages/flask/app.py", line 1997, in __call__
    return self.wsgi_app(environ, start_response)
  File "/home/kallme/.local/lib/python3.5/site-packages/flask/app.py", line 1985, in wsgi_app
    response = self.handle_exception(e)
  File "/home/kallme/.local/lib/python3.5/site-packages/flask/app.py", line 1540, in handle_exception
    reraise(exc_type, exc_value, tb)
  File "/home/kallme/.local/lib/python3.5/site-packages/flask/_compat.py", line 33, in reraise
    raise value
  File "/home/kallme/.local/lib/python3.5/site-packages/flask/app.py", line 1982, in wsgi_app
    response = self.full_dispatch_request()
  File "/home/kallme/.local/lib/python3.5/site-packages/flask/app.py", line 1615, in full_dispatch_request
    return self.finalize_request(rv)
  File "/home/kallme/.local/lib/python3.5/site-packages/flask/app.py", line 1630, in finalize_request
    response = self.make_response(rv)
  File "/home/kallme/.local/lib/python3.5/site-packages/flask/app.py", line 1725, in make_response
    raise ValueError('View function did not return a response')
ValueError: View function did not return a response
103.227.96.138 - - [10/Jun/2017 02:42:51] "GET /user/adduser?__debugger__=yes&cmd=resource&f=style.css HTTP/1.1" 200 -
103.227.96.138 - - [10/Jun/2017 02:42:51] "GET /user/adduser?__debugger__=yes&cmd=resource&f=jquery.js HTTP/1.1" 200 -
103.227.96.138 - - [10/Jun/2017 02:42:52] "GET /user/adduser?__debugger__=yes&cmd=resource&f=debugger.js HTTP/1.1" 200 -
103.227.96.138 - - [10/Jun/2017 02:42:53] "GET /user/adduser?__debugger__=yes&cmd=resource&f=ubuntu.ttf HTTP/1.1" 200 -
103.227.96.138 - - [10/Jun/2017 02:42:54] "GET /user/adduser?__debugger__=yes&cmd=resource&f=console.png HTTP/1.1" 200 -
 * Detected change in '/var/www/apps/restserver/app/user/models.py', reloading
 * Restarting with stat
 * Debugger is active!
 * Debugger PIN: 135-965-059
103.227.96.138 - - [10/Jun/2017 02:44:00] "GET /user/adduser HTTP/1.1" 500 -
Traceback (most recent call last):
  File "/home/kallme/.local/lib/python3.5/site-packages/flask/app.py", line 1997, in __call__
    return self.wsgi_app(environ, start_response)
  File "/home/kallme/.local/lib/python3.5/site-packages/flask/app.py", line 1985, in wsgi_app
    response = self.handle_exception(e)
  File "/home/kallme/.local/lib/python3.5/site-packages/flask/app.py", line 1540, in handle_exception
    reraise(exc_type, exc_value, tb)
  File "/home/kallme/.local/lib/python3.5/site-packages/flask/_compat.py", line 33, in reraise
    raise value
  File "/home/kallme/.local/lib/python3.5/site-packages/flask/app.py", line 1982, in wsgi_app
    response = self.full_dispatch_request()
  File "/home/kallme/.local/lib/python3.5/site-packages/flask/app.py", line 1615, in full_dispatch_request
    return self.finalize_request(rv)
  File "/home/kallme/.local/lib/python3.5/site-packages/flask/app.py", line 1630, in finalize_request
    response = self.make_response(rv)
  File "/home/kallme/.local/lib/python3.5/site-packages/flask/app.py", line 1725, in make_response
    raise ValueError('View function did not return a response')
ValueError: View function did not return a response
103.227.96.138 - - [10/Jun/2017 02:44:01] "GET /user/adduser?__debugger__=yes&cmd=resource&f=jquery.js HTTP/1.1" 200 -
103.227.96.138 - - [10/Jun/2017 02:44:03] "GET /user/adduser?__debugger__=yes&cmd=resource&f=style.css HTTP/1.1" 200 -
103.227.96.138 - - [10/Jun/2017 02:44:03] "GET /user/adduser?__debugger__=yes&cmd=resource&f=debugger.js HTTP/1.1" 200 -
103.227.96.138 - - [10/Jun/2017 02:44:04] "GET /user/adduser?__debugger__=yes&cmd=resource&f=ubuntu.ttf HTTP/1.1" 200 -
103.227.96.138 - - [10/Jun/2017 02:44:05] "GET /user/adduser?__debugger__=yes&cmd=resource&f=console.png HTTP/1.1" 200 -
103.227.96.138 - - [10/Jun/2017 02:44:07] "GET /user/adduser?__debugger__=yes&cmd=resource&f=console.png HTTP/1.1" 200 -
 * Detected change in '/var/www/apps/restserver/app/user/models.py', reloading
 * Restarting with stat
 * Debugger is active!
 * Debugger PIN: 135-965-059
 * Detected change in '/var/www/apps/restserver/app/user/controllers.py', reloading
 * Restarting with stat
 * Debugger is active!
 * Debugger PIN: 135-965-059
103.227.96.138 - - [10/Jun/2017 02:45:02] "GET /user/adduser HTTP/1.1" 500 -
Traceback (most recent call last):
  File "/home/kallme/.local/lib/python3.5/site-packages/flask/app.py", line 1997, in __call__
    return self.wsgi_app(environ, start_response)
  File "/home/kallme/.local/lib/python3.5/site-packages/flask/app.py", line 1985, in wsgi_app
    response = self.handle_exception(e)
  File "/home/kallme/.local/lib/python3.5/site-packages/flask/app.py", line 1540, in handle_exception
    reraise(exc_type, exc_value, tb)
  File "/home/kallme/.local/lib/python3.5/site-packages/flask/_compat.py", line 33, in reraise
    raise value
  File "/home/kallme/.local/lib/python3.5/site-packages/flask/app.py", line 1982, in wsgi_app
    response = self.full_dispatch_request()
  File "/home/kallme/.local/lib/python3.5/site-packages/flask/app.py", line 1615, in full_dispatch_request
    return self.finalize_request(rv)
  File "/home/kallme/.local/lib/python3.5/site-packages/flask/app.py", line 1630, in finalize_request
    response = self.make_response(rv)
  File "/home/kallme/.local/lib/python3.5/site-packages/flask/app.py", line 1725, in make_response
    raise ValueError('View function did not return a response')
ValueError: View function did not return a response
103.227.96.138 - - [10/Jun/2017 02:45:03] "GET /user/adduser?__debugger__=yes&cmd=resource&f=jquery.js HTTP/1.1" 200 -
103.227.96.138 - - [10/Jun/2017 02:45:04] "GET /user/adduser?__debugger__=yes&cmd=resource&f=style.css HTTP/1.1" 200 -
103.227.96.138 - - [10/Jun/2017 02:45:04] "GET /user/adduser?__debugger__=yes&cmd=resource&f=debugger.js HTTP/1.1" 200 -
103.227.96.138 - - [10/Jun/2017 02:45:05] "GET /user/adduser?__debugger__=yes&cmd=resource&f=ubuntu.ttf HTTP/1.1" 200 -
103.227.96.138 - - [10/Jun/2017 02:45:06] "GET /user/adduser?__debugger__=yes&cmd=resource&f=console.png HTTP/1.1" 200 -
103.227.96.138 - - [10/Jun/2017 02:45:10] "GET /user/adduser HTTP/1.1" 500 -
Traceback (most recent call last):
  File "/home/kallme/.local/lib/python3.5/site-packages/flask/app.py", line 1997, in __call__
    return self.wsgi_app(environ, start_response)
  File "/home/kallme/.local/lib/python3.5/site-packages/flask/app.py", line 1985, in wsgi_app
    response = self.handle_exception(e)
  File "/home/kallme/.local/lib/python3.5/site-packages/flask/app.py", line 1540, in handle_exception
    reraise(exc_type, exc_value, tb)
  File "/home/kallme/.local/lib/python3.5/site-packages/flask/_compat.py", line 33, in reraise
    raise value
  File "/home/kallme/.local/lib/python3.5/site-packages/flask/app.py", line 1982, in wsgi_app
    response = self.full_dispatch_request()
  File "/home/kallme/.local/lib/python3.5/site-packages/flask/app.py", line 1614, in full_dispatch_request
    rv = self.handle_user_exception(e)
  File "/home/kallme/.local/lib/python3.5/site-packages/flask/app.py", line 1517, in handle_user_exception
    reraise(exc_type, exc_value, tb)
  File "/home/kallme/.local/lib/python3.5/site-packages/flask/_compat.py", line 33, in reraise
    raise value
  File "/home/kallme/.local/lib/python3.5/site-packages/flask/app.py", line 1612, in full_dispatch_request
    rv = self.dispatch_request()
  File "/home/kallme/.local/lib/python3.5/site-packages/flask/app.py", line 1598, in dispatch_request
    return self.view_functions[rule.endpoint](**req.view_args)
  File "/var/www/apps/restserver/app/user/controllers.py", line 9, in index
    adduser()
  File "/var/www/apps/restserver/app/user/models.py", line 7, in adduser
    cur = cursor.execute("INSERT INTO user VALUES('ritesh','demo','ritesh.dobhal@glassbeam.com','Ritesh','Dobhal')")
  File "/home/kallme/.local/lib/python3.5/site-packages/pymysql/cursors.py", line 166, in execute
    result = self._query(query)
  File "/home/kallme/.local/lib/python3.5/site-packages/pymysql/cursors.py", line 322, in _query
    conn.query(q)
  File "/home/kallme/.local/lib/python3.5/site-packages/pymysql/connections.py", line 855, in query
    self._execute_command(COMMAND.COM_QUERY, sql)
  File "/home/kallme/.local/lib/python3.5/site-packages/pymysql/connections.py", line 1071, in _execute_command
    raise err.InterfaceError("(0, '')")
pymysql.err.InterfaceError: (0, '')
103.227.96.138 - - [10/Jun/2017 02:45:11] "GET /user/adduser?__debugger__=yes&cmd=resource&f=style.css HTTP/1.1" 200 -
103.227.96.138 - - [10/Jun/2017 02:45:11] "GET /user/adduser?__debugger__=yes&cmd=resource&f=jquery.js HTTP/1.1" 200 -
103.227.96.138 - - [10/Jun/2017 02:45:13] "GET /user/adduser?__debugger__=yes&cmd=resource&f=debugger.js HTTP/1.1" 200 -
103.227.96.138 - - [10/Jun/2017 02:45:15] "GET /user/adduser?__debugger__=yes&cmd=resource&f=console.png HTTP/1.1" 200 -
103.227.96.138 - - [10/Jun/2017 02:45:15] "GET /user/adduser?__debugger__=yes&cmd=resource&f=ubuntu.ttf HTTP/1.1" 200 -
103.227.96.138 - - [10/Jun/2017 02:45:17] "GET /user/adduser?__debugger__=yes&cmd=resource&f=console.png HTTP/1.1" 200 -
103.227.96.138 - - [10/Jun/2017 02:45:23] "GET /user/adduser HTTP/1.1" 500 -
Traceback (most recent call last):
  File "/home/kallme/.local/lib/python3.5/site-packages/flask/app.py", line 1997, in __call__
    return self.wsgi_app(environ, start_response)
  File "/home/kallme/.local/lib/python3.5/site-packages/flask/app.py", line 1985, in wsgi_app
    response = self.handle_exception(e)
  File "/home/kallme/.local/lib/python3.5/site-packages/flask/app.py", line 1540, in handle_exception
    reraise(exc_type, exc_value, tb)
  File "/home/kallme/.local/lib/python3.5/site-packages/flask/_compat.py", line 33, in reraise
    raise value
  File "/home/kallme/.local/lib/python3.5/site-packages/flask/app.py", line 1982, in wsgi_app
    response = self.full_dispatch_request()
  File "/home/kallme/.local/lib/python3.5/site-packages/flask/app.py", line 1614, in full_dispatch_request
    rv = self.handle_user_exception(e)
  File "/home/kallme/.local/lib/python3.5/site-packages/flask/app.py", line 1517, in handle_user_exception
    reraise(exc_type, exc_value, tb)
  File "/home/kallme/.local/lib/python3.5/site-packages/flask/_compat.py", line 33, in reraise
    raise value
  File "/home/kallme/.local/lib/python3.5/site-packages/flask/app.py", line 1612, in full_dispatch_request
    rv = self.dispatch_request()
  File "/home/kallme/.local/lib/python3.5/site-packages/flask/app.py", line 1598, in dispatch_request
    return self.view_functions[rule.endpoint](**req.view_args)
  File "/var/www/apps/restserver/app/user/controllers.py", line 9, in index
    adduser()
  File "/var/www/apps/restserver/app/user/models.py", line 7, in adduser
    cur = cursor.execute("INSERT INTO user VALUES('ritesh','demo','ritesh.dobhal@glassbeam.com','Ritesh','Dobhal')")
  File "/home/kallme/.local/lib/python3.5/site-packages/pymysql/cursors.py", line 166, in execute
    result = self._query(query)
  File "/home/kallme/.local/lib/python3.5/site-packages/pymysql/cursors.py", line 322, in _query
    conn.query(q)
  File "/home/kallme/.local/lib/python3.5/site-packages/pymysql/connections.py", line 855, in query
    self._execute_command(COMMAND.COM_QUERY, sql)
  File "/home/kallme/.local/lib/python3.5/site-packages/pymysql/connections.py", line 1071, in _execute_command
    raise err.InterfaceError("(0, '')")
pymysql.err.InterfaceError: (0, '')
103.227.96.138 - - [10/Jun/2017 02:45:24] "GET /user/adduser?__debugger__=yes&cmd=resource&f=jquery.js HTTP/1.1" 200 -
103.227.96.138 - - [10/Jun/2017 02:45:25] "GET /user/adduser?__debugger__=yes&cmd=resource&f=style.css HTTP/1.1" 200 -
103.227.96.138 - - [10/Jun/2017 02:45:25] "GET /user/adduser?__debugger__=yes&cmd=resource&f=debugger.js HTTP/1.1" 200 -
103.227.96.138 - - [10/Jun/2017 02:45:27] "GET /user/adduser?__debugger__=yes&cmd=resource&f=ubuntu.ttf HTTP/1.1" 200 -
103.227.96.138 - - [10/Jun/2017 02:45:28] "GET /user/adduser?__debugger__=yes&cmd=resource&f=console.png HTTP/1.1" 200 -
103.227.96.138 - - [10/Jun/2017 02:45:30] "GET /user/adduser?__debugger__=yes&cmd=resource&f=console.png HTTP/1.1" 200 -
 * Detected change in '/var/www/apps/restserver/app/user/controllers.py', reloading
User added
 * Restarting with stat
 * Debugger is active!
 * Debugger PIN: 135-965-059
103.227.96.138 - - [10/Jun/2017 02:47:20] "GET /user/adduser HTTP/1.1" 500 -
Traceback (most recent call last):
  File "/home/kallme/.local/lib/python3.5/site-packages/flask/app.py", line 1997, in __call__
    return self.wsgi_app(environ, start_response)
  File "/home/kallme/.local/lib/python3.5/site-packages/flask/app.py", line 1985, in wsgi_app
    response = self.handle_exception(e)
  File "/home/kallme/.local/lib/python3.5/site-packages/flask/app.py", line 1540, in handle_exception
    reraise(exc_type, exc_value, tb)
  File "/home/kallme/.local/lib/python3.5/site-packages/flask/_compat.py", line 33, in reraise
    raise value
  File "/home/kallme/.local/lib/python3.5/site-packages/flask/app.py", line 1982, in wsgi_app
    response = self.full_dispatch_request()
  File "/home/kallme/.local/lib/python3.5/site-packages/flask/app.py", line 1615, in full_dispatch_request
    return self.finalize_request(rv)
  File "/home/kallme/.local/lib/python3.5/site-packages/flask/app.py", line 1630, in finalize_request
    response = self.make_response(rv)
  File "/home/kallme/.local/lib/python3.5/site-packages/flask/app.py", line 1725, in make_response
    raise ValueError('View function did not return a response')
ValueError: View function did not return a response
103.227.96.138 - - [10/Jun/2017 02:47:21] "GET /user/adduser?__debugger__=yes&cmd=resource&f=style.css HTTP/1.1" 200 -
103.227.96.138 - - [10/Jun/2017 02:47:21] "GET /user/adduser?__debugger__=yes&cmd=resource&f=jquery.js HTTP/1.1" 200 -
103.227.96.138 - - [10/Jun/2017 02:47:23] "GET /user/adduser?__debugger__=yes&cmd=resource&f=debugger.js HTTP/1.1" 200 -
103.227.96.138 - - [10/Jun/2017 02:47:24] "GET /user/adduser?__debugger__=yes&cmd=resource&f=console.png HTTP/1.1" 200 -
103.227.96.138 - - [10/Jun/2017 02:47:24] "GET /user/adduser?__debugger__=yes&cmd=resource&f=ubuntu.ttf HTTP/1.1" 200 -
103.227.96.138 - - [10/Jun/2017 02:47:32] "GET /user/adduser HTTP/1.1" 500 -
Traceback (most recent call last):
  File "/home/kallme/.local/lib/python3.5/site-packages/flask/app.py", line 1997, in __call__
    return self.wsgi_app(environ, start_response)
  File "/home/kallme/.local/lib/python3.5/site-packages/flask/app.py", line 1985, in wsgi_app
    response = self.handle_exception(e)
  File "/home/kallme/.local/lib/python3.5/site-packages/flask/app.py", line 1540, in handle_exception
    reraise(exc_type, exc_value, tb)
  File "/home/kallme/.local/lib/python3.5/site-packages/flask/_compat.py", line 33, in reraise
    raise value
  File "/home/kallme/.local/lib/python3.5/site-packages/flask/app.py", line 1982, in wsgi_app
    response = self.full_dispatch_request()
  File "/home/kallme/.local/lib/python3.5/site-packages/flask/app.py", line 1614, in full_dispatch_request
    rv = self.handle_user_exception(e)
  File "/home/kallme/.local/lib/python3.5/site-packages/flask/app.py", line 1517, in handle_user_exception
    reraise(exc_type, exc_value, tb)
  File "/home/kallme/.local/lib/python3.5/site-packages/flask/_compat.py", line 33, in reraise
    raise value
  File "/home/kallme/.local/lib/python3.5/site-packages/flask/app.py", line 1612, in full_dispatch_request
    rv = self.dispatch_request()
  File "/home/kallme/.local/lib/python3.5/site-packages/flask/app.py", line 1598, in dispatch_request
    return self.view_functions[rule.endpoint](**req.view_args)
  File "/var/www/apps/restserver/app/user/controllers.py", line 9, in index
    adduser()
  File "/var/www/apps/restserver/app/user/models.py", line 7, in adduser
    cur = cursor.execute("INSERT INTO user VALUES('ritesh','demo','ritesh.dobhal@glassbeam.com','Ritesh','Dobhal')")
  File "/home/kallme/.local/lib/python3.5/site-packages/pymysql/cursors.py", line 166, in execute
    result = self._query(query)
  File "/home/kallme/.local/lib/python3.5/site-packages/pymysql/cursors.py", line 322, in _query
    conn.query(q)
  File "/home/kallme/.local/lib/python3.5/site-packages/pymysql/connections.py", line 855, in query
    self._execute_command(COMMAND.COM_QUERY, sql)
  File "/home/kallme/.local/lib/python3.5/site-packages/pymysql/connections.py", line 1071, in _execute_command
    raise err.InterfaceError("(0, '')")
pymysql.err.InterfaceError: (0, '')
103.227.96.138 - - [10/Jun/2017 02:47:33] "GET /user/adduser?__debugger__=yes&cmd=resource&f=style.css HTTP/1.1" 200 -
103.227.96.138 - - [10/Jun/2017 02:47:33] "GET /user/adduser?__debugger__=yes&cmd=resource&f=jquery.js HTTP/1.1" 200 -
 * Detected change in '/var/www/apps/restserver/app/user/controllers.py', reloading
User added
 * Restarting with stat
 * Debugger is active!
 * Debugger PIN: 135-965-059
103.227.96.138 - - [10/Jun/2017 02:48:23] "GET /user/adduser?__debugger__=yes&cmd=resource&f=debugger.js HTTP/1.1" 200 -
103.227.96.138 - - [10/Jun/2017 02:48:24] "GET /user/adduser?__debugger__=yes&cmd=resource&f=ubuntu.ttf HTTP/1.1" 200 -
103.227.96.138 - - [10/Jun/2017 02:48:25] "GET /user/adduser?__debugger__=yes&cmd=resource&f=console.png HTTP/1.1" 200 -
103.227.96.138 - - [10/Jun/2017 02:48:26] "GET /user/adduser?__debugger__=yes&cmd=resource&f=console.png HTTP/1.1" 200 -
103.227.96.138 - - [10/Jun/2017 02:48:53] "GET /user/adduser HTTP/1.1" 200 -
 * Detected change in '/var/www/apps/restserver/app/user/models.py', reloading
 * Restarting with stat
 * Debugger is active!
 * Debugger PIN: 135-965-059
 * Detected change in '/var/www/apps/restserver/app/user/models.py', reloading
 * Restarting with stat
 * Debugger is active!
 * Debugger PIN: 135-965-059
 * Detected change in '/var/www/apps/restserver/app/user/controllers.py', reloading
 * Restarting with stat
 * Debugger is active!
 * Debugger PIN: 135-965-059
 * Detected change in '/var/www/apps/restserver/app/user/controllers.py', reloading
 * Restarting with stat
 * Debugger is active!
 * Debugger PIN: 135-965-059
 * Detected change in '/var/www/apps/restserver/app/user/models.py', reloading
 * Restarting with stat
 * Debugger is active!
 * Debugger PIN: 135-965-059
 * Detected change in '/var/www/apps/restserver/run.py', reloading
 * Restarting with stat
 * Debugger is active!
 * Debugger PIN: 135-965-059
 * Detected change in '/var/www/apps/restserver/run.py', reloading
 * Restarting with stat
 * Debugger is active!
 * Debugger PIN: 135-965-059
 * Detected change in '/var/www/apps/restserver/config.py', reloading
 * Restarting with stat
 * Debugger is active!
 * Debugger PIN: 135-965-059
 * Detected change in '/var/www/apps/restserver/connection.py', reloading
 * Restarting with stat
 * Debugger is active!
 * Debugger PIN: 135-965-059
 * Detected change in '/var/www/apps/restserver/app/user/controllers.py', reloading
 * Restarting with stat
 * Debugger is active!
 * Debugger PIN: 135-965-059
 * Detected change in '/var/www/apps/restserver/app/user/controllers.py', reloading
 * Restarting with stat
 * Debugger is active!
 * Debugger PIN: 135-965-059
 * Detected change in '/var/www/apps/restserver/app/user/controllers.py', reloading
 * Restarting with stat
 * Debugger is active!
 * Debugger PIN: 135-965-059
 * Detected change in '/var/www/apps/restserver/app/user/models.py', reloading
 * Restarting with stat
Traceback (most recent call last):
  File "run.py", line 1, in <module>
    from app import app
  File "/var/www/apps/restserver/app/__init__.py", line 4, in <module>
    from app.user.controllers import user
  File "/var/www/apps/restserver/app/user/controllers.py", line 3, in <module>
    from . models import *
  File "/var/www/apps/restserver/app/user/models.py", line 3, in <module>
    from db import *
ImportError: No module named 'db'
 * Running on http://0.0.0.0:5000/ (Press CTRL+C to quit)
 * Restarting with stat
 * Debugger is active!
 * Debugger PIN: 135-965-059
 * Detected change in '/var/www/apps/restserver/app/user/models.py', reloading
 * Restarting with stat
Traceback (most recent call last):
  File "run.py", line 1, in <module>
    from app import app
  File "/var/www/apps/restserver/app/__init__.py", line 4, in <module>
    from app.user.controllers import user
  File "/var/www/apps/restserver/app/user/controllers.py", line 3, in <module>
    from . models import *
  File "/var/www/apps/restserver/app/user/models.py", line 8
    "INSERT INTO account_holder (email,username,phone,password) VALUES (?,?,?,?)", (email,username,phone,password))
                                                                                                                  ^
SyntaxError: invalid syntax
 * Running on http://0.0.0.0:5000/ (Press CTRL+C to quit)
 * Restarting with stat
 * Debugger is active!
 * Debugger PIN: 135-965-059
106.51.138.236 - - [10/Jun/2017 07:18:01] "GET /user/add?username=ritesh HTTP/1.1" 500 -
Traceback (most recent call last):
  File "/home/kallme/.local/lib/python3.5/site-packages/flask/app.py", line 1997, in __call__
    return self.wsgi_app(environ, start_response)
  File "/home/kallme/.local/lib/python3.5/site-packages/flask/app.py", line 1985, in wsgi_app
    response = self.handle_exception(e)
  File "/home/kallme/.local/lib/python3.5/site-packages/flask/app.py", line 1540, in handle_exception
    reraise(exc_type, exc_value, tb)
  File "/home/kallme/.local/lib/python3.5/site-packages/flask/_compat.py", line 33, in reraise
    raise value
  File "/home/kallme/.local/lib/python3.5/site-packages/flask/app.py", line 1982, in wsgi_app
    response = self.full_dispatch_request()
  File "/home/kallme/.local/lib/python3.5/site-packages/flask/app.py", line 1614, in full_dispatch_request
    rv = self.handle_user_exception(e)
  File "/home/kallme/.local/lib/python3.5/site-packages/flask/app.py", line 1517, in handle_user_exception
    reraise(exc_type, exc_value, tb)
  File "/home/kallme/.local/lib/python3.5/site-packages/flask/_compat.py", line 33, in reraise
    raise value
  File "/home/kallme/.local/lib/python3.5/site-packages/flask/app.py", line 1612, in full_dispatch_request
    rv = self.dispatch_request()
  File "/home/kallme/.local/lib/python3.5/site-packages/flask/app.py", line 1598, in dispatch_request
    return self.view_functions[rule.endpoint](**req.view_args)
  File "/var/www/apps/restserver/app/user/controllers.py", line 10, in add
    adddb(params)
  File "/var/www/apps/restserver/app/user/models.py", line 8, in adddb
    cur = cursor.execute("INSERT INTO user (firstname,lastname,email,username,password)VALUES(?,?,?,?,?)",('ritesh','demo','ritesh.dobhal@glassbeam.com',username,'Dobhal'))
  File "/home/kallme/.local/lib/python3.5/site-packages/pymysql/cursors.py", line 164, in execute
    query = self.mogrify(query, args)
  File "/home/kallme/.local/lib/python3.5/site-packages/pymysql/cursors.py", line 143, in mogrify
    query = query % self._escape_args(args, conn)
TypeError: not all arguments converted during string formatting
106.51.138.236 - - [10/Jun/2017 07:18:03] "GET /user/add?username=ritesh HTTP/1.1" 500 -
Traceback (most recent call last):
  File "/home/kallme/.local/lib/python3.5/site-packages/flask/app.py", line 1997, in __call__
    return self.wsgi_app(environ, start_response)
  File "/home/kallme/.local/lib/python3.5/site-packages/flask/app.py", line 1985, in wsgi_app
    response = self.handle_exception(e)
  File "/home/kallme/.local/lib/python3.5/site-packages/flask/app.py", line 1540, in handle_exception
    reraise(exc_type, exc_value, tb)
  File "/home/kallme/.local/lib/python3.5/site-packages/flask/_compat.py", line 33, in reraise
    raise value
  File "/home/kallme/.local/lib/python3.5/site-packages/flask/app.py", line 1982, in wsgi_app
    response = self.full_dispatch_request()
  File "/home/kallme/.local/lib/python3.5/site-packages/flask/app.py", line 1614, in full_dispatch_request
    rv = self.handle_user_exception(e)
  File "/home/kallme/.local/lib/python3.5/site-packages/flask/app.py", line 1517, in handle_user_exception
    reraise(exc_type, exc_value, tb)
  File "/home/kallme/.local/lib/python3.5/site-packages/flask/_compat.py", line 33, in reraise
    raise value
  File "/home/kallme/.local/lib/python3.5/site-packages/flask/app.py", line 1612, in full_dispatch_request
    rv = self.dispatch_request()
  File "/home/kallme/.local/lib/python3.5/site-packages/flask/app.py", line 1598, in dispatch_request
    return self.view_functions[rule.endpoint](**req.view_args)
  File "/var/www/apps/restserver/app/user/controllers.py", line 10, in add
    adddb(params)
  File "/var/www/apps/restserver/app/user/models.py", line 8, in adddb
    cur = cursor.execute("INSERT INTO user (firstname,lastname,email,username,password)VALUES(?,?,?,?,?)",('ritesh','demo','ritesh.dobhal@glassbeam.com',username,'Dobhal'))
  File "/home/kallme/.local/lib/python3.5/site-packages/pymysql/cursors.py", line 164, in execute
    query = self.mogrify(query, args)
  File "/home/kallme/.local/lib/python3.5/site-packages/pymysql/cursors.py", line 143, in mogrify
    query = query % self._escape_args(args, conn)
TypeError: not all arguments converted during string formatting
106.51.138.236 - - [10/Jun/2017 07:18:04] "GET /user/add?__debugger__=yes&cmd=resource&f=style.css HTTP/1.1" 200 -
106.51.138.236 - - [10/Jun/2017 07:18:04] "GET /user/add?__debugger__=yes&cmd=resource&f=jquery.js HTTP/1.1" 200 -
106.51.138.236 - - [10/Jun/2017 07:18:04] "GET /user/add?__debugger__=yes&cmd=resource&f=debugger.js HTTP/1.1" 200 -
106.51.138.236 - - [10/Jun/2017 07:18:05] "GET /user/add?__debugger__=yes&cmd=resource&f=ubuntu.ttf HTTP/1.1" 200 -
106.51.138.236 - - [10/Jun/2017 07:18:06] "GET /user/add?__debugger__=yes&cmd=resource&f=console.png HTTP/1.1" 200 -
106.51.138.236 - - [10/Jun/2017 07:18:06] "GET /user/add?__debugger__=yes&cmd=resource&f=console.png HTTP/1.1" 200 -
 * Detected change in '/var/www/apps/restserver/app/user/models.py', reloading
 * Restarting with stat
 * Debugger is active!
 * Debugger PIN: 135-965-059
106.51.138.236 - - [10/Jun/2017 07:19:09] "GET /user/add?username=ritesh HTTP/1.1" 200 -
 * Detected change in '/var/www/apps/restserver/app/user/models.py', reloading
 * Restarting with stat
 * Debugger is active!
 * Debugger PIN: 135-965-059
106.51.138.236 - - [10/Jun/2017 07:21:02] "GET /user/add?username=ritesh HTTP/1.1" 500 -
Traceback (most recent call last):
  File "/home/kallme/.local/lib/python3.5/site-packages/flask/app.py", line 1997, in __call__
    return self.wsgi_app(environ, start_response)
  File "/home/kallme/.local/lib/python3.5/site-packages/flask/app.py", line 1985, in wsgi_app
    response = self.handle_exception(e)
  File "/home/kallme/.local/lib/python3.5/site-packages/flask/app.py", line 1540, in handle_exception
    reraise(exc_type, exc_value, tb)
  File "/home/kallme/.local/lib/python3.5/site-packages/flask/_compat.py", line 33, in reraise
    raise value
  File "/home/kallme/.local/lib/python3.5/site-packages/flask/app.py", line 1982, in wsgi_app
    response = self.full_dispatch_request()
  File "/home/kallme/.local/lib/python3.5/site-packages/flask/app.py", line 1614, in full_dispatch_request
    rv = self.handle_user_exception(e)
  File "/home/kallme/.local/lib/python3.5/site-packages/flask/app.py", line 1517, in handle_user_exception
    reraise(exc_type, exc_value, tb)
  File "/home/kallme/.local/lib/python3.5/site-packages/flask/_compat.py", line 33, in reraise
    raise value
  File "/home/kallme/.local/lib/python3.5/site-packages/flask/app.py", line 1612, in full_dispatch_request
    rv = self.dispatch_request()
  File "/home/kallme/.local/lib/python3.5/site-packages/flask/app.py", line 1598, in dispatch_request
    return self.view_functions[rule.endpoint](**req.view_args)
  File "/var/www/apps/restserver/app/user/controllers.py", line 10, in add
    adddb(params)
  File "/var/www/apps/restserver/app/user/models.py", line 12, in adddb
    cur = cursor.execute("INSERT INTO user (firstname,lastname,email,username,password)VALUES(?,?,?,?,?)",(firstname,password,email,username,lastname))
  File "/home/kallme/.local/lib/python3.5/site-packages/pymysql/cursors.py", line 164, in execute
    query = self.mogrify(query, args)
  File "/home/kallme/.local/lib/python3.5/site-packages/pymysql/cursors.py", line 143, in mogrify
    query = query % self._escape_args(args, conn)
TypeError: not all arguments converted during string formatting
106.51.138.236 - - [10/Jun/2017 07:21:03] "GET /user/add?__debugger__=yes&cmd=resource&f=style.css HTTP/1.1" 200 -
106.51.138.236 - - [10/Jun/2017 07:21:03] "GET /user/add?__debugger__=yes&cmd=resource&f=jquery.js HTTP/1.1" 200 -
106.51.138.236 - - [10/Jun/2017 07:21:04] "GET /user/add?__debugger__=yes&cmd=resource&f=debugger.js HTTP/1.1" 200 -
106.51.138.236 - - [10/Jun/2017 07:21:04] "GET /user/add?__debugger__=yes&cmd=resource&f=ubuntu.ttf HTTP/1.1" 200 -
106.51.138.236 - - [10/Jun/2017 07:21:05] "GET /user/add?__debugger__=yes&cmd=resource&f=console.png HTTP/1.1" 200 -
106.51.138.236 - - [10/Jun/2017 07:21:06] "GET /user/add?__debugger__=yes&cmd=resource&f=console.png HTTP/1.1" 200 -
106.51.138.236 - - [10/Jun/2017 07:21:09] "GET /user/add?username=ritesh HTTP/1.1" 500 -
Traceback (most recent call last):
  File "/home/kallme/.local/lib/python3.5/site-packages/flask/app.py", line 1997, in __call__
    return self.wsgi_app(environ, start_response)
  File "/home/kallme/.local/lib/python3.5/site-packages/flask/app.py", line 1985, in wsgi_app
    response = self.handle_exception(e)
  File "/home/kallme/.local/lib/python3.5/site-packages/flask/app.py", line 1540, in handle_exception
    reraise(exc_type, exc_value, tb)
  File "/home/kallme/.local/lib/python3.5/site-packages/flask/_compat.py", line 33, in reraise
    raise value
  File "/home/kallme/.local/lib/python3.5/site-packages/flask/app.py", line 1982, in wsgi_app
    response = self.full_dispatch_request()
  File "/home/kallme/.local/lib/python3.5/site-packages/flask/app.py", line 1614, in full_dispatch_request
    rv = self.handle_user_exception(e)
  File "/home/kallme/.local/lib/python3.5/site-packages/flask/app.py", line 1517, in handle_user_exception
    reraise(exc_type, exc_value, tb)
  File "/home/kallme/.local/lib/python3.5/site-packages/flask/_compat.py", line 33, in reraise
    raise value
  File "/home/kallme/.local/lib/python3.5/site-packages/flask/app.py", line 1612, in full_dispatch_request
    rv = self.dispatch_request()
  File "/home/kallme/.local/lib/python3.5/site-packages/flask/app.py", line 1598, in dispatch_request
    return self.view_functions[rule.endpoint](**req.view_args)
  File "/var/www/apps/restserver/app/user/controllers.py", line 10, in add
    adddb(params)
  File "/var/www/apps/restserver/app/user/models.py", line 12, in adddb
    cur = cursor.execute("INSERT INTO user (firstname,lastname,email,username,password)VALUES(?,?,?,?,?)",(firstname,password,email,username,lastname))
  File "/home/kallme/.local/lib/python3.5/site-packages/pymysql/cursors.py", line 164, in execute
    query = self.mogrify(query, args)
  File "/home/kallme/.local/lib/python3.5/site-packages/pymysql/cursors.py", line 143, in mogrify
    query = query % self._escape_args(args, conn)
TypeError: not all arguments converted during string formatting
106.51.138.236 - - [10/Jun/2017 07:21:09] "GET /user/add?__debugger__=yes&cmd=resource&f=style.css HTTP/1.1" 200 -
106.51.138.236 - - [10/Jun/2017 07:21:09] "GET /user/add?__debugger__=yes&cmd=resource&f=jquery.js HTTP/1.1" 200 -
106.51.138.236 - - [10/Jun/2017 07:21:11] "GET /user/add?__debugger__=yes&cmd=resource&f=debugger.js HTTP/1.1" 200 -
106.51.138.236 - - [10/Jun/2017 07:21:11] "GET /user/add?__debugger__=yes&cmd=resource&f=ubuntu.ttf HTTP/1.1" 200 -
106.51.138.236 - - [10/Jun/2017 07:21:12] "GET /user/add?__debugger__=yes&cmd=resource&f=console.png HTTP/1.1" 200 -
106.51.138.236 - - [10/Jun/2017 07:21:13] "GET /user/add?__debugger__=yes&cmd=resource&f=console.png HTTP/1.1" 200 -
 * Detected change in '/var/www/apps/restserver/app/user/models.py', reloading
 * Restarting with stat
 * Debugger is active!
 * Debugger PIN: 135-965-059
106.51.138.236 - - [10/Jun/2017 07:21:49] "GET /user/add?username=ritesh HTTP/1.1" 500 -
Traceback (most recent call last):
  File "/home/kallme/.local/lib/python3.5/site-packages/flask/app.py", line 1997, in __call__
    return self.wsgi_app(environ, start_response)
  File "/home/kallme/.local/lib/python3.5/site-packages/flask/app.py", line 1985, in wsgi_app
    response = self.handle_exception(e)
  File "/home/kallme/.local/lib/python3.5/site-packages/flask/app.py", line 1540, in handle_exception
    reraise(exc_type, exc_value, tb)
  File "/home/kallme/.local/lib/python3.5/site-packages/flask/_compat.py", line 33, in reraise
    raise value
  File "/home/kallme/.local/lib/python3.5/site-packages/flask/app.py", line 1982, in wsgi_app
    response = self.full_dispatch_request()
  File "/home/kallme/.local/lib/python3.5/site-packages/flask/app.py", line 1614, in full_dispatch_request
    rv = self.handle_user_exception(e)
  File "/home/kallme/.local/lib/python3.5/site-packages/flask/app.py", line 1517, in handle_user_exception
    reraise(exc_type, exc_value, tb)
  File "/home/kallme/.local/lib/python3.5/site-packages/flask/_compat.py", line 33, in reraise
    raise value
  File "/home/kallme/.local/lib/python3.5/site-packages/flask/app.py", line 1612, in full_dispatch_request
    rv = self.dispatch_request()
  File "/home/kallme/.local/lib/python3.5/site-packages/flask/app.py", line 1598, in dispatch_request
    return self.view_functions[rule.endpoint](**req.view_args)
  File "/var/www/apps/restserver/app/user/controllers.py", line 10, in add
    adddb(params)
  File "/var/www/apps/restserver/app/user/models.py", line 13, in adddb
    cur = cursor.execute("INSERT INTO user (firstname,lastname,email,username,password)VALUES(?,?,?,?,?)",(firstname,password,email,username,lastname))
  File "/home/kallme/.local/lib/python3.5/site-packages/pymysql/cursors.py", line 164, in execute
    query = self.mogrify(query, args)
  File "/home/kallme/.local/lib/python3.5/site-packages/pymysql/cursors.py", line 143, in mogrify
    query = query % self._escape_args(args, conn)
TypeError: not all arguments converted during string formatting
106.51.138.236 - - [10/Jun/2017 07:21:50] "GET /user/add?__debugger__=yes&cmd=resource&f=style.css HTTP/1.1" 200 -
106.51.138.236 - - [10/Jun/2017 07:21:50] "GET /user/add?__debugger__=yes&cmd=resource&f=jquery.js HTTP/1.1" 200 -
106.51.138.236 - - [10/Jun/2017 07:22:03] "GET /user/add?__debugger__=yes&cmd=resource&f=debugger.js HTTP/1.1" 200 -
106.51.138.236 - - [10/Jun/2017 07:22:03] "GET /user/add?username=ritesh HTTP/1.1" 500 -
Traceback (most recent call last):
  File "/home/kallme/.local/lib/python3.5/site-packages/flask/app.py", line 1997, in __call__
    return self.wsgi_app(environ, start_response)
  File "/home/kallme/.local/lib/python3.5/site-packages/flask/app.py", line 1985, in wsgi_app
    response = self.handle_exception(e)
  File "/home/kallme/.local/lib/python3.5/site-packages/flask/app.py", line 1540, in handle_exception
    reraise(exc_type, exc_value, tb)
  File "/home/kallme/.local/lib/python3.5/site-packages/flask/_compat.py", line 33, in reraise
    raise value
  File "/home/kallme/.local/lib/python3.5/site-packages/flask/app.py", line 1982, in wsgi_app
    response = self.full_dispatch_request()
  File "/home/kallme/.local/lib/python3.5/site-packages/flask/app.py", line 1614, in full_dispatch_request
    rv = self.handle_user_exception(e)
  File "/home/kallme/.local/lib/python3.5/site-packages/flask/app.py", line 1517, in handle_user_exception
    reraise(exc_type, exc_value, tb)
  File "/home/kallme/.local/lib/python3.5/site-packages/flask/_compat.py", line 33, in reraise
    raise value
  File "/home/kallme/.local/lib/python3.5/site-packages/flask/app.py", line 1612, in full_dispatch_request
    rv = self.dispatch_request()
  File "/home/kallme/.local/lib/python3.5/site-packages/flask/app.py", line 1598, in dispatch_request
    return self.view_functions[rule.endpoint](**req.view_args)
  File "/var/www/apps/restserver/app/user/controllers.py", line 10, in add
    adddb(params)
  File "/var/www/apps/restserver/app/user/models.py", line 13, in adddb
    cur = cursor.execute("INSERT INTO user (firstname,lastname,email,username,password)VALUES(?,?,?,?,?)",(firstname,password,email,username,lastname))
  File "/home/kallme/.local/lib/python3.5/site-packages/pymysql/cursors.py", line 164, in execute
    query = self.mogrify(query, args)
  File "/home/kallme/.local/lib/python3.5/site-packages/pymysql/cursors.py", line 143, in mogrify
    query = query % self._escape_args(args, conn)
TypeError: not all arguments converted during string formatting
106.51.138.236 - - [10/Jun/2017 07:22:04] "GET /user/add?__debugger__=yes&cmd=resource&f=style.css HTTP/1.1" 200 -
106.51.138.236 - - [10/Jun/2017 07:22:04] "GET /user/add?__debugger__=yes&cmd=resource&f=jquery.js HTTP/1.1" 200 -
106.51.138.236 - - [10/Jun/2017 07:22:05] "GET /user/add?__debugger__=yes&cmd=resource&f=debugger.js HTTP/1.1" 200 -
106.51.138.236 - - [10/Jun/2017 07:22:06] "GET /user/add?__debugger__=yes&cmd=resource&f=ubuntu.ttf HTTP/1.1" 200 -
106.51.138.236 - - [10/Jun/2017 07:22:06] "GET /user/add?__debugger__=yes&cmd=resource&f=console.png HTTP/1.1" 200 -
106.51.138.236 - - [10/Jun/2017 07:22:07] "GET /user/add?__debugger__=yes&cmd=resource&f=console.png HTTP/1.1" 200 -
106.51.138.236 - - [10/Jun/2017 07:22:14] "GET /user/add?username=ritesh HTTP/1.1" 500 -
Traceback (most recent call last):
  File "/home/kallme/.local/lib/python3.5/site-packages/flask/app.py", line 1997, in __call__
    return self.wsgi_app(environ, start_response)
  File "/home/kallme/.local/lib/python3.5/site-packages/flask/app.py", line 1985, in wsgi_app
    response = self.handle_exception(e)
  File "/home/kallme/.local/lib/python3.5/site-packages/flask/app.py", line 1540, in handle_exception
    reraise(exc_type, exc_value, tb)
  File "/home/kallme/.local/lib/python3.5/site-packages/flask/_compat.py", line 33, in reraise
    raise value
  File "/home/kallme/.local/lib/python3.5/site-packages/flask/app.py", line 1982, in wsgi_app
    response = self.full_dispatch_request()
  File "/home/kallme/.local/lib/python3.5/site-packages/flask/app.py", line 1614, in full_dispatch_request
    rv = self.handle_user_exception(e)
  File "/home/kallme/.local/lib/python3.5/site-packages/flask/app.py", line 1517, in handle_user_exception
    reraise(exc_type, exc_value, tb)
  File "/home/kallme/.local/lib/python3.5/site-packages/flask/_compat.py", line 33, in reraise
    raise value
  File "/home/kallme/.local/lib/python3.5/site-packages/flask/app.py", line 1612, in full_dispatch_request
    rv = self.dispatch_request()
  File "/home/kallme/.local/lib/python3.5/site-packages/flask/app.py", line 1598, in dispatch_request
    return self.view_functions[rule.endpoint](**req.view_args)
  File "/var/www/apps/restserver/app/user/controllers.py", line 10, in add
    adddb(params)
  File "/var/www/apps/restserver/app/user/models.py", line 13, in adddb
    cur = cursor.execute("INSERT INTO user (firstname,lastname,email,username,password)VALUES(?,?,?,?,?)",(firstname,password,email,username,lastname))
  File "/home/kallme/.local/lib/python3.5/site-packages/pymysql/cursors.py", line 164, in execute
    query = self.mogrify(query, args)
  File "/home/kallme/.local/lib/python3.5/site-packages/pymysql/cursors.py", line 143, in mogrify
    query = query % self._escape_args(args, conn)
TypeError: not all arguments converted during string formatting
106.51.138.236 - - [10/Jun/2017 07:22:14] "GET /user/add?__debugger__=yes&cmd=resource&f=style.css HTTP/1.1" 200 -
106.51.138.236 - - [10/Jun/2017 07:22:14] "GET /user/add?__debugger__=yes&cmd=resource&f=jquery.js HTTP/1.1" 200 -
 * Detected change in '/var/www/apps/restserver/app/user/models.py', reloading
 * Restarting with stat
 * Debugger is active!
 * Debugger PIN: 135-965-059
106.51.138.236 - - [10/Jun/2017 07:22:46] "GET /user/add?__debugger__=yes&cmd=resource&f=debugger.js HTTP/1.1" 200 -
106.51.138.236 - - [10/Jun/2017 07:22:47] "GET /user/add?__debugger__=yes&cmd=resource&f=ubuntu.ttf HTTP/1.1" 200 -
106.51.138.236 - - [10/Jun/2017 07:22:47] "GET /user/add?__debugger__=yes&cmd=resource&f=console.png HTTP/1.1" 200 -
106.51.138.236 - - [10/Jun/2017 07:22:48] "GET /user/add?__debugger__=yes&cmd=resource&f=console.png HTTP/1.1" 200 -
106.51.138.236 - - [10/Jun/2017 07:22:48] "GET /user/add?username=ritesh HTTP/1.1" 500 -
Traceback (most recent call last):
  File "/home/kallme/.local/lib/python3.5/site-packages/flask/app.py", line 1997, in __call__
    return self.wsgi_app(environ, start_response)
  File "/home/kallme/.local/lib/python3.5/site-packages/flask/app.py", line 1985, in wsgi_app
    response = self.handle_exception(e)
  File "/home/kallme/.local/lib/python3.5/site-packages/flask/app.py", line 1540, in handle_exception
    reraise(exc_type, exc_value, tb)
  File "/home/kallme/.local/lib/python3.5/site-packages/flask/_compat.py", line 33, in reraise
    raise value
  File "/home/kallme/.local/lib/python3.5/site-packages/flask/app.py", line 1982, in wsgi_app
    response = self.full_dispatch_request()
  File "/home/kallme/.local/lib/python3.5/site-packages/flask/app.py", line 1614, in full_dispatch_request
    rv = self.handle_user_exception(e)
  File "/home/kallme/.local/lib/python3.5/site-packages/flask/app.py", line 1517, in handle_user_exception
    reraise(exc_type, exc_value, tb)
  File "/home/kallme/.local/lib/python3.5/site-packages/flask/_compat.py", line 33, in reraise
    raise value
  File "/home/kallme/.local/lib/python3.5/site-packages/flask/app.py", line 1612, in full_dispatch_request
    rv = self.dispatch_request()
  File "/home/kallme/.local/lib/python3.5/site-packages/flask/app.py", line 1598, in dispatch_request
    return self.view_functions[rule.endpoint](**req.view_args)
  File "/var/www/apps/restserver/app/user/controllers.py", line 10, in add
    adddb(params)
  File "/var/www/apps/restserver/app/user/models.py", line 13, in adddb
    cursor.execute("INSERT INTO user (firstname,lastname,email,username,password)VALUES(?,?,?,?,?)",(firstname,password,email,username,lastname))
  File "/home/kallme/.local/lib/python3.5/site-packages/pymysql/cursors.py", line 164, in execute
    query = self.mogrify(query, args)
  File "/home/kallme/.local/lib/python3.5/site-packages/pymysql/cursors.py", line 143, in mogrify
    query = query % self._escape_args(args, conn)
TypeError: not all arguments converted during string formatting
106.51.138.236 - - [10/Jun/2017 07:23:04] "GET /user/add?__debugger__=yes&cmd=resource&f=style.css HTTP/1.1" 200 -
106.51.138.236 - - [10/Jun/2017 07:23:04] "GET /user/add?__debugger__=yes&cmd=resource&f=jquery.js HTTP/1.1" 200 -
106.51.138.236 - - [10/Jun/2017 07:23:04] "GET /user/add?__debugger__=yes&cmd=resource&f=debugger.js HTTP/1.1" 200 -
106.51.138.236 - - [10/Jun/2017 07:23:04] "GET /user/add?username=ritesh HTTP/1.1" 500 -
Traceback (most recent call last):
  File "/home/kallme/.local/lib/python3.5/site-packages/flask/app.py", line 1997, in __call__
    return self.wsgi_app(environ, start_response)
  File "/home/kallme/.local/lib/python3.5/site-packages/flask/app.py", line 1985, in wsgi_app
    response = self.handle_exception(e)
  File "/home/kallme/.local/lib/python3.5/site-packages/flask/app.py", line 1540, in handle_exception
    reraise(exc_type, exc_value, tb)
  File "/home/kallme/.local/lib/python3.5/site-packages/flask/_compat.py", line 33, in reraise
    raise value
  File "/home/kallme/.local/lib/python3.5/site-packages/flask/app.py", line 1982, in wsgi_app
    response = self.full_dispatch_request()
  File "/home/kallme/.local/lib/python3.5/site-packages/flask/app.py", line 1614, in full_dispatch_request
    rv = self.handle_user_exception(e)
  File "/home/kallme/.local/lib/python3.5/site-packages/flask/app.py", line 1517, in handle_user_exception
    reraise(exc_type, exc_value, tb)
  File "/home/kallme/.local/lib/python3.5/site-packages/flask/_compat.py", line 33, in reraise
    raise value
  File "/home/kallme/.local/lib/python3.5/site-packages/flask/app.py", line 1612, in full_dispatch_request
    rv = self.dispatch_request()
  File "/home/kallme/.local/lib/python3.5/site-packages/flask/app.py", line 1598, in dispatch_request
    return self.view_functions[rule.endpoint](**req.view_args)
  File "/var/www/apps/restserver/app/user/controllers.py", line 10, in add
    adddb(params)
  File "/var/www/apps/restserver/app/user/models.py", line 13, in adddb
    cursor.execute("INSERT INTO user (firstname,lastname,email,username,password)VALUES(?,?,?,?,?)",(firstname,password,email,username,lastname))
  File "/home/kallme/.local/lib/python3.5/site-packages/pymysql/cursors.py", line 164, in execute
    query = self.mogrify(query, args)
  File "/home/kallme/.local/lib/python3.5/site-packages/pymysql/cursors.py", line 143, in mogrify
    query = query % self._escape_args(args, conn)
TypeError: not all arguments converted during string formatting
106.51.138.236 - - [10/Jun/2017 07:23:05] "GET /user/add?__debugger__=yes&cmd=resource&f=style.css HTTP/1.1" 200 -
106.51.138.236 - - [10/Jun/2017 07:23:05] "GET /user/add?__debugger__=yes&cmd=resource&f=jquery.js HTTP/1.1" 200 -
106.51.138.236 - - [10/Jun/2017 07:23:06] "GET /user/add?__debugger__=yes&cmd=resource&f=debugger.js HTTP/1.1" 200 -
106.51.138.236 - - [10/Jun/2017 07:23:07] "GET /user/add?__debugger__=yes&cmd=resource&f=ubuntu.ttf HTTP/1.1" 200 -
106.51.138.236 - - [10/Jun/2017 07:23:08] "GET /user/add?__debugger__=yes&cmd=resource&f=console.png HTTP/1.1" 200 -
106.51.138.236 - - [10/Jun/2017 07:23:09] "GET /user/add?__debugger__=yes&cmd=resource&f=console.png HTTP/1.1" 200 -
106.51.138.236 - - [10/Jun/2017 07:23:11] "GET /user/add?username=ritesh HTTP/1.1" 500 -
Traceback (most recent call last):
  File "/home/kallme/.local/lib/python3.5/site-packages/flask/app.py", line 1997, in __call__
    return self.wsgi_app(environ, start_response)
  File "/home/kallme/.local/lib/python3.5/site-packages/flask/app.py", line 1985, in wsgi_app
    response = self.handle_exception(e)
  File "/home/kallme/.local/lib/python3.5/site-packages/flask/app.py", line 1540, in handle_exception
    reraise(exc_type, exc_value, tb)
  File "/home/kallme/.local/lib/python3.5/site-packages/flask/_compat.py", line 33, in reraise
    raise value
  File "/home/kallme/.local/lib/python3.5/site-packages/flask/app.py", line 1982, in wsgi_app
    response = self.full_dispatch_request()
  File "/home/kallme/.local/lib/python3.5/site-packages/flask/app.py", line 1614, in full_dispatch_request
    rv = self.handle_user_exception(e)
  File "/home/kallme/.local/lib/python3.5/site-packages/flask/app.py", line 1517, in handle_user_exception
    reraise(exc_type, exc_value, tb)
  File "/home/kallme/.local/lib/python3.5/site-packages/flask/_compat.py", line 33, in reraise
    raise value
  File "/home/kallme/.local/lib/python3.5/site-packages/flask/app.py", line 1612, in full_dispatch_request
    rv = self.dispatch_request()
  File "/home/kallme/.local/lib/python3.5/site-packages/flask/app.py", line 1598, in dispatch_request
    return self.view_functions[rule.endpoint](**req.view_args)
  File "/var/www/apps/restserver/app/user/controllers.py", line 10, in add
    adddb(params)
  File "/var/www/apps/restserver/app/user/models.py", line 13, in adddb
    cursor.execute("INSERT INTO user (firstname,lastname,email,username,password)VALUES(?,?,?,?,?)",(firstname,password,email,username,lastname))
  File "/home/kallme/.local/lib/python3.5/site-packages/pymysql/cursors.py", line 164, in execute
    query = self.mogrify(query, args)
  File "/home/kallme/.local/lib/python3.5/site-packages/pymysql/cursors.py", line 143, in mogrify
    query = query % self._escape_args(args, conn)
TypeError: not all arguments converted during string formatting
106.51.138.236 - - [10/Jun/2017 07:23:11] "GET /user/add?__debugger__=yes&cmd=resource&f=style.css HTTP/1.1" 200 -
106.51.138.236 - - [10/Jun/2017 07:23:11] "GET /user/add?__debugger__=yes&cmd=resource&f=jquery.js HTTP/1.1" 200 -
106.51.138.236 - - [10/Jun/2017 07:23:12] "GET /user/add?__debugger__=yes&cmd=resource&f=debugger.js HTTP/1.1" 200 -
106.51.138.236 - - [10/Jun/2017 07:23:13] "GET /user/add?__debugger__=yes&cmd=resource&f=ubuntu.ttf HTTP/1.1" 200 -
106.51.138.236 - - [10/Jun/2017 07:23:14] "GET /user/add?__debugger__=yes&cmd=resource&f=console.png HTTP/1.1" 200 -
106.51.138.236 - - [10/Jun/2017 07:23:14] "GET /user/add?__debugger__=yes&cmd=resource&f=console.png HTTP/1.1" 200 -
106.51.138.236 - - [10/Jun/2017 07:25:34] "GET /user/add?username=ritesh HTTP/1.1" 500 -
Traceback (most recent call last):
  File "/home/kallme/.local/lib/python3.5/site-packages/flask/app.py", line 1997, in __call__
    return self.wsgi_app(environ, start_response)
  File "/home/kallme/.local/lib/python3.5/site-packages/flask/app.py", line 1985, in wsgi_app
    response = self.handle_exception(e)
  File "/home/kallme/.local/lib/python3.5/site-packages/flask/app.py", line 1540, in handle_exception
    reraise(exc_type, exc_value, tb)
  File "/home/kallme/.local/lib/python3.5/site-packages/flask/_compat.py", line 33, in reraise
    raise value
  File "/home/kallme/.local/lib/python3.5/site-packages/flask/app.py", line 1982, in wsgi_app
    response = self.full_dispatch_request()
  File "/home/kallme/.local/lib/python3.5/site-packages/flask/app.py", line 1614, in full_dispatch_request
    rv = self.handle_user_exception(e)
  File "/home/kallme/.local/lib/python3.5/site-packages/flask/app.py", line 1517, in handle_user_exception
    reraise(exc_type, exc_value, tb)
  File "/home/kallme/.local/lib/python3.5/site-packages/flask/_compat.py", line 33, in reraise
    raise value
  File "/home/kallme/.local/lib/python3.5/site-packages/flask/app.py", line 1612, in full_dispatch_request
    rv = self.dispatch_request()
  File "/home/kallme/.local/lib/python3.5/site-packages/flask/app.py", line 1598, in dispatch_request
    return self.view_functions[rule.endpoint](**req.view_args)
  File "/var/www/apps/restserver/app/user/controllers.py", line 10, in add
    adddb(params)
  File "/var/www/apps/restserver/app/user/models.py", line 13, in adddb
    cursor.execute("INSERT INTO user (firstname,lastname,email,username,password)VALUES(?,?,?,?,?)",(firstname,password,email,username,lastname))
  File "/home/kallme/.local/lib/python3.5/site-packages/pymysql/cursors.py", line 164, in execute
    query = self.mogrify(query, args)
  File "/home/kallme/.local/lib/python3.5/site-packages/pymysql/cursors.py", line 143, in mogrify
    query = query % self._escape_args(args, conn)
TypeError: not all arguments converted during string formatting
106.51.138.236 - - [10/Jun/2017 07:25:36] "GET /user/add?__debugger__=yes&cmd=resource&f=style.css HTTP/1.1" 200 -
106.51.138.236 - - [10/Jun/2017 07:25:36] "GET /user/add?__debugger__=yes&cmd=resource&f=jquery.js HTTP/1.1" 200 -
106.51.138.236 - - [10/Jun/2017 07:25:37] "GET /user/add?__debugger__=yes&cmd=resource&f=debugger.js HTTP/1.1" 200 -
106.51.138.236 - - [10/Jun/2017 07:25:38] "GET /user/add?__debugger__=yes&cmd=resource&f=ubuntu.ttf HTTP/1.1" 200 -
106.51.138.236 - - [10/Jun/2017 07:25:38] "GET /user/add?__debugger__=yes&cmd=resource&f=console.png HTTP/1.1" 200 -
106.51.138.236 - - [10/Jun/2017 07:25:39] "GET /user/add?__debugger__=yes&cmd=resource&f=console.png HTTP/1.1" 200 -
 * Detected change in '/var/www/apps/restserver/app/user/models.py', reloading
 * Restarting with stat
 * Debugger is active!
 * Debugger PIN: 135-965-059
106.51.138.236 - - [10/Jun/2017 07:26:14] "GET /user/add?username=ritesh HTTP/1.1" 500 -
Traceback (most recent call last):
  File "/home/kallme/.local/lib/python3.5/site-packages/flask/app.py", line 1997, in __call__
    return self.wsgi_app(environ, start_response)
  File "/home/kallme/.local/lib/python3.5/site-packages/flask/app.py", line 1985, in wsgi_app
    response = self.handle_exception(e)
  File "/home/kallme/.local/lib/python3.5/site-packages/flask/app.py", line 1540, in handle_exception
    reraise(exc_type, exc_value, tb)
  File "/home/kallme/.local/lib/python3.5/site-packages/flask/_compat.py", line 33, in reraise
    raise value
  File "/home/kallme/.local/lib/python3.5/site-packages/flask/app.py", line 1982, in wsgi_app
    response = self.full_dispatch_request()
  File "/home/kallme/.local/lib/python3.5/site-packages/flask/app.py", line 1614, in full_dispatch_request
    rv = self.handle_user_exception(e)
  File "/home/kallme/.local/lib/python3.5/site-packages/flask/app.py", line 1517, in handle_user_exception
    reraise(exc_type, exc_value, tb)
  File "/home/kallme/.local/lib/python3.5/site-packages/flask/_compat.py", line 33, in reraise
    raise value
  File "/home/kallme/.local/lib/python3.5/site-packages/flask/app.py", line 1612, in full_dispatch_request
    rv = self.dispatch_request()
  File "/home/kallme/.local/lib/python3.5/site-packages/flask/app.py", line 1598, in dispatch_request
    return self.view_functions[rule.endpoint](**req.view_args)
  File "/var/www/apps/restserver/app/user/controllers.py", line 10, in add
    adddb(params)
  File "/var/www/apps/restserver/app/user/models.py", line 13, in adddb
    cursor.execute("INSERT INTO user (firstname,lastname,email,username,password)VALUES(?,?,?,?,?)",(firstname,password,email,username,lastname))
  File "/home/kallme/.local/lib/python3.5/site-packages/pymysql/cursors.py", line 164, in execute
    query = self.mogrify(query, args)
  File "/home/kallme/.local/lib/python3.5/site-packages/pymysql/cursors.py", line 143, in mogrify
    query = query % self._escape_args(args, conn)
TypeError: not all arguments converted during string formatting
106.51.138.236 - - [10/Jun/2017 07:26:15] "GET /user/add?__debugger__=yes&cmd=resource&f=debugger.js HTTP/1.1" 200 -
106.51.138.236 - - [10/Jun/2017 07:26:15] "GET /user/add?__debugger__=yes&cmd=resource&f=jquery.js HTTP/1.1" 200 -
106.51.138.236 - - [10/Jun/2017 07:26:16] "GET /user/add?__debugger__=yes&cmd=resource&f=style.css HTTP/1.1" 200 -
106.51.138.236 - - [10/Jun/2017 07:26:16] "GET /user/add?username=ritesh HTTP/1.1" 500 -
Traceback (most recent call last):
  File "/home/kallme/.local/lib/python3.5/site-packages/flask/app.py", line 1997, in __call__
    return self.wsgi_app(environ, start_response)
  File "/home/kallme/.local/lib/python3.5/site-packages/flask/app.py", line 1985, in wsgi_app
    response = self.handle_exception(e)
  File "/home/kallme/.local/lib/python3.5/site-packages/flask/app.py", line 1540, in handle_exception
    reraise(exc_type, exc_value, tb)
  File "/home/kallme/.local/lib/python3.5/site-packages/flask/_compat.py", line 33, in reraise
    raise value
  File "/home/kallme/.local/lib/python3.5/site-packages/flask/app.py", line 1982, in wsgi_app
    response = self.full_dispatch_request()
  File "/home/kallme/.local/lib/python3.5/site-packages/flask/app.py", line 1614, in full_dispatch_request
    rv = self.handle_user_exception(e)
  File "/home/kallme/.local/lib/python3.5/site-packages/flask/app.py", line 1517, in handle_user_exception
    reraise(exc_type, exc_value, tb)
  File "/home/kallme/.local/lib/python3.5/site-packages/flask/_compat.py", line 33, in reraise
    raise value
  File "/home/kallme/.local/lib/python3.5/site-packages/flask/app.py", line 1612, in full_dispatch_request
    rv = self.dispatch_request()
  File "/home/kallme/.local/lib/python3.5/site-packages/flask/app.py", line 1598, in dispatch_request
    return self.view_functions[rule.endpoint](**req.view_args)
  File "/var/www/apps/restserver/app/user/controllers.py", line 10, in add
    adddb(params)
  File "/var/www/apps/restserver/app/user/models.py", line 13, in adddb
    cursor.execute("INSERT INTO user (firstname,lastname,email,username,password)VALUES(?,?,?,?,?)",(firstname,password,email,username,lastname))
  File "/home/kallme/.local/lib/python3.5/site-packages/pymysql/cursors.py", line 164, in execute
    query = self.mogrify(query, args)
  File "/home/kallme/.local/lib/python3.5/site-packages/pymysql/cursors.py", line 143, in mogrify
    query = query % self._escape_args(args, conn)
TypeError: not all arguments converted during string formatting
106.51.138.236 - - [10/Jun/2017 07:26:17] "GET /user/add?__debugger__=yes&cmd=resource&f=style.css HTTP/1.1" 200 -
106.51.138.236 - - [10/Jun/2017 07:26:17] "GET /user/add?__debugger__=yes&cmd=resource&f=jquery.js HTTP/1.1" 200 -
106.51.138.236 - - [10/Jun/2017 07:26:17] "GET /user/add?__debugger__=yes&cmd=resource&f=debugger.js HTTP/1.1" 200 -
106.51.138.236 - - [10/Jun/2017 07:26:18] "GET /user/add?__debugger__=yes&cmd=resource&f=ubuntu.ttf HTTP/1.1" 200 -
106.51.138.236 - - [10/Jun/2017 07:26:19] "GET /user/add?__debugger__=yes&cmd=resource&f=console.png HTTP/1.1" 200 -
106.51.138.236 - - [10/Jun/2017 07:26:20] "GET /user/add?__debugger__=yes&cmd=resource&f=console.png HTTP/1.1" 200 -
 * Detected change in '/var/www/apps/restserver/app/user/models.py', reloading
 * Restarting with stat
 * Debugger is active!
 * Debugger PIN: 135-965-059
106.51.138.236 - - [10/Jun/2017 07:27:39] "GET /user/add?username=ritesh HTTP/1.1" 500 -
Traceback (most recent call last):
  File "/home/kallme/.local/lib/python3.5/site-packages/flask/app.py", line 1997, in __call__
    return self.wsgi_app(environ, start_response)
  File "/home/kallme/.local/lib/python3.5/site-packages/flask/app.py", line 1985, in wsgi_app
    response = self.handle_exception(e)
  File "/home/kallme/.local/lib/python3.5/site-packages/flask/app.py", line 1540, in handle_exception
    reraise(exc_type, exc_value, tb)
  File "/home/kallme/.local/lib/python3.5/site-packages/flask/_compat.py", line 33, in reraise
    raise value
  File "/home/kallme/.local/lib/python3.5/site-packages/flask/app.py", line 1982, in wsgi_app
    response = self.full_dispatch_request()
  File "/home/kallme/.local/lib/python3.5/site-packages/flask/app.py", line 1614, in full_dispatch_request
    rv = self.handle_user_exception(e)
  File "/home/kallme/.local/lib/python3.5/site-packages/flask/app.py", line 1517, in handle_user_exception
    reraise(exc_type, exc_value, tb)
  File "/home/kallme/.local/lib/python3.5/site-packages/flask/_compat.py", line 33, in reraise
    raise value
  File "/home/kallme/.local/lib/python3.5/site-packages/flask/app.py", line 1612, in full_dispatch_request
    rv = self.dispatch_request()
  File "/home/kallme/.local/lib/python3.5/site-packages/flask/app.py", line 1598, in dispatch_request
    return self.view_functions[rule.endpoint](**req.view_args)
  File "/var/www/apps/restserver/app/user/controllers.py", line 10, in add
    adddb(params)
  File "/var/www/apps/restserver/app/user/models.py", line 13, in adddb
    cursor.execute("INSERT INTO user (firstname,lastname,email,username,password) VALUES (?,?,?,?,?)",(firstname,password,email,username,lastname))
  File "/home/kallme/.local/lib/python3.5/site-packages/pymysql/cursors.py", line 164, in execute
    query = self.mogrify(query, args)
  File "/home/kallme/.local/lib/python3.5/site-packages/pymysql/cursors.py", line 143, in mogrify
    query = query % self._escape_args(args, conn)
TypeError: not all arguments converted during string formatting
106.51.138.236 - - [10/Jun/2017 07:27:40] "GET /user/add?__debugger__=yes&cmd=resource&f=style.css HTTP/1.1" 200 -
106.51.138.236 - - [10/Jun/2017 07:27:40] "GET /user/add?__debugger__=yes&cmd=resource&f=jquery.js HTTP/1.1" 200 -
106.51.138.236 - - [10/Jun/2017 07:27:40] "GET /user/add?__debugger__=yes&cmd=resource&f=debugger.js HTTP/1.1" 200 -
106.51.138.236 - - [10/Jun/2017 07:27:42] "GET /user/add?__debugger__=yes&cmd=resource&f=ubuntu.ttf HTTP/1.1" 200 -
106.51.138.236 - - [10/Jun/2017 07:27:43] "GET /user/add?__debugger__=yes&cmd=resource&f=console.png HTTP/1.1" 200 -
106.51.138.236 - - [10/Jun/2017 07:27:44] "GET /user/add?__debugger__=yes&cmd=resource&f=console.png HTTP/1.1" 200 -
 * Detected change in '/var/www/apps/restserver/app/user/models.py', reloading
 * Restarting with stat
 * Debugger is active!
 * Debugger PIN: 135-965-059
106.51.138.236 - - [10/Jun/2017 07:28:34] "GET /user/add?username=ritesh HTTP/1.1" 500 -
Traceback (most recent call last):
  File "/home/kallme/.local/lib/python3.5/site-packages/flask/app.py", line 1997, in __call__
    return self.wsgi_app(environ, start_response)
  File "/home/kallme/.local/lib/python3.5/site-packages/flask/app.py", line 1985, in wsgi_app
    response = self.handle_exception(e)
  File "/home/kallme/.local/lib/python3.5/site-packages/flask/app.py", line 1540, in handle_exception
    reraise(exc_type, exc_value, tb)
  File "/home/kallme/.local/lib/python3.5/site-packages/flask/_compat.py", line 33, in reraise
    raise value
  File "/home/kallme/.local/lib/python3.5/site-packages/flask/app.py", line 1982, in wsgi_app
    response = self.full_dispatch_request()
  File "/home/kallme/.local/lib/python3.5/site-packages/flask/app.py", line 1614, in full_dispatch_request
    rv = self.handle_user_exception(e)
  File "/home/kallme/.local/lib/python3.5/site-packages/flask/app.py", line 1517, in handle_user_exception
    reraise(exc_type, exc_value, tb)
  File "/home/kallme/.local/lib/python3.5/site-packages/flask/_compat.py", line 33, in reraise
    raise value
  File "/home/kallme/.local/lib/python3.5/site-packages/flask/app.py", line 1612, in full_dispatch_request
    rv = self.dispatch_request()
  File "/home/kallme/.local/lib/python3.5/site-packages/flask/app.py", line 1598, in dispatch_request
    return self.view_functions[rule.endpoint](**req.view_args)
  File "/var/www/apps/restserver/app/user/controllers.py", line 10, in add
    adddb(params)
  File "/var/www/apps/restserver/app/user/models.py", line 13, in adddb
    cursor.execute("INSERT INTO user (firstname,lastname,email,username,password) VALUES (?,?,?,?,?)",(firstname,password,email,username,lastname))
  File "/home/kallme/.local/lib/python3.5/site-packages/pymysql/cursors.py", line 164, in execute
    query = self.mogrify(query, args)
  File "/home/kallme/.local/lib/python3.5/site-packages/pymysql/cursors.py", line 143, in mogrify
    query = query % self._escape_args(args, conn)
TypeError: not all arguments converted during string formatting
106.51.138.236 - - [10/Jun/2017 07:28:35] "GET /user/add?__debugger__=yes&cmd=resource&f=style.css HTTP/1.1" 200 -
106.51.138.236 - - [10/Jun/2017 07:28:35] "GET /user/add?__debugger__=yes&cmd=resource&f=debugger.js HTTP/1.1" 200 -
106.51.138.236 - - [10/Jun/2017 07:28:35] "GET /user/add?__debugger__=yes&cmd=resource&f=jquery.js HTTP/1.1" 200 -
106.51.138.236 - - [10/Jun/2017 07:28:37] "GET /user/add?__debugger__=yes&cmd=resource&f=ubuntu.ttf HTTP/1.1" 200 -
106.51.138.236 - - [10/Jun/2017 07:28:38] "GET /user/add?__debugger__=yes&cmd=resource&f=console.png HTTP/1.1" 200 -
 * Detected change in '/var/www/apps/restserver/app/user/models.py', reloading
 * Restarting with stat
 * Debugger is active!
 * Debugger PIN: 135-965-059
106.51.138.236 - - [10/Jun/2017 07:31:32] "GET /user/add?username=ritesh HTTP/1.1" 200 -
 * Detected change in '/var/www/apps/restserver/app/user/models.py', reloading
 * Restarting with stat
 * Debugger is active!
 * Debugger PIN: 135-965-059
106.51.138.236 - - [10/Jun/2017 07:32:10] "GET /user/add?username=ritesh HTTP/1.1" 200 -
106.51.138.236 - - [10/Jun/2017 07:32:10] "GET /user/add?username=ritesh HTTP/1.1" 500 -
Traceback (most recent call last):
  File "/home/kallme/.local/lib/python3.5/site-packages/flask/app.py", line 1997, in __call__
    return self.wsgi_app(environ, start_response)
  File "/home/kallme/.local/lib/python3.5/site-packages/flask/app.py", line 1985, in wsgi_app
    response = self.handle_exception(e)
  File "/home/kallme/.local/lib/python3.5/site-packages/flask/app.py", line 1540, in handle_exception
    reraise(exc_type, exc_value, tb)
  File "/home/kallme/.local/lib/python3.5/site-packages/flask/_compat.py", line 33, in reraise
    raise value
  File "/home/kallme/.local/lib/python3.5/site-packages/flask/app.py", line 1982, in wsgi_app
    response = self.full_dispatch_request()
  File "/home/kallme/.local/lib/python3.5/site-packages/flask/app.py", line 1614, in full_dispatch_request
    rv = self.handle_user_exception(e)
  File "/home/kallme/.local/lib/python3.5/site-packages/flask/app.py", line 1517, in handle_user_exception
    reraise(exc_type, exc_value, tb)
  File "/home/kallme/.local/lib/python3.5/site-packages/flask/_compat.py", line 33, in reraise
    raise value
  File "/home/kallme/.local/lib/python3.5/site-packages/flask/app.py", line 1612, in full_dispatch_request
    rv = self.dispatch_request()
  File "/home/kallme/.local/lib/python3.5/site-packages/flask/app.py", line 1598, in dispatch_request
    return self.view_functions[rule.endpoint](**req.view_args)
  File "/var/www/apps/restserver/app/user/controllers.py", line 10, in add
    adddb(params)
  File "/var/www/apps/restserver/app/user/models.py", line 13, in adddb
    cursor.execute("INSERT INTO user (firstname,lastname,email,username,password) VALUES (%s,%s,%s,%s,%s)",(firstname,password,email,username,lastname))
  File "/home/kallme/.local/lib/python3.5/site-packages/pymysql/cursors.py", line 166, in execute
    result = self._query(query)
  File "/home/kallme/.local/lib/python3.5/site-packages/pymysql/cursors.py", line 322, in _query
    conn.query(q)
  File "/home/kallme/.local/lib/python3.5/site-packages/pymysql/connections.py", line 855, in query
    self._execute_command(COMMAND.COM_QUERY, sql)
  File "/home/kallme/.local/lib/python3.5/site-packages/pymysql/connections.py", line 1071, in _execute_command
    raise err.InterfaceError("(0, '')")
pymysql.err.InterfaceError: (0, '')
106.51.138.236 - - [10/Jun/2017 07:32:11] "GET /user/add?__debugger__=yes&cmd=resource&f=style.css HTTP/1.1" 200 -
106.51.138.236 - - [10/Jun/2017 07:32:11] "GET /user/add?__debugger__=yes&cmd=resource&f=jquery.js HTTP/1.1" 200 -
106.51.138.236 - - [10/Jun/2017 07:32:13] "GET /user/add?__debugger__=yes&cmd=resource&f=debugger.js HTTP/1.1" 200 -
106.51.138.236 - - [10/Jun/2017 07:32:13] "GET /user/add?__debugger__=yes&cmd=resource&f=ubuntu.ttf HTTP/1.1" 200 -
106.51.138.236 - - [10/Jun/2017 07:32:14] "GET /user/add?__debugger__=yes&cmd=resource&f=console.png HTTP/1.1" 200 -
106.51.138.236 - - [10/Jun/2017 07:32:15] "GET /user/add?__debugger__=yes&cmd=resource&f=console.png HTTP/1.1" 200 -
106.51.138.236 - - [10/Jun/2017 07:32:19] "GET /user/add?username=ritesh HTTP/1.1" 500 -
Traceback (most recent call last):
  File "/home/kallme/.local/lib/python3.5/site-packages/flask/app.py", line 1997, in __call__
    return self.wsgi_app(environ, start_response)
  File "/home/kallme/.local/lib/python3.5/site-packages/flask/app.py", line 1985, in wsgi_app
    response = self.handle_exception(e)
  File "/home/kallme/.local/lib/python3.5/site-packages/flask/app.py", line 1540, in handle_exception
    reraise(exc_type, exc_value, tb)
  File "/home/kallme/.local/lib/python3.5/site-packages/flask/_compat.py", line 33, in reraise
    raise value
  File "/home/kallme/.local/lib/python3.5/site-packages/flask/app.py", line 1982, in wsgi_app
    response = self.full_dispatch_request()
  File "/home/kallme/.local/lib/python3.5/site-packages/flask/app.py", line 1614, in full_dispatch_request
    rv = self.handle_user_exception(e)
  File "/home/kallme/.local/lib/python3.5/site-packages/flask/app.py", line 1517, in handle_user_exception
    reraise(exc_type, exc_value, tb)
  File "/home/kallme/.local/lib/python3.5/site-packages/flask/_compat.py", line 33, in reraise
    raise value
  File "/home/kallme/.local/lib/python3.5/site-packages/flask/app.py", line 1612, in full_dispatch_request
    rv = self.dispatch_request()
  File "/home/kallme/.local/lib/python3.5/site-packages/flask/app.py", line 1598, in dispatch_request
    return self.view_functions[rule.endpoint](**req.view_args)
  File "/var/www/apps/restserver/app/user/controllers.py", line 10, in add
    adddb(params)
  File "/var/www/apps/restserver/app/user/models.py", line 13, in adddb
    cursor.execute("INSERT INTO user (firstname,lastname,email,username,password) VALUES (%s,%s,%s,%s,%s)",(firstname,password,email,username,lastname))
  File "/home/kallme/.local/lib/python3.5/site-packages/pymysql/cursors.py", line 166, in execute
    result = self._query(query)
  File "/home/kallme/.local/lib/python3.5/site-packages/pymysql/cursors.py", line 322, in _query
    conn.query(q)
  File "/home/kallme/.local/lib/python3.5/site-packages/pymysql/connections.py", line 855, in query
    self._execute_command(COMMAND.COM_QUERY, sql)
  File "/home/kallme/.local/lib/python3.5/site-packages/pymysql/connections.py", line 1071, in _execute_command
    raise err.InterfaceError("(0, '')")
pymysql.err.InterfaceError: (0, '')
106.51.138.236 - - [10/Jun/2017 07:32:20] "GET /user/add?__debugger__=yes&cmd=resource&f=style.css HTTP/1.1" 200 -
106.51.138.236 - - [10/Jun/2017 07:32:20] "GET /user/add?__debugger__=yes&cmd=resource&f=jquery.js HTTP/1.1" 200 -
106.51.138.236 - - [10/Jun/2017 07:33:14] "GET /user/add?__debugger__=yes&cmd=resource&f=debugger.js HTTP/1.1" 200 -
106.51.138.236 - - [10/Jun/2017 07:33:14] "GET /user/add?__debugger__=yes&cmd=resource&f=ubuntu.ttf HTTP/1.1" 200 -
106.51.138.236 - - [10/Jun/2017 07:33:15] "GET /user/add?__debugger__=yes&cmd=resource&f=console.png HTTP/1.1" 200 -
106.51.138.236 - - [10/Jun/2017 07:33:51] "GET /user/add?username=ritesh HTTP/1.1" 500 -
Traceback (most recent call last):
  File "/home/kallme/.local/lib/python3.5/site-packages/flask/app.py", line 1997, in __call__
    return self.wsgi_app(environ, start_response)
  File "/home/kallme/.local/lib/python3.5/site-packages/flask/app.py", line 1985, in wsgi_app
    response = self.handle_exception(e)
  File "/home/kallme/.local/lib/python3.5/site-packages/flask/app.py", line 1540, in handle_exception
    reraise(exc_type, exc_value, tb)
  File "/home/kallme/.local/lib/python3.5/site-packages/flask/_compat.py", line 33, in reraise
    raise value
  File "/home/kallme/.local/lib/python3.5/site-packages/flask/app.py", line 1982, in wsgi_app
    response = self.full_dispatch_request()
  File "/home/kallme/.local/lib/python3.5/site-packages/flask/app.py", line 1614, in full_dispatch_request
    rv = self.handle_user_exception(e)
  File "/home/kallme/.local/lib/python3.5/site-packages/flask/app.py", line 1517, in handle_user_exception
    reraise(exc_type, exc_value, tb)
  File "/home/kallme/.local/lib/python3.5/site-packages/flask/_compat.py", line 33, in reraise
    raise value
  File "/home/kallme/.local/lib/python3.5/site-packages/flask/app.py", line 1612, in full_dispatch_request
    rv = self.dispatch_request()
  File "/home/kallme/.local/lib/python3.5/site-packages/flask/app.py", line 1598, in dispatch_request
    return self.view_functions[rule.endpoint](**req.view_args)
  File "/var/www/apps/restserver/app/user/controllers.py", line 10, in add
    adddb(params)
  File "/var/www/apps/restserver/app/user/models.py", line 13, in adddb
    cursor.execute("INSERT INTO user (firstname,lastname,email,username,password) VALUES (%s,%s,%s,%s,%s)",(firstname,password,email,username,lastname))
  File "/home/kallme/.local/lib/python3.5/site-packages/pymysql/cursors.py", line 166, in execute
    result = self._query(query)
  File "/home/kallme/.local/lib/python3.5/site-packages/pymysql/cursors.py", line 322, in _query
    conn.query(q)
  File "/home/kallme/.local/lib/python3.5/site-packages/pymysql/connections.py", line 855, in query
    self._execute_command(COMMAND.COM_QUERY, sql)
  File "/home/kallme/.local/lib/python3.5/site-packages/pymysql/connections.py", line 1071, in _execute_command
    raise err.InterfaceError("(0, '')")
pymysql.err.InterfaceError: (0, '')
106.51.138.236 - - [10/Jun/2017 07:33:52] "GET /user/add?username=ritesh HTTP/1.1" 500 -
Traceback (most recent call last):
  File "/home/kallme/.local/lib/python3.5/site-packages/flask/app.py", line 1997, in __call__
    return self.wsgi_app(environ, start_response)
  File "/home/kallme/.local/lib/python3.5/site-packages/flask/app.py", line 1985, in wsgi_app
    response = self.handle_exception(e)
  File "/home/kallme/.local/lib/python3.5/site-packages/flask/app.py", line 1540, in handle_exception
    reraise(exc_type, exc_value, tb)
  File "/home/kallme/.local/lib/python3.5/site-packages/flask/_compat.py", line 33, in reraise
    raise value
  File "/home/kallme/.local/lib/python3.5/site-packages/flask/app.py", line 1982, in wsgi_app
    response = self.full_dispatch_request()
  File "/home/kallme/.local/lib/python3.5/site-packages/flask/app.py", line 1614, in full_dispatch_request
    rv = self.handle_user_exception(e)
  File "/home/kallme/.local/lib/python3.5/site-packages/flask/app.py", line 1517, in handle_user_exception
    reraise(exc_type, exc_value, tb)
  File "/home/kallme/.local/lib/python3.5/site-packages/flask/_compat.py", line 33, in reraise
    raise value
  File "/home/kallme/.local/lib/python3.5/site-packages/flask/app.py", line 1612, in full_dispatch_request
    rv = self.dispatch_request()
  File "/home/kallme/.local/lib/python3.5/site-packages/flask/app.py", line 1598, in dispatch_request
    return self.view_functions[rule.endpoint](**req.view_args)
  File "/var/www/apps/restserver/app/user/controllers.py", line 10, in add
    adddb(params)
  File "/var/www/apps/restserver/app/user/models.py", line 13, in adddb
    cursor.execute("INSERT INTO user (firstname,lastname,email,username,password) VALUES (%s,%s,%s,%s,%s)",(firstname,password,email,username,lastname))
  File "/home/kallme/.local/lib/python3.5/site-packages/pymysql/cursors.py", line 166, in execute
    result = self._query(query)
  File "/home/kallme/.local/lib/python3.5/site-packages/pymysql/cursors.py", line 322, in _query
    conn.query(q)
  File "/home/kallme/.local/lib/python3.5/site-packages/pymysql/connections.py", line 855, in query
    self._execute_command(COMMAND.COM_QUERY, sql)
  File "/home/kallme/.local/lib/python3.5/site-packages/pymysql/connections.py", line 1071, in _execute_command
    raise err.InterfaceError("(0, '')")
pymysql.err.InterfaceError: (0, '')
106.51.138.236 - - [10/Jun/2017 07:33:52] "GET /user/add?__debugger__=yes&cmd=resource&f=style.css HTTP/1.1" 200 -
106.51.138.236 - - [10/Jun/2017 07:33:52] "GET /user/add?__debugger__=yes&cmd=resource&f=jquery.js HTTP/1.1" 200 -
106.51.138.236 - - [10/Jun/2017 07:33:53] "GET /user/add?__debugger__=yes&cmd=resource&f=debugger.js HTTP/1.1" 200 -
106.51.138.236 - - [10/Jun/2017 07:33:54] "GET /user/add?__debugger__=yes&cmd=resource&f=ubuntu.ttf HTTP/1.1" 200 -
106.51.138.236 - - [10/Jun/2017 07:33:55] "GET /user/add?__debugger__=yes&cmd=resource&f=console.png HTTP/1.1" 200 -
106.51.138.236 - - [10/Jun/2017 07:34:22] "GET /user/add?username=ritesh HTTP/1.1" 500 -
Traceback (most recent call last):
  File "/home/kallme/.local/lib/python3.5/site-packages/flask/app.py", line 1997, in __call__
    return self.wsgi_app(environ, start_response)
  File "/home/kallme/.local/lib/python3.5/site-packages/flask/app.py", line 1985, in wsgi_app
    response = self.handle_exception(e)
  File "/home/kallme/.local/lib/python3.5/site-packages/flask/app.py", line 1540, in handle_exception
    reraise(exc_type, exc_value, tb)
  File "/home/kallme/.local/lib/python3.5/site-packages/flask/_compat.py", line 33, in reraise
    raise value
  File "/home/kallme/.local/lib/python3.5/site-packages/flask/app.py", line 1982, in wsgi_app
    response = self.full_dispatch_request()
  File "/home/kallme/.local/lib/python3.5/site-packages/flask/app.py", line 1614, in full_dispatch_request
    rv = self.handle_user_exception(e)
  File "/home/kallme/.local/lib/python3.5/site-packages/flask/app.py", line 1517, in handle_user_exception
    reraise(exc_type, exc_value, tb)
  File "/home/kallme/.local/lib/python3.5/site-packages/flask/_compat.py", line 33, in reraise
    raise value
  File "/home/kallme/.local/lib/python3.5/site-packages/flask/app.py", line 1612, in full_dispatch_request
    rv = self.dispatch_request()
  File "/home/kallme/.local/lib/python3.5/site-packages/flask/app.py", line 1598, in dispatch_request
    return self.view_functions[rule.endpoint](**req.view_args)
  File "/var/www/apps/restserver/app/user/controllers.py", line 10, in add
    adddb(params)
  File "/var/www/apps/restserver/app/user/models.py", line 13, in adddb
    cursor.execute("INSERT INTO user (firstname,lastname,email,username,password) VALUES (%s,%s,%s,%s,%s)",(firstname,password,email,username,lastname))
  File "/home/kallme/.local/lib/python3.5/site-packages/pymysql/cursors.py", line 166, in execute
    result = self._query(query)
  File "/home/kallme/.local/lib/python3.5/site-packages/pymysql/cursors.py", line 322, in _query
    conn.query(q)
  File "/home/kallme/.local/lib/python3.5/site-packages/pymysql/connections.py", line 855, in query
    self._execute_command(COMMAND.COM_QUERY, sql)
  File "/home/kallme/.local/lib/python3.5/site-packages/pymysql/connections.py", line 1071, in _execute_command
    raise err.InterfaceError("(0, '')")
pymysql.err.InterfaceError: (0, '')
106.51.138.236 - - [10/Jun/2017 07:34:23] "GET /user/add?__debugger__=yes&cmd=resource&f=style.css HTTP/1.1" 200 -
106.51.138.236 - - [10/Jun/2017 07:34:23] "GET /user/add?__debugger__=yes&cmd=resource&f=jquery.js HTTP/1.1" 200 -
106.51.138.236 - - [10/Jun/2017 07:34:24] "GET /user/add?__debugger__=yes&cmd=resource&f=debugger.js HTTP/1.1" 200 -
106.51.138.236 - - [10/Jun/2017 07:34:25] "GET /user/add?__debugger__=yes&cmd=resource&f=ubuntu.ttf HTTP/1.1" 200 -
106.51.138.236 - - [10/Jun/2017 07:34:26] "GET /user/add?__debugger__=yes&cmd=resource&f=console.png HTTP/1.1" 200 -
106.51.138.236 - - [10/Jun/2017 07:34:26] "GET /user/add?__debugger__=yes&cmd=resource&f=console.png HTTP/1.1" 200 -
106.51.138.236 - - [10/Jun/2017 07:34:45] "GET /user/add?username=ritesh HTTP/1.1" 500 -
Traceback (most recent call last):
  File "/home/kallme/.local/lib/python3.5/site-packages/flask/app.py", line 1997, in __call__
    return self.wsgi_app(environ, start_response)
  File "/home/kallme/.local/lib/python3.5/site-packages/flask/app.py", line 1985, in wsgi_app
    response = self.handle_exception(e)
  File "/home/kallme/.local/lib/python3.5/site-packages/flask/app.py", line 1540, in handle_exception
    reraise(exc_type, exc_value, tb)
  File "/home/kallme/.local/lib/python3.5/site-packages/flask/_compat.py", line 33, in reraise
    raise value
  File "/home/kallme/.local/lib/python3.5/site-packages/flask/app.py", line 1982, in wsgi_app
    response = self.full_dispatch_request()
  File "/home/kallme/.local/lib/python3.5/site-packages/flask/app.py", line 1614, in full_dispatch_request
    rv = self.handle_user_exception(e)
  File "/home/kallme/.local/lib/python3.5/site-packages/flask/app.py", line 1517, in handle_user_exception
    reraise(exc_type, exc_value, tb)
  File "/home/kallme/.local/lib/python3.5/site-packages/flask/_compat.py", line 33, in reraise
    raise value
  File "/home/kallme/.local/lib/python3.5/site-packages/flask/app.py", line 1612, in full_dispatch_request
    rv = self.dispatch_request()
  File "/home/kallme/.local/lib/python3.5/site-packages/flask/app.py", line 1598, in dispatch_request
    return self.view_functions[rule.endpoint](**req.view_args)
  File "/var/www/apps/restserver/app/user/controllers.py", line 10, in add
    adddb(params)
  File "/var/www/apps/restserver/app/user/models.py", line 13, in adddb
    cursor.execute("INSERT INTO user (firstname,lastname,email,username,password) VALUES (%s,%s,%s,%s,%s)",(firstname,password,email,username,lastname))
  File "/home/kallme/.local/lib/python3.5/site-packages/pymysql/cursors.py", line 166, in execute
    result = self._query(query)
  File "/home/kallme/.local/lib/python3.5/site-packages/pymysql/cursors.py", line 322, in _query
    conn.query(q)
  File "/home/kallme/.local/lib/python3.5/site-packages/pymysql/connections.py", line 855, in query
    self._execute_command(COMMAND.COM_QUERY, sql)
  File "/home/kallme/.local/lib/python3.5/site-packages/pymysql/connections.py", line 1071, in _execute_command
    raise err.InterfaceError("(0, '')")
pymysql.err.InterfaceError: (0, '')
106.51.138.236 - - [10/Jun/2017 07:34:46] "GET /user/add?__debugger__=yes&cmd=resource&f=jquery.js HTTP/1.1" 200 -
106.51.138.236 - - [10/Jun/2017 07:34:48] "GET /user/add?__debugger__=yes&cmd=resource&f=style.css HTTP/1.1" 200 -
106.51.138.236 - - [10/Jun/2017 07:34:48] "GET /user/add?__debugger__=yes&cmd=resource&f=debugger.js HTTP/1.1" 200 -
106.51.138.236 - - [10/Jun/2017 07:34:48] "GET /user/add?__debugger__=yes&cmd=resource&f=ubuntu.ttf HTTP/1.1" 200 -
106.51.138.236 - - [10/Jun/2017 07:34:49] "GET /user/add?__debugger__=yes&cmd=resource&f=console.png HTTP/1.1" 200 -
106.51.138.236 - - [10/Jun/2017 07:34:50] "GET /user/add?__debugger__=yes&cmd=resource&f=console.png HTTP/1.1" 200 -
 * Detected change in '/var/www/apps/restserver/app/user/models.py', reloading
 * Restarting with stat
 * Debugger is active!
 * Debugger PIN: 135-965-059
106.51.138.236 - - [10/Jun/2017 07:36:04] "GET /user/add?username=ritesh HTTP/1.1" 200 -
 * Detected change in '/var/www/apps/restserver/app/user/models.py', reloading
 * Restarting with stat
 * Debugger is active!
 * Debugger PIN: 135-965-059
106.51.138.236 - - [10/Jun/2017 07:36:56] "GET /user/add?username=ritesh HTTP/1.1" 200 -
106.51.138.236 - - [10/Jun/2017 07:36:59] "GET /user/add?username=ritesh HTTP/1.1" 500 -
Traceback (most recent call last):
  File "/home/kallme/.local/lib/python3.5/site-packages/flask/app.py", line 1997, in __call__
    return self.wsgi_app(environ, start_response)
  File "/home/kallme/.local/lib/python3.5/site-packages/flask/app.py", line 1985, in wsgi_app
    response = self.handle_exception(e)
  File "/home/kallme/.local/lib/python3.5/site-packages/flask/app.py", line 1540, in handle_exception
    reraise(exc_type, exc_value, tb)
  File "/home/kallme/.local/lib/python3.5/site-packages/flask/_compat.py", line 33, in reraise
    raise value
  File "/home/kallme/.local/lib/python3.5/site-packages/flask/app.py", line 1982, in wsgi_app
    response = self.full_dispatch_request()
  File "/home/kallme/.local/lib/python3.5/site-packages/flask/app.py", line 1614, in full_dispatch_request
    rv = self.handle_user_exception(e)
  File "/home/kallme/.local/lib/python3.5/site-packages/flask/app.py", line 1517, in handle_user_exception
    reraise(exc_type, exc_value, tb)
  File "/home/kallme/.local/lib/python3.5/site-packages/flask/_compat.py", line 33, in reraise
    raise value
  File "/home/kallme/.local/lib/python3.5/site-packages/flask/app.py", line 1612, in full_dispatch_request
    rv = self.dispatch_request()
  File "/home/kallme/.local/lib/python3.5/site-packages/flask/app.py", line 1598, in dispatch_request
    return self.view_functions[rule.endpoint](**req.view_args)
  File "/var/www/apps/restserver/app/user/controllers.py", line 10, in add
    adddb(params)
  File "/var/www/apps/restserver/app/user/models.py", line 13, in adddb
    cursor.execute("INSERT INTO user (firstname,lastname,email,username,password) VALUES (%s,%s,%s,%s,%s)",(firstname,password,email,username,lastname))
  File "/home/kallme/.local/lib/python3.5/site-packages/pymysql/cursors.py", line 166, in execute
    result = self._query(query)
  File "/home/kallme/.local/lib/python3.5/site-packages/pymysql/cursors.py", line 322, in _query
    conn.query(q)
  File "/home/kallme/.local/lib/python3.5/site-packages/pymysql/connections.py", line 855, in query
    self._execute_command(COMMAND.COM_QUERY, sql)
  File "/home/kallme/.local/lib/python3.5/site-packages/pymysql/connections.py", line 1071, in _execute_command
    raise err.InterfaceError("(0, '')")
pymysql.err.InterfaceError: (0, '')
106.51.138.236 - - [10/Jun/2017 07:36:59] "GET /user/add?__debugger__=yes&cmd=resource&f=jquery.js HTTP/1.1" 200 -
106.51.138.236 - - [10/Jun/2017 07:37:01] "GET /user/add?__debugger__=yes&cmd=resource&f=style.css HTTP/1.1" 200 -
106.51.138.236 - - [10/Jun/2017 07:37:01] "GET /user/add?__debugger__=yes&cmd=resource&f=debugger.js HTTP/1.1" 200 -
106.51.138.236 - - [10/Jun/2017 07:37:02] "GET /user/add?__debugger__=yes&cmd=resource&f=ubuntu.ttf HTTP/1.1" 200 -
106.51.138.236 - - [10/Jun/2017 07:37:03] "GET /user/add?__debugger__=yes&cmd=resource&f=console.png HTTP/1.1" 200 -
106.51.138.236 - - [10/Jun/2017 07:37:03] "GET /user/add?__debugger__=yes&cmd=resource&f=console.png HTTP/1.1" 200 -
106.51.138.236 - - [10/Jun/2017 07:37:05] "GET /user/add?username=ritesh HTTP/1.1" 500 -
Traceback (most recent call last):
  File "/home/kallme/.local/lib/python3.5/site-packages/flask/app.py", line 1997, in __call__
    return self.wsgi_app(environ, start_response)
  File "/home/kallme/.local/lib/python3.5/site-packages/flask/app.py", line 1985, in wsgi_app
    response = self.handle_exception(e)
  File "/home/kallme/.local/lib/python3.5/site-packages/flask/app.py", line 1540, in handle_exception
    reraise(exc_type, exc_value, tb)
  File "/home/kallme/.local/lib/python3.5/site-packages/flask/_compat.py", line 33, in reraise
    raise value
  File "/home/kallme/.local/lib/python3.5/site-packages/flask/app.py", line 1982, in wsgi_app
    response = self.full_dispatch_request()
  File "/home/kallme/.local/lib/python3.5/site-packages/flask/app.py", line 1614, in full_dispatch_request
    rv = self.handle_user_exception(e)
  File "/home/kallme/.local/lib/python3.5/site-packages/flask/app.py", line 1517, in handle_user_exception
    reraise(exc_type, exc_value, tb)
  File "/home/kallme/.local/lib/python3.5/site-packages/flask/_compat.py", line 33, in reraise
    raise value
  File "/home/kallme/.local/lib/python3.5/site-packages/flask/app.py", line 1612, in full_dispatch_request
    rv = self.dispatch_request()
  File "/home/kallme/.local/lib/python3.5/site-packages/flask/app.py", line 1598, in dispatch_request
    return self.view_functions[rule.endpoint](**req.view_args)
  File "/var/www/apps/restserver/app/user/controllers.py", line 10, in add
    adddb(params)
  File "/var/www/apps/restserver/app/user/models.py", line 13, in adddb
    cursor.execute("INSERT INTO user (firstname,lastname,email,username,password) VALUES (%s,%s,%s,%s,%s)",(firstname,password,email,username,lastname))
  File "/home/kallme/.local/lib/python3.5/site-packages/pymysql/cursors.py", line 166, in execute
    result = self._query(query)
  File "/home/kallme/.local/lib/python3.5/site-packages/pymysql/cursors.py", line 322, in _query
    conn.query(q)
  File "/home/kallme/.local/lib/python3.5/site-packages/pymysql/connections.py", line 855, in query
    self._execute_command(COMMAND.COM_QUERY, sql)
  File "/home/kallme/.local/lib/python3.5/site-packages/pymysql/connections.py", line 1071, in _execute_command
    raise err.InterfaceError("(0, '')")
pymysql.err.InterfaceError: (0, '')
106.51.138.236 - - [10/Jun/2017 07:37:07] "GET /user/add?__debugger__=yes&cmd=resource&f=style.css HTTP/1.1" 200 -
106.51.138.236 - - [10/Jun/2017 07:37:07] "GET /user/add?__debugger__=yes&cmd=resource&f=jquery.js HTTP/1.1" 200 -
106.51.138.236 - - [10/Jun/2017 07:37:08] "GET /user/add?__debugger__=yes&cmd=resource&f=debugger.js HTTP/1.1" 200 -
106.51.138.236 - - [10/Jun/2017 07:37:09] "GET /user/add?__debugger__=yes&cmd=resource&f=ubuntu.ttf HTTP/1.1" 200 -
106.51.138.236 - - [10/Jun/2017 07:37:10] "GET /user/add?__debugger__=yes&cmd=resource&f=console.png HTTP/1.1" 200 -
106.51.138.236 - - [10/Jun/2017 07:37:11] "GET /user/add?__debugger__=yes&cmd=resource&f=console.png HTTP/1.1" 200 -
106.51.138.236 - - [10/Jun/2017 07:37:21] "GET /user/add?username=ritesh HTTP/1.1" 500 -
Traceback (most recent call last):
  File "/home/kallme/.local/lib/python3.5/site-packages/flask/app.py", line 1997, in __call__
    return self.wsgi_app(environ, start_response)
  File "/home/kallme/.local/lib/python3.5/site-packages/flask/app.py", line 1985, in wsgi_app
    response = self.handle_exception(e)
  File "/home/kallme/.local/lib/python3.5/site-packages/flask/app.py", line 1540, in handle_exception
    reraise(exc_type, exc_value, tb)
  File "/home/kallme/.local/lib/python3.5/site-packages/flask/_compat.py", line 33, in reraise
    raise value
  File "/home/kallme/.local/lib/python3.5/site-packages/flask/app.py", line 1982, in wsgi_app
    response = self.full_dispatch_request()
  File "/home/kallme/.local/lib/python3.5/site-packages/flask/app.py", line 1614, in full_dispatch_request
    rv = self.handle_user_exception(e)
  File "/home/kallme/.local/lib/python3.5/site-packages/flask/app.py", line 1517, in handle_user_exception
    reraise(exc_type, exc_value, tb)
  File "/home/kallme/.local/lib/python3.5/site-packages/flask/_compat.py", line 33, in reraise
    raise value
  File "/home/kallme/.local/lib/python3.5/site-packages/flask/app.py", line 1612, in full_dispatch_request
    rv = self.dispatch_request()
  File "/home/kallme/.local/lib/python3.5/site-packages/flask/app.py", line 1598, in dispatch_request
    return self.view_functions[rule.endpoint](**req.view_args)
  File "/var/www/apps/restserver/app/user/controllers.py", line 10, in add
    adddb(params)
  File "/var/www/apps/restserver/app/user/models.py", line 13, in adddb
    cursor.execute("INSERT INTO user (firstname,lastname,email,username,password) VALUES (%s,%s,%s,%s,%s)",(firstname,password,email,username,lastname))
  File "/home/kallme/.local/lib/python3.5/site-packages/pymysql/cursors.py", line 166, in execute
    result = self._query(query)
  File "/home/kallme/.local/lib/python3.5/site-packages/pymysql/cursors.py", line 322, in _query
    conn.query(q)
  File "/home/kallme/.local/lib/python3.5/site-packages/pymysql/connections.py", line 855, in query
    self._execute_command(COMMAND.COM_QUERY, sql)
  File "/home/kallme/.local/lib/python3.5/site-packages/pymysql/connections.py", line 1071, in _execute_command
    raise err.InterfaceError("(0, '')")
pymysql.err.InterfaceError: (0, '')
106.51.138.236 - - [10/Jun/2017 07:37:21] "GET /user/add?__debugger__=yes&cmd=resource&f=jquery.js HTTP/1.1" 200 -
106.51.138.236 - - [10/Jun/2017 07:37:23] "GET /user/add?__debugger__=yes&cmd=resource&f=style.css HTTP/1.1" 200 -
106.51.138.236 - - [10/Jun/2017 07:37:38] "GET /user/add?__debugger__=yes&cmd=resource&f=debugger.js HTTP/1.1" 200 -
106.51.138.236 - - [10/Jun/2017 07:37:38] "GET /user/add?username=ritesh HTTP/1.1" 500 -
Traceback (most recent call last):
  File "/home/kallme/.local/lib/python3.5/site-packages/flask/app.py", line 1997, in __call__
    return self.wsgi_app(environ, start_response)
  File "/home/kallme/.local/lib/python3.5/site-packages/flask/app.py", line 1985, in wsgi_app
    response = self.handle_exception(e)
  File "/home/kallme/.local/lib/python3.5/site-packages/flask/app.py", line 1540, in handle_exception
    reraise(exc_type, exc_value, tb)
  File "/home/kallme/.local/lib/python3.5/site-packages/flask/_compat.py", line 33, in reraise
    raise value
  File "/home/kallme/.local/lib/python3.5/site-packages/flask/app.py", line 1982, in wsgi_app
    response = self.full_dispatch_request()
  File "/home/kallme/.local/lib/python3.5/site-packages/flask/app.py", line 1614, in full_dispatch_request
    rv = self.handle_user_exception(e)
  File "/home/kallme/.local/lib/python3.5/site-packages/flask/app.py", line 1517, in handle_user_exception
    reraise(exc_type, exc_value, tb)
  File "/home/kallme/.local/lib/python3.5/site-packages/flask/_compat.py", line 33, in reraise
    raise value
  File "/home/kallme/.local/lib/python3.5/site-packages/flask/app.py", line 1612, in full_dispatch_request
    rv = self.dispatch_request()
  File "/home/kallme/.local/lib/python3.5/site-packages/flask/app.py", line 1598, in dispatch_request
    return self.view_functions[rule.endpoint](**req.view_args)
  File "/var/www/apps/restserver/app/user/controllers.py", line 10, in add
    adddb(params)
  File "/var/www/apps/restserver/app/user/models.py", line 13, in adddb
    cursor.execute("INSERT INTO user (firstname,lastname,email,username,password) VALUES (%s,%s,%s,%s,%s)",(firstname,password,email,username,lastname))
  File "/home/kallme/.local/lib/python3.5/site-packages/pymysql/cursors.py", line 166, in execute
    result = self._query(query)
  File "/home/kallme/.local/lib/python3.5/site-packages/pymysql/cursors.py", line 322, in _query
    conn.query(q)
  File "/home/kallme/.local/lib/python3.5/site-packages/pymysql/connections.py", line 855, in query
    self._execute_command(COMMAND.COM_QUERY, sql)
  File "/home/kallme/.local/lib/python3.5/site-packages/pymysql/connections.py", line 1071, in _execute_command
    raise err.InterfaceError("(0, '')")
pymysql.err.InterfaceError: (0, '')
106.51.138.236 - - [10/Jun/2017 07:37:39] "GET /user/add?__debugger__=yes&cmd=resource&f=style.css HTTP/1.1" 200 -
106.51.138.236 - - [10/Jun/2017 07:37:39] "GET /user/add?__debugger__=yes&cmd=resource&f=debugger.js HTTP/1.1" 200 -
106.51.138.236 - - [10/Jun/2017 07:37:39] "GET /user/add?__debugger__=yes&cmd=resource&f=jquery.js HTTP/1.1" 200 -
106.51.138.236 - - [10/Jun/2017 07:37:42] "GET /user/add?__debugger__=yes&cmd=resource&f=ubuntu.ttf HTTP/1.1" 200 -
106.51.138.236 - - [10/Jun/2017 07:37:44] "GET /user/add?__debugger__=yes&cmd=resource&f=console.png HTTP/1.1" 200 -
106.51.138.236 - - [10/Jun/2017 07:37:44] "GET /user/add?__debugger__=yes&cmd=resource&f=console.png HTTP/1.1" 200 -
 * Detected change in '/var/www/apps/restserver/app/user/models.py', reloading
 * Restarting with stat
 * Debugger is active!
 * Debugger PIN: 135-965-059
106.51.138.236 - - [10/Jun/2017 07:38:21] "GET /user/add?username=ritesh HTTP/1.1" 200 -
106.51.138.236 - - [10/Jun/2017 07:40:01] "GET /user/add?username=ritesh HTTP/1.1" 500 -
Traceback (most recent call last):
  File "/home/kallme/.local/lib/python3.5/site-packages/flask/app.py", line 1997, in __call__
    return self.wsgi_app(environ, start_response)
  File "/home/kallme/.local/lib/python3.5/site-packages/flask/app.py", line 1985, in wsgi_app
    response = self.handle_exception(e)
  File "/home/kallme/.local/lib/python3.5/site-packages/flask/app.py", line 1540, in handle_exception
    reraise(exc_type, exc_value, tb)
  File "/home/kallme/.local/lib/python3.5/site-packages/flask/_compat.py", line 33, in reraise
    raise value
  File "/home/kallme/.local/lib/python3.5/site-packages/flask/app.py", line 1982, in wsgi_app
    response = self.full_dispatch_request()
  File "/home/kallme/.local/lib/python3.5/site-packages/flask/app.py", line 1614, in full_dispatch_request
    rv = self.handle_user_exception(e)
  File "/home/kallme/.local/lib/python3.5/site-packages/flask/app.py", line 1517, in handle_user_exception
    reraise(exc_type, exc_value, tb)
  File "/home/kallme/.local/lib/python3.5/site-packages/flask/_compat.py", line 33, in reraise
    raise value
  File "/home/kallme/.local/lib/python3.5/site-packages/flask/app.py", line 1612, in full_dispatch_request
    rv = self.dispatch_request()
  File "/home/kallme/.local/lib/python3.5/site-packages/flask/app.py", line 1598, in dispatch_request
    return self.view_functions[rule.endpoint](**req.view_args)
  File "/var/www/apps/restserver/app/user/controllers.py", line 10, in add
    adddb(params)
  File "/var/www/apps/restserver/app/user/models.py", line 13, in adddb
    cursor.execute("INSERT INTO user (firstname,lastname,email,username,password) VALUES (%s,%s,%s,%s,%s)",(firstname,password,email,username,lastname))
  File "/home/kallme/.local/lib/python3.5/site-packages/pymysql/cursors.py", line 166, in execute
    result = self._query(query)
  File "/home/kallme/.local/lib/python3.5/site-packages/pymysql/cursors.py", line 322, in _query
    conn.query(q)
  File "/home/kallme/.local/lib/python3.5/site-packages/pymysql/connections.py", line 855, in query
    self._execute_command(COMMAND.COM_QUERY, sql)
  File "/home/kallme/.local/lib/python3.5/site-packages/pymysql/connections.py", line 1071, in _execute_command
    raise err.InterfaceError("(0, '')")
pymysql.err.InterfaceError: (0, '')
106.51.138.236 - - [10/Jun/2017 07:40:04] "GET /user/add?username=ritesh HTTP/1.1" 500 -
Traceback (most recent call last):
  File "/home/kallme/.local/lib/python3.5/site-packages/flask/app.py", line 1997, in __call__
    return self.wsgi_app(environ, start_response)
  File "/home/kallme/.local/lib/python3.5/site-packages/flask/app.py", line 1985, in wsgi_app
    response = self.handle_exception(e)
  File "/home/kallme/.local/lib/python3.5/site-packages/flask/app.py", line 1540, in handle_exception
    reraise(exc_type, exc_value, tb)
  File "/home/kallme/.local/lib/python3.5/site-packages/flask/_compat.py", line 33, in reraise
    raise value
  File "/home/kallme/.local/lib/python3.5/site-packages/flask/app.py", line 1982, in wsgi_app
    response = self.full_dispatch_request()
  File "/home/kallme/.local/lib/python3.5/site-packages/flask/app.py", line 1614, in full_dispatch_request
    rv = self.handle_user_exception(e)
  File "/home/kallme/.local/lib/python3.5/site-packages/flask/app.py", line 1517, in handle_user_exception
    reraise(exc_type, exc_value, tb)
  File "/home/kallme/.local/lib/python3.5/site-packages/flask/_compat.py", line 33, in reraise
    raise value
  File "/home/kallme/.local/lib/python3.5/site-packages/flask/app.py", line 1612, in full_dispatch_request
    rv = self.dispatch_request()
  File "/home/kallme/.local/lib/python3.5/site-packages/flask/app.py", line 1598, in dispatch_request
    return self.view_functions[rule.endpoint](**req.view_args)
  File "/var/www/apps/restserver/app/user/controllers.py", line 10, in add
    adddb(params)
  File "/var/www/apps/restserver/app/user/models.py", line 13, in adddb
    cursor.execute("INSERT INTO user (firstname,lastname,email,username,password) VALUES (%s,%s,%s,%s,%s)",(firstname,password,email,username,lastname))
  File "/home/kallme/.local/lib/python3.5/site-packages/pymysql/cursors.py", line 166, in execute
    result = self._query(query)
  File "/home/kallme/.local/lib/python3.5/site-packages/pymysql/cursors.py", line 322, in _query
    conn.query(q)
  File "/home/kallme/.local/lib/python3.5/site-packages/pymysql/connections.py", line 855, in query
    self._execute_command(COMMAND.COM_QUERY, sql)
  File "/home/kallme/.local/lib/python3.5/site-packages/pymysql/connections.py", line 1071, in _execute_command
    raise err.InterfaceError("(0, '')")
pymysql.err.InterfaceError: (0, '')
106.51.138.236 - - [10/Jun/2017 07:40:05] "GET /user/add?__debugger__=yes&cmd=resource&f=jquery.js HTTP/1.1" 200 -
106.51.138.236 - - [10/Jun/2017 07:40:06] "GET /user/add?__debugger__=yes&cmd=resource&f=style.css HTTP/1.1" 200 -
106.51.138.236 - - [10/Jun/2017 07:40:06] "GET /user/add?__debugger__=yes&cmd=resource&f=debugger.js HTTP/1.1" 200 -
106.51.138.236 - - [10/Jun/2017 07:40:08] "GET /user/add?__debugger__=yes&cmd=resource&f=ubuntu.ttf HTTP/1.1" 200 -
106.51.138.236 - - [10/Jun/2017 07:40:08] "GET /user/add?__debugger__=yes&cmd=resource&f=console.png HTTP/1.1" 200 -
106.51.138.236 - - [10/Jun/2017 07:40:09] "GET /user/add?__debugger__=yes&cmd=resource&f=console.png HTTP/1.1" 200 -
 * Detected change in '/var/www/apps/restserver/app/user/models.py', reloading
 * Restarting with stat
 * Debugger is active!
 * Debugger PIN: 135-965-059
106.51.138.236 - - [10/Jun/2017 07:40:41] "GET /user/add?username=ritesh HTTP/1.1" 200 -
106.51.138.236 - - [10/Jun/2017 07:40:43] "GET /user/add?username=ritesh HTTP/1.1" 500 -
Traceback (most recent call last):
  File "/home/kallme/.local/lib/python3.5/site-packages/flask/app.py", line 1997, in __call__
    return self.wsgi_app(environ, start_response)
  File "/home/kallme/.local/lib/python3.5/site-packages/flask/app.py", line 1985, in wsgi_app
    response = self.handle_exception(e)
  File "/home/kallme/.local/lib/python3.5/site-packages/flask/app.py", line 1540, in handle_exception
    reraise(exc_type, exc_value, tb)
  File "/home/kallme/.local/lib/python3.5/site-packages/flask/_compat.py", line 33, in reraise
    raise value
  File "/home/kallme/.local/lib/python3.5/site-packages/flask/app.py", line 1982, in wsgi_app
    response = self.full_dispatch_request()
  File "/home/kallme/.local/lib/python3.5/site-packages/flask/app.py", line 1614, in full_dispatch_request
    rv = self.handle_user_exception(e)
  File "/home/kallme/.local/lib/python3.5/site-packages/flask/app.py", line 1517, in handle_user_exception
    reraise(exc_type, exc_value, tb)
  File "/home/kallme/.local/lib/python3.5/site-packages/flask/_compat.py", line 33, in reraise
    raise value
  File "/home/kallme/.local/lib/python3.5/site-packages/flask/app.py", line 1612, in full_dispatch_request
    rv = self.dispatch_request()
  File "/home/kallme/.local/lib/python3.5/site-packages/flask/app.py", line 1598, in dispatch_request
    return self.view_functions[rule.endpoint](**req.view_args)
  File "/var/www/apps/restserver/app/user/controllers.py", line 10, in add
    adddb(params)
  File "/var/www/apps/restserver/app/user/models.py", line 13, in adddb
    cursor.execute("INSERT INTO user (firstname,lastname,email,username,password) VALUES (%s,%s,%s,%s,%s)",(firstname,password,email,username,lastname))
  File "/home/kallme/.local/lib/python3.5/site-packages/pymysql/cursors.py", line 166, in execute
    result = self._query(query)
  File "/home/kallme/.local/lib/python3.5/site-packages/pymysql/cursors.py", line 322, in _query
    conn.query(q)
  File "/home/kallme/.local/lib/python3.5/site-packages/pymysql/connections.py", line 855, in query
    self._execute_command(COMMAND.COM_QUERY, sql)
  File "/home/kallme/.local/lib/python3.5/site-packages/pymysql/connections.py", line 1071, in _execute_command
    raise err.InterfaceError("(0, '')")
pymysql.err.InterfaceError: (0, '')
106.51.138.236 - - [10/Jun/2017 07:40:44] "GET /user/add?__debugger__=yes&cmd=resource&f=style.css HTTP/1.1" 200 -
106.51.138.236 - - [10/Jun/2017 07:40:44] "GET /user/add?__debugger__=yes&cmd=resource&f=jquery.js HTTP/1.1" 200 -
106.51.138.236 - - [10/Jun/2017 07:40:45] "GET /user/add?__debugger__=yes&cmd=resource&f=debugger.js HTTP/1.1" 200 -
106.51.138.236 - - [10/Jun/2017 07:40:46] "GET /user/add?__debugger__=yes&cmd=resource&f=ubuntu.ttf HTTP/1.1" 200 -
106.51.138.236 - - [10/Jun/2017 07:40:47] "GET /user/add?__debugger__=yes&cmd=resource&f=console.png HTTP/1.1" 200 -
106.51.138.236 - - [10/Jun/2017 07:40:47] "GET /user/add?__debugger__=yes&cmd=resource&f=console.png HTTP/1.1" 200 -
106.51.138.236 - - [10/Jun/2017 07:40:49] "GET /user/add?username=ritesh HTTP/1.1" 500 -
Traceback (most recent call last):
  File "/home/kallme/.local/lib/python3.5/site-packages/flask/app.py", line 1997, in __call__
    return self.wsgi_app(environ, start_response)
  File "/home/kallme/.local/lib/python3.5/site-packages/flask/app.py", line 1985, in wsgi_app
    response = self.handle_exception(e)
  File "/home/kallme/.local/lib/python3.5/site-packages/flask/app.py", line 1540, in handle_exception
    reraise(exc_type, exc_value, tb)
  File "/home/kallme/.local/lib/python3.5/site-packages/flask/_compat.py", line 33, in reraise
    raise value
  File "/home/kallme/.local/lib/python3.5/site-packages/flask/app.py", line 1982, in wsgi_app
    response = self.full_dispatch_request()
  File "/home/kallme/.local/lib/python3.5/site-packages/flask/app.py", line 1614, in full_dispatch_request
    rv = self.handle_user_exception(e)
  File "/home/kallme/.local/lib/python3.5/site-packages/flask/app.py", line 1517, in handle_user_exception
    reraise(exc_type, exc_value, tb)
  File "/home/kallme/.local/lib/python3.5/site-packages/flask/_compat.py", line 33, in reraise
    raise value
  File "/home/kallme/.local/lib/python3.5/site-packages/flask/app.py", line 1612, in full_dispatch_request
    rv = self.dispatch_request()
  File "/home/kallme/.local/lib/python3.5/site-packages/flask/app.py", line 1598, in dispatch_request
    return self.view_functions[rule.endpoint](**req.view_args)
  File "/var/www/apps/restserver/app/user/controllers.py", line 10, in add
    adddb(params)
  File "/var/www/apps/restserver/app/user/models.py", line 13, in adddb
    cursor.execute("INSERT INTO user (firstname,lastname,email,username,password) VALUES (%s,%s,%s,%s,%s)",(firstname,password,email,username,lastname))
  File "/home/kallme/.local/lib/python3.5/site-packages/pymysql/cursors.py", line 166, in execute
    result = self._query(query)
  File "/home/kallme/.local/lib/python3.5/site-packages/pymysql/cursors.py", line 322, in _query
    conn.query(q)
  File "/home/kallme/.local/lib/python3.5/site-packages/pymysql/connections.py", line 855, in query
    self._execute_command(COMMAND.COM_QUERY, sql)
  File "/home/kallme/.local/lib/python3.5/site-packages/pymysql/connections.py", line 1071, in _execute_command
    raise err.InterfaceError("(0, '')")
pymysql.err.InterfaceError: (0, '')
106.51.138.236 - - [10/Jun/2017 07:40:50] "GET /user/add?__debugger__=yes&cmd=resource&f=style.css HTTP/1.1" 200 -
106.51.138.236 - - [10/Jun/2017 07:40:50] "GET /user/add?__debugger__=yes&cmd=resource&f=jquery.js HTTP/1.1" 200 -
106.51.138.236 - - [10/Jun/2017 07:40:51] "GET /user/add?__debugger__=yes&cmd=resource&f=debugger.js HTTP/1.1" 200 -
106.51.138.236 - - [10/Jun/2017 07:40:52] "GET /user/add?__debugger__=yes&cmd=resource&f=ubuntu.ttf HTTP/1.1" 200 -
106.51.138.236 - - [10/Jun/2017 07:40:53] "GET /user/add?__debugger__=yes&cmd=resource&f=console.png HTTP/1.1" 200 -
106.51.138.236 - - [10/Jun/2017 07:40:54] "GET /user/add?__debugger__=yes&cmd=resource&f=console.png HTTP/1.1" 200 -
 * Detected change in '/var/www/apps/restserver/app/user/models.py', reloading
 * Restarting with stat
 * Debugger is active!
 * Debugger PIN: 135-965-059
 * Detected change in '/var/www/apps/restserver/config.py', reloading
 * Restarting with stat
 * Debugger is active!
 * Debugger PIN: 135-965-059
 * Detected change in '/var/www/apps/restserver/db.py', reloading
 * Restarting with stat
 * Debugger is active!
 * Debugger PIN: 135-965-059
 * Detected change in '/var/www/apps/restserver/app/user/models.py', reloading
 * Restarting with stat
 * Debugger is active!
 * Debugger PIN: 135-965-059
106.51.138.236 - - [10/Jun/2017 07:44:31] "GET /user/add?username=ritesh HTTP/1.1" 200 -
106.51.138.236 - - [10/Jun/2017 07:44:33] "GET /user/add?username=ritesh HTTP/1.1" 500 -
Traceback (most recent call last):
  File "/home/kallme/.local/lib/python3.5/site-packages/flask/app.py", line 1997, in __call__
    return self.wsgi_app(environ, start_response)
  File "/home/kallme/.local/lib/python3.5/site-packages/flask/app.py", line 1985, in wsgi_app
    response = self.handle_exception(e)
  File "/home/kallme/.local/lib/python3.5/site-packages/flask/app.py", line 1540, in handle_exception
    reraise(exc_type, exc_value, tb)
  File "/home/kallme/.local/lib/python3.5/site-packages/flask/_compat.py", line 33, in reraise
    raise value
  File "/home/kallme/.local/lib/python3.5/site-packages/flask/app.py", line 1982, in wsgi_app
    response = self.full_dispatch_request()
  File "/home/kallme/.local/lib/python3.5/site-packages/flask/app.py", line 1614, in full_dispatch_request
    rv = self.handle_user_exception(e)
  File "/home/kallme/.local/lib/python3.5/site-packages/flask/app.py", line 1517, in handle_user_exception
    reraise(exc_type, exc_value, tb)
  File "/home/kallme/.local/lib/python3.5/site-packages/flask/_compat.py", line 33, in reraise
    raise value
  File "/home/kallme/.local/lib/python3.5/site-packages/flask/app.py", line 1612, in full_dispatch_request
    rv = self.dispatch_request()
  File "/home/kallme/.local/lib/python3.5/site-packages/flask/app.py", line 1598, in dispatch_request
    return self.view_functions[rule.endpoint](**req.view_args)
  File "/var/www/apps/restserver/app/user/controllers.py", line 10, in add
    adddb(params)
  File "/var/www/apps/restserver/app/user/models.py", line 14, in adddb
    cursor.execute("INSERT INTO user (firstname,lastname,email,username,password) VALUES (%s,%s,%s,%s,%s)",(firstname,password,email,username,lastname))
  File "/home/kallme/.local/lib/python3.5/site-packages/pymysql/cursors.py", line 166, in execute
    result = self._query(query)
  File "/home/kallme/.local/lib/python3.5/site-packages/pymysql/cursors.py", line 322, in _query
    conn.query(q)
  File "/home/kallme/.local/lib/python3.5/site-packages/pymysql/connections.py", line 855, in query
    self._execute_command(COMMAND.COM_QUERY, sql)
  File "/home/kallme/.local/lib/python3.5/site-packages/pymysql/connections.py", line 1071, in _execute_command
    raise err.InterfaceError("(0, '')")
pymysql.err.InterfaceError: (0, '')
106.51.138.236 - - [10/Jun/2017 07:44:34] "GET /user/add?__debugger__=yes&cmd=resource&f=jquery.js HTTP/1.1" 200 -
106.51.138.236 - - [10/Jun/2017 07:44:35] "GET /user/add?__debugger__=yes&cmd=resource&f=style.css HTTP/1.1" 200 -
106.51.138.236 - - [10/Jun/2017 07:44:45] "GET /user/add?__debugger__=yes&cmd=resource&f=debugger.js HTTP/1.1" 200 -
106.51.138.236 - - [10/Jun/2017 07:44:45] "GET /user/add?username=ritesh HTTP/1.1" 500 -
Traceback (most recent call last):
  File "/home/kallme/.local/lib/python3.5/site-packages/flask/app.py", line 1997, in __call__
    return self.wsgi_app(environ, start_response)
  File "/home/kallme/.local/lib/python3.5/site-packages/flask/app.py", line 1985, in wsgi_app
    response = self.handle_exception(e)
  File "/home/kallme/.local/lib/python3.5/site-packages/flask/app.py", line 1540, in handle_exception
    reraise(exc_type, exc_value, tb)
  File "/home/kallme/.local/lib/python3.5/site-packages/flask/_compat.py", line 33, in reraise
    raise value
  File "/home/kallme/.local/lib/python3.5/site-packages/flask/app.py", line 1982, in wsgi_app
    response = self.full_dispatch_request()
  File "/home/kallme/.local/lib/python3.5/site-packages/flask/app.py", line 1614, in full_dispatch_request
    rv = self.handle_user_exception(e)
  File "/home/kallme/.local/lib/python3.5/site-packages/flask/app.py", line 1517, in handle_user_exception
    reraise(exc_type, exc_value, tb)
  File "/home/kallme/.local/lib/python3.5/site-packages/flask/_compat.py", line 33, in reraise
    raise value
  File "/home/kallme/.local/lib/python3.5/site-packages/flask/app.py", line 1612, in full_dispatch_request
    rv = self.dispatch_request()
  File "/home/kallme/.local/lib/python3.5/site-packages/flask/app.py", line 1598, in dispatch_request
    return self.view_functions[rule.endpoint](**req.view_args)
  File "/var/www/apps/restserver/app/user/controllers.py", line 10, in add
    adddb(params)
  File "/var/www/apps/restserver/app/user/models.py", line 14, in adddb
    cursor.execute("INSERT INTO user (firstname,lastname,email,username,password) VALUES (%s,%s,%s,%s,%s)",(firstname,password,email,username,lastname))
  File "/home/kallme/.local/lib/python3.5/site-packages/pymysql/cursors.py", line 166, in execute
    result = self._query(query)
  File "/home/kallme/.local/lib/python3.5/site-packages/pymysql/cursors.py", line 322, in _query
    conn.query(q)
  File "/home/kallme/.local/lib/python3.5/site-packages/pymysql/connections.py", line 855, in query
    self._execute_command(COMMAND.COM_QUERY, sql)
  File "/home/kallme/.local/lib/python3.5/site-packages/pymysql/connections.py", line 1071, in _execute_command
    raise err.InterfaceError("(0, '')")
pymysql.err.InterfaceError: (0, '')
106.51.138.236 - - [10/Jun/2017 07:44:46] "GET /user/add?__debugger__=yes&cmd=resource&f=style.css HTTP/1.1" 200 -
106.51.138.236 - - [10/Jun/2017 07:44:46] "GET /user/add?__debugger__=yes&cmd=resource&f=jquery.js HTTP/1.1" 200 -
106.51.138.236 - - [10/Jun/2017 07:44:47] "GET /user/add?__debugger__=yes&cmd=resource&f=debugger.js HTTP/1.1" 200 -
106.51.138.236 - - [10/Jun/2017 07:44:48] "GET /user/add?__debugger__=yes&cmd=resource&f=ubuntu.ttf HTTP/1.1" 200 -
106.51.138.236 - - [10/Jun/2017 07:44:48] "GET /user/add?__debugger__=yes&cmd=resource&f=console.png HTTP/1.1" 200 -
106.51.138.236 - - [10/Jun/2017 07:44:49] "GET /user/add?__debugger__=yes&cmd=resource&f=console.png HTTP/1.1" 200 -
106.51.138.236 - - [10/Jun/2017 07:44:51] "GET /user/add?username=ritesh HTTP/1.1" 500 -
Traceback (most recent call last):
  File "/home/kallme/.local/lib/python3.5/site-packages/flask/app.py", line 1997, in __call__
    return self.wsgi_app(environ, start_response)
  File "/home/kallme/.local/lib/python3.5/site-packages/flask/app.py", line 1985, in wsgi_app
    response = self.handle_exception(e)
  File "/home/kallme/.local/lib/python3.5/site-packages/flask/app.py", line 1540, in handle_exception
    reraise(exc_type, exc_value, tb)
  File "/home/kallme/.local/lib/python3.5/site-packages/flask/_compat.py", line 33, in reraise
    raise value
  File "/home/kallme/.local/lib/python3.5/site-packages/flask/app.py", line 1982, in wsgi_app
    response = self.full_dispatch_request()
  File "/home/kallme/.local/lib/python3.5/site-packages/flask/app.py", line 1614, in full_dispatch_request
    rv = self.handle_user_exception(e)
  File "/home/kallme/.local/lib/python3.5/site-packages/flask/app.py", line 1517, in handle_user_exception
    reraise(exc_type, exc_value, tb)
  File "/home/kallme/.local/lib/python3.5/site-packages/flask/_compat.py", line 33, in reraise
    raise value
  File "/home/kallme/.local/lib/python3.5/site-packages/flask/app.py", line 1612, in full_dispatch_request
    rv = self.dispatch_request()
  File "/home/kallme/.local/lib/python3.5/site-packages/flask/app.py", line 1598, in dispatch_request
    return self.view_functions[rule.endpoint](**req.view_args)
  File "/var/www/apps/restserver/app/user/controllers.py", line 10, in add
    adddb(params)
  File "/var/www/apps/restserver/app/user/models.py", line 14, in adddb
    cursor.execute("INSERT INTO user (firstname,lastname,email,username,password) VALUES (%s,%s,%s,%s,%s)",(firstname,password,email,username,lastname))
  File "/home/kallme/.local/lib/python3.5/site-packages/pymysql/cursors.py", line 166, in execute
    result = self._query(query)
  File "/home/kallme/.local/lib/python3.5/site-packages/pymysql/cursors.py", line 322, in _query
    conn.query(q)
  File "/home/kallme/.local/lib/python3.5/site-packages/pymysql/connections.py", line 855, in query
    self._execute_command(COMMAND.COM_QUERY, sql)
  File "/home/kallme/.local/lib/python3.5/site-packages/pymysql/connections.py", line 1071, in _execute_command
    raise err.InterfaceError("(0, '')")
pymysql.err.InterfaceError: (0, '')
106.51.138.236 - - [10/Jun/2017 07:44:52] "GET /user/add?__debugger__=yes&cmd=resource&f=jquery.js HTTP/1.1" 200 -
106.51.138.236 - - [10/Jun/2017 07:44:53] "GET /user/add?__debugger__=yes&cmd=resource&f=style.css HTTP/1.1" 200 -
106.51.138.236 - - [10/Jun/2017 07:44:53] "GET /user/add?__debugger__=yes&cmd=resource&f=debugger.js HTTP/1.1" 200 -
106.51.138.236 - - [10/Jun/2017 07:44:54] "GET /user/add?__debugger__=yes&cmd=resource&f=ubuntu.ttf HTTP/1.1" 200 -
106.51.138.236 - - [10/Jun/2017 07:44:55] "GET /user/add?__debugger__=yes&cmd=resource&f=console.png HTTP/1.1" 200 -
106.51.138.236 - - [10/Jun/2017 07:44:56] "GET /user/add?__debugger__=yes&cmd=resource&f=console.png HTTP/1.1" 200 -
106.51.141.48 - - [10/Jun/2017 07:49:50] "GET /user/add?username=ritesh HTTP/1.1" 500 -
Traceback (most recent call last):
  File "/home/kallme/.local/lib/python3.5/site-packages/flask/app.py", line 1997, in __call__
    return self.wsgi_app(environ, start_response)
  File "/home/kallme/.local/lib/python3.5/site-packages/flask/app.py", line 1985, in wsgi_app
    response = self.handle_exception(e)
  File "/home/kallme/.local/lib/python3.5/site-packages/flask/app.py", line 1540, in handle_exception
    reraise(exc_type, exc_value, tb)
  File "/home/kallme/.local/lib/python3.5/site-packages/flask/_compat.py", line 33, in reraise
    raise value
  File "/home/kallme/.local/lib/python3.5/site-packages/flask/app.py", line 1982, in wsgi_app
    response = self.full_dispatch_request()
  File "/home/kallme/.local/lib/python3.5/site-packages/flask/app.py", line 1614, in full_dispatch_request
    rv = self.handle_user_exception(e)
  File "/home/kallme/.local/lib/python3.5/site-packages/flask/app.py", line 1517, in handle_user_exception
    reraise(exc_type, exc_value, tb)
  File "/home/kallme/.local/lib/python3.5/site-packages/flask/_compat.py", line 33, in reraise
    raise value
  File "/home/kallme/.local/lib/python3.5/site-packages/flask/app.py", line 1612, in full_dispatch_request
    rv = self.dispatch_request()
  File "/home/kallme/.local/lib/python3.5/site-packages/flask/app.py", line 1598, in dispatch_request
    return self.view_functions[rule.endpoint](**req.view_args)
  File "/var/www/apps/restserver/app/user/controllers.py", line 10, in add
    adddb(params)
  File "/var/www/apps/restserver/app/user/models.py", line 14, in adddb
    cursor.execute("INSERT INTO user (firstname,lastname,email,username,password) VALUES (%s,%s,%s,%s,%s)",(firstname,password,email,username,lastname))
  File "/home/kallme/.local/lib/python3.5/site-packages/pymysql/cursors.py", line 166, in execute
    result = self._query(query)
  File "/home/kallme/.local/lib/python3.5/site-packages/pymysql/cursors.py", line 322, in _query
    conn.query(q)
  File "/home/kallme/.local/lib/python3.5/site-packages/pymysql/connections.py", line 855, in query
    self._execute_command(COMMAND.COM_QUERY, sql)
  File "/home/kallme/.local/lib/python3.5/site-packages/pymysql/connections.py", line 1071, in _execute_command
    raise err.InterfaceError("(0, '')")
pymysql.err.InterfaceError: (0, '')
106.51.141.48 - - [10/Jun/2017 07:49:52] "GET /user/add?__debugger__=yes&cmd=resource&f=style.css HTTP/1.1" 200 -
106.51.141.48 - - [10/Jun/2017 07:49:52] "GET /user/add?__debugger__=yes&cmd=resource&f=debugger.js HTTP/1.1" 200 -
106.51.141.48 - - [10/Jun/2017 07:49:52] "GET /user/add?__debugger__=yes&cmd=resource&f=jquery.js HTTP/1.1" 200 -
106.51.141.48 - - [10/Jun/2017 07:49:55] "GET /user/add?__debugger__=yes&cmd=resource&f=ubuntu.ttf HTTP/1.1" 200 -
106.51.141.48 - - [10/Jun/2017 07:49:56] "GET /user/add?__debugger__=yes&cmd=resource&f=console.png HTTP/1.1" 200 -
106.51.141.48 - - [10/Jun/2017 07:49:57] "GET /user/add?__debugger__=yes&cmd=resource&f=console.png HTTP/1.1" 200 -
 * Detected change in '/var/www/apps/restserver/app/user/models.py', reloading
 * Restarting with stat
 * Debugger is active!
 * Debugger PIN: 135-965-059
106.51.241.237 - - [10/Jun/2017 07:52:14] "GET /user/add?username=ritesh HTTP/1.1" 200 -
106.51.241.237 - - [10/Jun/2017 07:52:14] "GET /user/add?username=ritesh HTTP/1.1" 500 -
 * Running on http://0.0.0.0:5000/ (Press CTRL+C to quit)
 * Restarting with stat
 * Debugger is active!
 * Debugger PIN: 135-965-059
106.51.232.42 - - [12/Jun/2017 08:48:09] "GET /user/add?username=ritesh HTTP/1.1" 200 -
 * Detected change in '/var/www/kallme/apps/restserver/app/user/controllers.py', reloading
 * Restarting with stat
 * Debugger is active!
 * Debugger PIN: 135-965-059
--------------------------------------------------------------------------------
INFO in controllers [/var/www/kallme/apps/restserver/app/user/controllers.py:15]:
testing info log
--------------------------------------------------------------------------------
106.51.232.42 - - [12/Jun/2017 08:49:55] "GET /user/add?username=ritesh HTTP/1.1" 200 -
 * Detected change in '/var/www/kallme/apps/restserver/app/user/controllers.py', reloading
 * Restarting with stat
 * Debugger is active!
 * Debugger PIN: 135-965-059
 * Detected change in '/var/www/kallme/apps/restserver/app/user/controllers.py', reloading
 * Restarting with stat
 * Debugger is active!
 * Debugger PIN: 135-965-059
 * Detected change in '/var/www/kallme/apps/restserver/app/user/controllers.py', reloading
 * Restarting with stat
 * Debugger is active!
 * Debugger PIN: 135-965-059
 * Detected change in '/var/www/kallme/apps/restserver/app/user/controllers.py', reloading
 * Restarting with stat
 * Debugger is active!
 * Debugger PIN: 135-965-059
 * Detected change in '/var/www/kallme/apps/restserver/app/user/controllers.py', reloading
 * Restarting with stat
 * Debugger is active!
 * Debugger PIN: 135-965-059
 * Detected change in '/var/www/kallme/apps/restserver/app/user/controllers.py', reloading
 * Restarting with stat
 * Debugger is active!
 * Debugger PIN: 135-965-059
 * Running on http://0.0.0.0:5000/ (Press CTRL+C to quit)
 * Restarting with stat
 * Debugger is active!
 * Debugger PIN: 135-965-059
106.51.232.42 - - [12/Jun/2017 08:56:19] "GET /user/add?username=ritesh HTTP/1.1" 500 -
Traceback (most recent call last):
  File "/home/kallme/.local/lib/python3.5/site-packages/flask/app.py", line 1997, in __call__
    return self.wsgi_app(environ, start_response)
  File "/home/kallme/.local/lib/python3.5/site-packages/flask/app.py", line 1985, in wsgi_app
    response = self.handle_exception(e)
  File "/home/kallme/.local/lib/python3.5/site-packages/flask/app.py", line 1540, in handle_exception
    reraise(exc_type, exc_value, tb)
  File "/home/kallme/.local/lib/python3.5/site-packages/flask/_compat.py", line 33, in reraise
    raise value
  File "/home/kallme/.local/lib/python3.5/site-packages/flask/app.py", line 1982, in wsgi_app
    response = self.full_dispatch_request()
  File "/home/kallme/.local/lib/python3.5/site-packages/flask/app.py", line 1614, in full_dispatch_request
    rv = self.handle_user_exception(e)
  File "/home/kallme/.local/lib/python3.5/site-packages/flask/app.py", line 1517, in handle_user_exception
    reraise(exc_type, exc_value, tb)
  File "/home/kallme/.local/lib/python3.5/site-packages/flask/_compat.py", line 33, in reraise
    raise value
  File "/home/kallme/.local/lib/python3.5/site-packages/flask/app.py", line 1612, in full_dispatch_request
    rv = self.dispatch_request()
  File "/home/kallme/.local/lib/python3.5/site-packages/flask/app.py", line 1598, in dispatch_request
    return self.view_functions[rule.endpoint](**req.view_args)
  File "/var/www/kallme/apps/restserver/app/user/controllers.py", line 15, in add
    user.logger.info("test")
AttributeError: 'Blueprint' object has no attribute 'logger'
106.51.232.42 - - [12/Jun/2017 08:56:20] "GET /user/add?__debugger__=yes&cmd=resource&f=style.css HTTP/1.1" 200 -
106.51.232.42 - - [12/Jun/2017 08:56:20] "GET /user/add?__debugger__=yes&cmd=resource&f=jquery.js HTTP/1.1" 200 -
106.51.232.42 - - [12/Jun/2017 08:56:21] "GET /user/add?__debugger__=yes&cmd=resource&f=debugger.js HTTP/1.1" 200 -
106.51.232.42 - - [12/Jun/2017 08:56:22] "GET /user/add?__debugger__=yes&cmd=resource&f=ubuntu.ttf HTTP/1.1" 200 -
106.51.232.42 - - [12/Jun/2017 08:56:22] "GET /user/add?__debugger__=yes&cmd=resource&f=console.png HTTP/1.1" 200 -
106.51.232.42 - - [12/Jun/2017 08:56:23] "GET /user/add?__debugger__=yes&cmd=resource&f=console.png HTTP/1.1" 200 -
 * Detected change in '/var/www/kallme/apps/restserver/app/user/controllers.py', reloading
 * Restarting with stat
 * Debugger is active!
 * Debugger PIN: 135-965-059
--------------------------------------------------------------------------------
INFO in controllers [/var/www/kallme/apps/restserver/app/user/controllers.py:15]:
test
--------------------------------------------------------------------------------
106.51.232.42 - - [12/Jun/2017 08:57:25] "GET /user/add?username=ritesh HTTP/1.1" 200 -
 * Detected change in '/var/www/kallme/apps/restserver/app/user/controllers.py', reloading
 * Restarting with stat
 * Debugger is active!
 * Debugger PIN: 135-965-059
 * Detected change in '/var/www/kallme/apps/restserver/run.py', reloading
 * Restarting with stat
 * Debugger is active!
 * Debugger PIN: 135-965-059
 * Running on http://0.0.0.0:5000/ (Press CTRL+C to quit)
 * Restarting with stat
 * Debugger is active!
 * Debugger PIN: 135-965-059
--------------------------------------------------------------------------------
INFO in controllers [/var/www/kallme/apps/restserver/app/user/controllers.py:15]:
test
--------------------------------------------------------------------------------
106.51.232.42 - - [12/Jun/2017 09:04:58] "GET /user/add?username=ritesh HTTP/1.1" 200 -
--------------------------------------------------------------------------------
INFO in controllers [/var/www/kallme/apps/restserver/app/user/controllers.py:15]:
test
--------------------------------------------------------------------------------
106.51.232.42 - - [12/Jun/2017 09:05:17] "GET /user/add?username=ritesh HTTP/1.1" 200 -
 * Detected change in '/var/www/kallme/apps/restserver/run.py', reloading
 * Restarting with stat
 * Debugger is active!
 * Debugger PIN: 135-965-059
 * Running on http://0.0.0.0:5000/ (Press CTRL+C to quit)
 * Restarting with stat
 * Debugger is active!
 * Debugger PIN: 135-965-059
--------------------------------------------------------------------------------
INFO in controllers [/var/www/kallme/apps/restserver/app/user/controllers.py:15]:
test
--------------------------------------------------------------------------------
106.51.232.42 - - [12/Jun/2017 09:12:36] "GET /user/add?username=ritesh HTTP/1.1" 200 -
 * Detected change in '/var/www/kallme/apps/restserver/app/user/controllers.py', reloading
 * Restarting with stat
 * Debugger is active!
 * Debugger PIN: 135-965-059
--------------------------------------------------------------------------------
DEBUG in controllers [/var/www/kallme/apps/restserver/app/user/controllers.py:15]:
test
--------------------------------------------------------------------------------
106.51.232.42 - - [12/Jun/2017 09:14:02] "GET /user/add?username=ritesh HTTP/1.1" 200 -
--------------------------------------------------------------------------------
DEBUG in controllers [/var/www/kallme/apps/restserver/app/user/controllers.py:15]:
test
--------------------------------------------------------------------------------
106.51.232.42 - - [12/Jun/2017 09:14:12] "GET /user/add?username=ritesh HTTP/1.1" 200 -
--------------------------------------------------------------------------------
DEBUG in controllers [/var/www/kallme/apps/restserver/app/user/controllers.py:15]:
test
--------------------------------------------------------------------------------
106.51.232.42 - - [12/Jun/2017 09:14:14] "GET /user/add?username=ritesh HTTP/1.1" 200 -
--------------------------------------------------------------------------------
DEBUG in controllers [/var/www/kallme/apps/restserver/app/user/controllers.py:15]:
test
--------------------------------------------------------------------------------
64.233.172.184 - - [12/Jun/2017 21:26:06] "GET /user/add?username=ritesh HTTP/1.1" 200 -
64.233.172.182 - - [12/Jun/2017 21:26:06] "GET /favicon.ico HTTP/1.1" 404 -
185.127.27.186 - - [13/Jun/2017 14:26:05] code 400, message Bad HTTP/0.9 request type ('\x03\x00\x00+&à\x00\x00\x00\x00\x00Cookie:')
185.127.27.186 - - [13/Jun/2017 14:26:05] "  +&à     Cookie: mstshash=hello" HTTPStatus.BAD_REQUEST -
185.127.27.186 - - [13/Jun/2017 15:06:02] code 400, message Bad HTTP/0.9 request type ('\x03\x00\x00+&à\x00\x00\x00\x00\x00Cookie:')
185.127.27.186 - - [13/Jun/2017 15:06:02] "  +&à     Cookie: mstshash=hello" HTTPStatus.BAD_REQUEST -
185.127.27.186 - - [13/Jun/2017 15:46:04] code 400, message Bad HTTP/0.9 request type ('\x03\x00\x00+&à\x00\x00\x00\x00\x00Cookie:')
185.127.27.186 - - [13/Jun/2017 15:46:04] "  +&à     Cookie: mstshash=hello" HTTPStatus.BAD_REQUEST -
--------------------------------------------------------------------------------
DEBUG in controllers [/var/www/kallme/apps/restserver/app/user/controllers.py:15]:
test
--------------------------------------------------------------------------------
66.102.6.116 - - [13/Jun/2017 21:56:41] "GET /user/add?username=ritesh HTTP/1.1" 200 -
66.102.6.116 - - [13/Jun/2017 21:56:42] "GET /favicon.ico HTTP/1.1" 404 -
--------------------------------------------------------------------------------
DEBUG in controllers [/var/www/kallme/apps/restserver/app/user/controllers.py:15]:
test
--------------------------------------------------------------------------------
106.51.37.161 - - [13/Jun/2017 22:50:03] "GET /user/add?username=ritesh HTTP/1.1" 200 -
--------------------------------------------------------------------------------
DEBUG in controllers [/var/www/kallme/apps/restserver/app/user/controllers.py:15]:
test
--------------------------------------------------------------------------------
106.51.37.161 - - [13/Jun/2017 22:50:24] "GET /user/add?username=ritesh HTTP/1.1" 200 -
91.197.234.40 - - [14/Jun/2017 04:27:17] code 400, message Bad HTTP/0.9 request type ("\x03\x00\x00,'à\x00\x00\x00\x00\x00Cookie:")
91.197.234.40 - - [14/Jun/2017 04:27:17] "  ,'à     Cookie: mstshash=eltons" HTTPStatus.BAD_REQUEST -
168.1.128.53 - - [14/Jun/2017 22:26:45] "GET / HTTP/1.1" 404 -
168.1.128.53 - - [14/Jun/2017 22:26:45] "GET / HTTP/1.1" 404 -
196.52.43.51 - - [15/Jun/2017 09:46:16] "GET / HTTP/1.1" 404 -
146.185.239.25 - - [16/Jun/2017 14:15:34] code 400, message Bad HTTP/0.9 request type ('\x03\x00\x00*%à\x00\x00\x00\x00\x00Cookie:')
146.185.239.25 - - [16/Jun/2017 14:15:34] "  *%à     Cookie: mstshash=Test" HTTPStatus.BAD_REQUEST -
146.185.239.25 - - [16/Jun/2017 14:15:35] code 400, message Bad HTTP/0.9 request type ('\x03\x00\x00*%à\x00\x00\x00\x00\x00Cookie:')
146.185.239.25 - - [16/Jun/2017 14:15:35] "  *%à     Cookie: mstshash=Test" HTTPStatus.BAD_REQUEST -
46.17.98.64 - - [19/Jun/2017 02:32:28] code 400, message Bad HTTP/0.9 request type ('\x03\x00\x00*%à\x00\x00\x00\x00\x00Cookie:')
46.17.98.64 - - [19/Jun/2017 02:32:28] "  *%à     Cookie: mstshash=Test" HTTPStatus.BAD_REQUEST -
46.17.98.64 - - [19/Jun/2017 02:32:29] code 400, message Bad HTTP/0.9 request type ('\x03\x00\x00*%à\x00\x00\x00\x00\x00Cookie:')
46.17.98.64 - - [19/Jun/2017 02:32:29] "  *%à     Cookie: mstshash=Test" HTTPStatus.BAD_REQUEST -
196.52.43.62 - - [19/Jun/2017 15:42:31] "GET / HTTP/1.1" 404 -
91.197.235.10 - - [19/Jun/2017 22:25:55] code 400, message Bad HTTP/0.9 request type ("\x03\x00\x00,'à\x00\x00\x00\x00\x00Cookie:")
91.197.235.10 - - [19/Jun/2017 22:25:55] "  ,'à     Cookie: mstshash=eltons" HTTPStatus.BAD_REQUEST -
168.1.128.35 - - [20/Jun/2017 16:47:46] "GET / HTTP/1.1" 404 -
109.248.203.179 - - [21/Jun/2017 03:07:53] code 400, message Bad HTTP/0.9 request type ('\x03\x00\x00+&à\x00\x00\x00\x00\x00Cookie:')
109.248.203.179 - - [21/Jun/2017 03:07:53] "  +&à     Cookie: mstshash=hello" HTTPStatus.BAD_REQUEST -
109.248.203.179 - - [21/Jun/2017 03:52:33] code 400, message Bad HTTP/0.9 request type ('\x03\x00\x00+&à\x00\x00\x00\x00\x00Cookie:')
109.248.203.179 - - [21/Jun/2017 03:52:33] "  +&à     Cookie: mstshash=hello" HTTPStatus.BAD_REQUEST -
109.248.203.179 - - [21/Jun/2017 04:37:02] code 400, message Bad HTTP/0.9 request type ('\x03\x00\x00+&à\x00\x00\x00\x00\x00Cookie:')
109.248.203.179 - - [21/Jun/2017 04:37:02] "  +&à     Cookie: mstshash=hello" HTTPStatus.BAD_REQUEST -
158.85.81.126 - - [21/Jun/2017 10:58:08] "GET / HTTP/1.1" 404 -
212.7.208.111 - - [21/Jun/2017 13:00:24] code 400, message Bad HTTP/0.9 request type ('\x03\x00\x00*%à\x00\x00\x00\x00\x00Cookie:')
212.7.208.111 - - [21/Jun/2017 13:00:24] "  *%à     Cookie: mstshash=Test" HTTPStatus.BAD_REQUEST -
212.7.208.111 - - [21/Jun/2017 13:00:25] code 400, message Bad HTTP/0.9 request type ('\x03\x00\x00*%à\x00\x00\x00\x00\x00Cookie:')
212.7.208.111 - - [21/Jun/2017 13:00:25] "  *%à     Cookie: mstshash=Test" HTTPStatus.BAD_REQUEST -
91.218.114.146 - - [21/Jun/2017 15:54:32] code 400, message Bad HTTP/0.9 request type ('\x03\x00\x00&!à\x00\x00\x00\x00\x00Cookie:')
91.218.114.146 - - [21/Jun/2017 15:54:32] "  &!à     Cookie: mstshash=" HTTPStatus.BAD_REQUEST -
 * Detected change in '/var/www/kallme/apps/restserver/run.py', reloading
 * Restarting with stat
 * Debugger is active!
 * Debugger PIN: 135-965-059
169.53.184.5 - - [22/Jun/2017 22:28:57] "GET / HTTP/1.1" 404 -
 * Detected change in '/var/www/kallme/apps/restserver/run.py', reloading
 * Restarting with stat
 * Debugger is active!
 * Debugger PIN: 135-965-059
5.188.11.104 - - [23/Jun/2017 00:48:56] code 400, message Bad HTTP/0.9 request type ("\x03\x00\x00,'à\x00\x00\x00\x00\x00Cookie:")
5.188.11.104 - - [23/Jun/2017 00:48:56] "  ,'à     Cookie: mstshash=eltons" HTTPStatus.BAD_REQUEST -
196.52.43.58 - - [23/Jun/2017 17:44:26] "GET / HTTP/1.1" 404 -
 * Detected change in '/var/www/kallme/apps/restserver/app/user/models.py', reloading
 * Restarting with stat
 * Debugger is active!
 * Debugger PIN: 135-965-059
 * Detected change in '/var/www/kallme/apps/restserver/app/user/models.py', reloading
 * Restarting with stat
 * Debugger is active!
 * Debugger PIN: 135-965-059
106.51.242.87 - - [24/Jun/2017 06:21:00] "GET / HTTP/1.1" 404 -
106.51.242.87 - - [24/Jun/2017 06:21:00] "GET /favicon.ico HTTP/1.1" 404 -
 * Running on http://0.0.0.0:5000/ (Press CTRL+C to quit)
 * Restarting with stat
 * Debugger is active!
 * Debugger PIN: 135-965-059
45.33.12.203 - - [25/Jun/2017 10:52:38] "GET / HTTP/1.0" 404 -
5.188.11.103 - - [25/Jun/2017 20:55:52] code 400, message Bad HTTP/0.9 request type ("\x03\x00\x00,'à\x00\x00\x00\x00\x00Cookie:")
5.188.11.103 - - [25/Jun/2017 20:55:52] "  ,'à     Cookie: mstshash=eltons" HTTPStatus.BAD_REQUEST -
106.51.235.58 - - [26/Jun/2017 07:01:25] "GET /user/list HTTP/1.1" 200 -
106.51.235.58 - - [26/Jun/2017 07:01:26] "GET /favicon.ico HTTP/1.1" 404 -
106.51.235.58 - - [26/Jun/2017 08:52:57] "GET /user/list HTTP/1.1" 200 -
 * Detected change in '/var/www/kallme/apps/restserver/app/user/controllers.py', reloading
 * Restarting with stat
Traceback (most recent call last):
  File "run.py", line 1, in <module>
    from app import app
  File "/var/www/kallme/apps/restserver/app/__init__.py", line 4, in <module>
    from app.user.controllers import user
  File "/var/www/kallme/apps/restserver/app/user/controllers.py", line 34
    return jsonify(listuser())
         ^
SyntaxError: invalid syntax
 * Running on http://0.0.0.0:5000/ (Press CTRL+C to quit)
 * Restarting with stat
 * Debugger is active!
 * Debugger PIN: 135-965-059
106.51.129.1 - - [02/Jul/2017 10:14:58] "GET /user/list HTTP/1.1" 200 -
106.51.243.10 - - [02/Jul/2017 11:29:04] "GET /user/list HTTP/1.1" 200 -
106.51.128.67 - - [03/Jul/2017 09:28:20] "GET /user/list HTTP/1.1" 200 -
5.188.11.103 - - [03/Jul/2017 19:03:04] code 400, message Bad HTTP/0.9 request type ("\x03\x00\x00,'à\x00\x00\x00\x00\x00Cookie:")
5.188.11.103 - - [03/Jul/2017 19:03:04] "  ,'à     Cookie: mstshash=eltons" HTTPStatus.BAD_REQUEST -
106.205.89.220 - - [03/Jul/2017 23:46:31] "GET /user/list HTTP/1.1" 200 -
64.233.173.15 - - [04/Jul/2017 02:36:22] "GET /user/list HTTP/1.1" 200 -
168.1.128.37 - - [04/Jul/2017 16:06:08] "GET / HTTP/1.1" 404 -
158.85.81.126 - - [04/Jul/2017 21:38:56] "GET / HTTP/1.1" 404 -
46.17.47.89 - - [04/Jul/2017 22:00:32] "GET / HTTP/1.1" 404 -
169.54.244.84 - - [05/Jul/2017 01:32:48] "GET / HTTP/1.1" 404 -
169.54.244.84 - - [05/Jul/2017 01:32:51] "GET / HTTP/1.1" 404 -
169.54.244.84 - - [05/Jul/2017 01:32:52] "GET / HTTP/1.1" 404 -
169.54.244.84 - - [05/Jul/2017 01:32:58] "GET / HTTP/1.1" 404 -
5.188.11.103 - - [06/Jul/2017 00:57:59] code 400, message Bad HTTP/0.9 request type ("\x03\x00\x00,'à\x00\x00\x00\x00\x00Cookie:")
5.188.11.103 - - [06/Jul/2017 00:57:59] "  ,'à     Cookie: mstshash=eltons" HTTPStatus.BAD_REQUEST -
64.233.173.16 - - [06/Jul/2017 08:25:46] "GET /user/list HTTP/1.1" 200 -
64.233.173.17 - - [06/Jul/2017 18:59:40] "GET /user/list HTTP/1.1" 200 -
54.179.173.195 - - [06/Jul/2017 19:45:19] "GET / HTTP/1.1" 404 -
106.51.37.161 - - [06/Jul/2017 21:24:50] "GET /user/list HTTP/1.1" 200 -
169.54.244.78 - - [07/Jul/2017 08:52:00] "GET / HTTP/1.1" 404 -
169.54.244.78 - - [07/Jul/2017 08:52:02] "GET / HTTP/1.1" 404 -
169.54.244.78 - - [07/Jul/2017 08:52:05] "GET / HTTP/1.1" 404 -
169.54.244.78 - - [07/Jul/2017 08:52:10] "GET / HTTP/1.1" 404 -
91.197.232.10 - - [07/Jul/2017 17:02:06] code 400, message Bad HTTP/0.9 request type ('\x03\x00\x00+&à\x00\x00\x00\x00\x00Cookie:')
91.197.232.10 - - [07/Jul/2017 17:02:06] "  +&à     Cookie: mstshash=hello" HTTPStatus.BAD_REQUEST -
212.92.123.35 - - [08/Jul/2017 00:18:49] code 400, message Bad HTTP/0.9 request type ('\x03\x00\x00+&à\x00\x00\x00\x00\x00Cookie:')
212.92.123.35 - - [08/Jul/2017 00:18:49] "  +&à     Cookie: mstshash=hello" HTTPStatus.BAD_REQUEST -
 * Detected change in '/var/www/kallme/apps/restserver/app/__init__.py', reloading
 * Restarting with stat
 * Debugger is active!
 * Debugger PIN: 135-965-059
 * Detected change in '/var/www/kallme/apps/restserver/app/category/models.py', reloading
 * Restarting with stat
 * Debugger is active!
 * Debugger PIN: 135-965-059
 * Detected change in '/var/www/kallme/apps/restserver/app/category/models.py', reloading
 * Restarting with stat
 * Debugger is active!
 * Debugger PIN: 135-965-059
 * Detected change in '/var/www/kallme/apps/restserver/db.py', reloading
 * Restarting with stat
 * Debugger is active!
 * Debugger PIN: 135-965-059
 * Detected change in '/var/www/kallme/apps/restserver/app/category/models.py', reloading
 * Restarting with stat
Traceback (most recent call last):
  File "run.py", line 1, in <module>
    from app import app
  File "/var/www/kallme/apps/restserver/app/__init__.py", line 6, in <module>
    from app.category.controllers import category
  File "/var/www/kallme/apps/restserver/app/category/controllers.py", line 8, in <module>
    from . models import *
  File "/var/www/kallme/apps/restserver/app/category/models.py", line 13
    conn.close()
       ^
SyntaxError: invalid syntax
 * Running on http://0.0.0.0:5000/ (Press CTRL+C to quit)
 * Restarting with stat
 * Debugger is active!
 * Debugger PIN: 135-965-059
106.51.136.197 - - [09/Jul/2017 06:55:29] "GET /user/list HTTP/1.1" 200 -
64.233.173.17 - - [09/Jul/2017 20:08:09] "GET /user/list HTTP/1.1" 200 -
106.51.37.161 - - [09/Jul/2017 21:19:49] "GET /user/list HTTP/1.1" 200 -
64.233.173.17 - - [10/Jul/2017 05:14:02] "GET / HTTP/1.1" 404 -
64.233.173.17 - - [10/Jul/2017 05:14:03] "GET /favicon.ico HTTP/1.1" 404 -
64.233.173.17 - - [10/Jul/2017 05:14:15] "GET /user/list HTTP/1.1" 200 -
106.201.120.102 - - [10/Jul/2017 05:20:19] "GET /user/list HTTP/1.1" 200 -
106.201.120.125 - - [10/Jul/2017 05:20:20] "GET /favicon.ico HTTP/1.1" 404 -
14.141.179.130 - - [10/Jul/2017 05:20:53] "GET /category/list HTTP/1.1" 200 -
106.216.180.235 - - [10/Jul/2017 05:57:47] "GET /user/list HTTP/1.1" 200 -
106.216.180.235 - - [10/Jul/2017 06:08:11] "GET /user/list HTTP/1.1" 200 -
106.216.180.235 - - [10/Jul/2017 06:10:59] "GET /user/list HTTP/1.1" 200 -
103.210.133.248 - - [10/Jul/2017 06:35:11] "GET /user/list HTTP/1.1" 200 -
103.210.133.248 - - [10/Jul/2017 06:37:28] "GET /user/list HTTP/1.1" 200 -
103.210.133.248 - - [10/Jul/2017 06:38:02] "GET /user/list HTTP/1.1" 200 -
103.210.133.248 - - [10/Jul/2017 06:41:26] "GET /user/list HTTP/1.1" 200 -
103.210.133.248 - - [10/Jul/2017 06:50:06] "GET /user/list HTTP/1.1" 200 -
103.210.133.248 - - [10/Jul/2017 06:50:18] "GET /user/list HTTP/1.1" 200 -
103.210.133.248 - - [10/Jul/2017 06:58:26] "GET /user/list HTTP/1.1" 200 -
103.227.97.189 - - [10/Jul/2017 08:53:59] "GET /user/list HTTP/1.1" 200 -
 * Detected change in '/var/www/kallme/apps/restserver/app/category/models.py', reloading
 * Restarting with stat
 * Debugger is active!
 * Debugger PIN: 135-965-059
66.102.6.24 - - [10/Jul/2017 09:14:51] "GET /category/list HTTP/1.1" 200 -
66.102.6.20 - - [10/Jul/2017 09:14:52] "GET /favicon.ico HTTP/1.1" 404 -
103.227.97.189 - - [10/Jul/2017 09:14:53] "GET /category/list HTTP/1.1" 200 -
 * Detected change in '/var/www/kallme/apps/restserver/app/category/models.py', reloading
 * Restarting with stat
 * Debugger is active!
 * Debugger PIN: 135-965-059
 * Detected change in '/var/www/kallme/apps/restserver/app/category/controllers.py', reloading
 * Restarting with stat
Traceback (most recent call last):
  File "run.py", line 1, in <module>
    from app import app
  File "/var/www/kallme/apps/restserver/app/__init__.py", line 6, in <module>
    from app.category.controllers import category
  File "/var/www/kallme/apps/restserver/app/category/controllers.py", line 26
    print obj["categoryname"]
            ^
SyntaxError: Missing parentheses in call to 'print'
Traceback (most recent call last):
  File "run.py", line 1, in <module>
    from app import app
  File "/var/www/kallme/apps/restserver/app/__init__.py", line 6, in <module>
    from app.category.controllers import category
  File "/var/www/kallme/apps/restserver/app/category/controllers.py", line 28
    category["data"] = obj["subcategoryname"]
                                            ^
IndentationError: unindent does not match any outer indentation level
 * Running on http://0.0.0.0:5000/ (Press CTRL+C to quit)
 * Restarting with stat
 * Debugger is active!
 * Debugger PIN: 135-965-059
103.227.97.189 - - [10/Jul/2017 11:52:06] "GET /user/list HTTP/1.1" 200 -
 * Detected change in '/var/www/kallme/apps/restserver/app/category/controllers.py', reloading
 * Restarting with stat
 * Debugger is active!
 * Debugger PIN: 135-965-059
103.227.97.189 - - [10/Jul/2017 11:56:16] "GET /category/list HTTP/1.1" 200 -
103.227.97.189 - - [10/Jul/2017 11:56:23] "GET /category/list HTTP/1.1" 200 -
103.227.97.189 - - [10/Jul/2017 11:56:33] "GET /category/list HTTP/1.1" 200 -
103.227.97.189 - - [10/Jul/2017 11:56:37] "GET /category/list HTTP/1.1" 200 -
103.227.97.189 - - [10/Jul/2017 11:56:40] "GET /category/list HTTP/1.1" 200 -
103.227.97.189 - - [10/Jul/2017 11:56:42] "GET /category/list HTTP/1.1" 200 -
103.227.97.189 - - [10/Jul/2017 11:56:43] "GET /category/list HTTP/1.1" 200 -
103.227.97.189 - - [10/Jul/2017 11:57:05] "GET /category/list HTTP/1.1" 200 -
103.227.97.189 - - [10/Jul/2017 11:57:05] "GET /category/list HTTP/1.1" 200 -
103.227.97.189 - - [10/Jul/2017 11:57:06] "GET /category/list HTTP/1.1" 200 -
5.188.11.103 - - [10/Jul/2017 12:41:52] code 400, message Bad HTTP/0.9 request type ("\x03\x00\x00,'à\x00\x00\x00\x00\x00Cookie:")
5.188.11.103 - - [10/Jul/2017 12:41:52] "  ,'à     Cookie: mstshash=eltons" HTTPStatus.BAD_REQUEST -
66.102.6.20 - - [10/Jul/2017 21:32:12] "GET /category/list HTTP/1.1" 200 -
66.102.6.22 - - [10/Jul/2017 21:32:12] "GET /favicon.ico HTTP/1.1" 404 -
66.102.6.24 - - [10/Jul/2017 22:01:19] "GET /category/list HTTP/1.1" 200 -
64.233.173.15 - - [10/Jul/2017 22:40:02] "GET /user/list HTTP/1.1" 200 -
5.153.234.67 - - [10/Jul/2017 23:51:57] code 400, message Bad HTTP/0.9 request type ('\x03\x00\x00+&à\x00\x00\x00\x00\x00Cookie:')
5.153.234.67 - - [10/Jul/2017 23:51:57] "  +&à     Cookie: mstshash=hello" HTTPStatus.BAD_REQUEST -
5.153.234.67 - - [11/Jul/2017 00:10:43] code 400, message Bad HTTP/0.9 request type ('\x03\x00\x00+&à\x00\x00\x00\x00\x00Cookie:')
5.153.234.67 - - [11/Jul/2017 00:10:43] "  +&à     Cookie: mstshash=hello" HTTPStatus.BAD_REQUEST -
158.85.81.122 - - [11/Jul/2017 02:05:05] "GET / HTTP/1.1" 404 -
106.51.134.97 - - [11/Jul/2017 09:58:24] "GET /user/list HTTP/1.1" 200 -
196.52.43.55 - - [11/Jul/2017 12:18:23] "GET / HTTP/1.1" 404 -
158.85.81.120 - - [11/Jul/2017 14:36:50] "GET / HTTP/1.1" 404 -
5.39.216.150 - - [12/Jul/2017 04:46:53] code 400, message Bad HTTP/0.9 request type ('\x03\x00\x00*%à\x00\x00\x00\x00\x00Cookie:')
5.39.216.150 - - [12/Jul/2017 04:46:53] "  *%à     Cookie: mstshash=Test" HTTPStatus.BAD_REQUEST -
5.39.216.150 - - [12/Jul/2017 04:46:56] code 400, message Bad HTTP/0.9 request type ('\x03\x00\x00*%à\x00\x00\x00\x00\x00Cookie:')
5.39.216.150 - - [12/Jul/2017 04:46:56] "  *%à     Cookie: mstshash=Test" HTTPStatus.BAD_REQUEST -
 * Detected change in '/var/www/kallme/apps/restserver/app/category/controllers.py', reloading
 * Restarting with stat
 * Debugger is active!
 * Debugger PIN: 135-965-059
106.51.137.66 - - [12/Jul/2017 09:31:14] "GET /user/list HTTP/1.1" 200 -
 * Running on http://0.0.0.0:5000/ (Press CTRL+C to quit)
 * Restarting with stat
 * Debugger is active!
 * Debugger PIN: 135-965-059
106.51.137.66 - - [12/Jul/2017 09:50:55] "GET /user/list HTTP/1.1" 200 -
106.51.137.66 - - [12/Jul/2017 09:53:26] "GET /category/list HTTP/1.1" 200 -
106.51.137.66 - - [12/Jul/2017 09:53:26] "GET /favicon.ico HTTP/1.1" 404 -
106.51.137.181 - - [12/Jul/2017 10:52:46] "GET /user/list HTTP/1.1" 200 -
106.51.137.181 - - [12/Jul/2017 10:52:46] "GET /category/list HTTP/1.1" 200 -
106.51.137.181 - - [12/Jul/2017 10:54:16] "GET /user/list HTTP/1.1" 200 -
106.51.137.181 - - [12/Jul/2017 10:54:16] "GET /category/list HTTP/1.1" 200 -
106.51.137.181 - - [12/Jul/2017 10:54:44] "GET /user/list HTTP/1.1" 200 -
106.51.137.181 - - [12/Jul/2017 10:54:44] "GET /category/list HTTP/1.1" 200 -
 * Detected change in '/var/www/kallme/apps/restserver/app/category/models.py', reloading
 * Restarting with stat
 * Debugger is active!
 * Debugger PIN: 135-965-059
 * Detected change in '/var/www/kallme/apps/restserver/app/category/controllers.py', reloading
 * Restarting with stat
 * Debugger is active!
 * Debugger PIN: 135-965-059
 * Detected change in '/var/www/kallme/apps/restserver/app/category/models.py', reloading
 * Restarting with stat
 * Debugger is active!
 * Debugger PIN: 135-965-059
64.233.173.16 - - [12/Jul/2017 18:25:21] "GET /user/list HTTP/1.1" 200 -
64.233.173.15 - - [12/Jul/2017 18:25:21] "GET /category/list HTTP/1.1" 200 -
106.51.140.44 - - [12/Jul/2017 23:58:26] "GET /user/list HTTP/1.1" 200 -
106.51.140.44 - - [12/Jul/2017 23:58:26] "GET /category/list HTTP/1.1" 200 -
5.188.11.103 - - [13/Jul/2017 04:41:19] code 400, message Bad HTTP/0.9 request type ("\x03\x00\x00,'à\x00\x00\x00\x00\x00Cookie:")
5.188.11.103 - - [13/Jul/2017 04:41:19] "  ,'à     Cookie: mstshash=eltons" HTTPStatus.BAD_REQUEST -
106.51.135.186 - - [13/Jul/2017 07:57:59] "GET /user/list HTTP/1.1" 200 -
106.51.135.186 - - [13/Jul/2017 07:57:59] "GET /category/list HTTP/1.1" 200 -
169.54.92.142 - - [13/Jul/2017 08:11:35] "GET / HTTP/1.1" 404 -
106.51.135.186 - - [13/Jul/2017 09:32:58] "GET /user/list HTTP/1.1" 200 -
106.51.135.186 - - [13/Jul/2017 09:32:58] "GET /category/list HTTP/1.1" 200 -
103.227.97.50 - - [13/Jul/2017 20:43:17] "GET /user/list HTTP/1.1" 200 -
103.227.97.50 - - [13/Jul/2017 20:43:17] "GET /category/list HTTP/1.1" 200 -
103.227.97.50 - - [13/Jul/2017 20:43:20] "GET /user/list HTTP/1.1" 200 -
103.227.97.50 - - [13/Jul/2017 20:43:20] "GET /category/list HTTP/1.1" 200 -
103.227.97.50 - - [13/Jul/2017 20:43:22] "GET /category/list HTTP/1.1" 200 -
103.227.97.50 - - [13/Jul/2017 20:43:42] "GET /favicon.ico HTTP/1.1" 404 -
 * Detected change in '/var/www/kallme/apps/restserver/app/category/models.py', reloading
 * Restarting with stat
Traceback (most recent call last):
  File "run.py", line 1, in <module>
    from app import app
  File "/var/www/kallme/apps/restserver/app/__init__.py", line 6, in <module>
    from app.category.controllers import category
  File "/var/www/kallme/apps/restserver/app/category/controllers.py", line 8, in <module>
    from . models import *
  File "/var/www/kallme/apps/restserver/app/category/models.py", line 30
    cursor =conn.cursor(pymysql.cursors.DictCursor)
                                                  ^
TabError: inconsistent use of tabs and spaces in indentation
 * Running on http://0.0.0.0:5000/ (Press CTRL+C to quit)
 * Restarting with stat
 * Debugger is active!
 * Debugger PIN: 135-965-059
106.51.139.215 - - [13/Jul/2017 23:44:41] "GET /user/list HTTP/1.1" 200 -
106.51.139.215 - - [13/Jul/2017 23:44:41] "GET /category/list HTTP/1.1" 200 -
 * Detected change in '/var/www/kallme/apps/restserver/app/category/models.py', reloading
 * Restarting with stat
Traceback (most recent call last):
  File "run.py", line 1, in <module>
    from app import app
  File "/var/www/kallme/apps/restserver/app/__init__.py", line 6, in <module>
    from app.category.controllers import category
  File "/var/www/kallme/apps/restserver/app/category/controllers.py", line 8, in <module>
    from . models import *
  File "/var/www/kallme/apps/restserver/app/category/models.py", line 32
    qry = "SELECT " + tbl_category_dtls.get('name') + "." + tbl_category_dtls.get('columns')[1] + " FROM " + tbl_category_dtls.get('name') + " WHERE " tbl_category_dtls.get('columns')[2]+ "=1"
                                                                                                                                                                       ^
SyntaxError: invalid syntax
 * Running on http://0.0.0.0:5000/ (Press CTRL+C to quit)
 * Restarting with stat
 * Debugger is active!
 * Debugger PIN: 135-965-059
106.51.139.215 - - [13/Jul/2017 23:51:24] "GET /user/list HTTP/1.1" 200 -
106.51.139.215 - - [13/Jul/2017 23:51:24] "GET /category/list HTTP/1.1" 200 -
106.51.139.215 - - [13/Jul/2017 23:52:06] "GET /user/list HTTP/1.1" 200 -
106.51.139.215 - - [13/Jul/2017 23:52:06] "GET /category/list HTTP/1.1" 200 -
106.51.139.215 - - [13/Jul/2017 23:52:38] "GET /user/list HTTP/1.1" 200 -
106.51.139.215 - - [13/Jul/2017 23:52:38] "GET /category/list HTTP/1.1" 200 -
196.52.43.60 - - [14/Jul/2017 00:39:07] "GET / HTTP/1.1" 404 -
106.51.233.189 - - [14/Jul/2017 01:00:33] "GET /user/list HTTP/1.1" 200 -
106.51.233.189 - - [14/Jul/2017 01:00:33] "GET /category/list HTTP/1.1" 200 -
 * Running on http://0.0.0.0:5000/ (Press CTRL+C to quit)
 * Restarting with stat
 * Debugger is active!
 * Debugger PIN: 135-965-059
106.51.243.243 - - [14/Jul/2017 02:42:22] "GET /user/list HTTP/1.1" 200 -
106.51.243.243 - - [14/Jul/2017 02:42:22] "GET /category/list HTTP/1.1" 200 -
106.51.242.168 - - [14/Jul/2017 07:22:02] "GET /user/list HTTP/1.1" 200 -
106.51.242.168 - - [14/Jul/2017 07:22:02] "GET /category/list HTTP/1.1" 200 -
106.51.242.168 - - [14/Jul/2017 07:44:55] "GET /user/list HTTP/1.1" 200 -
106.51.242.168 - - [14/Jul/2017 07:44:55] "GET /category/list HTTP/1.1" 200 -
106.51.242.168 - - [14/Jul/2017 07:46:42] "GET /user/list HTTP/1.1" 200 -
106.51.242.168 - - [14/Jul/2017 07:46:42] "GET /category/list HTTP/1.1" 200 -
106.51.135.248 - - [14/Jul/2017 08:02:17] "GET /user/list HTTP/1.1" 200 -
106.51.135.248 - - [14/Jul/2017 08:02:17] "GET /category/list HTTP/1.1" 200 -
106.51.135.248 - - [14/Jul/2017 08:02:46] "GET /user/list HTTP/1.1" 200 -
106.51.135.248 - - [14/Jul/2017 08:02:47] "GET /category/list HTTP/1.1" 200 -
106.51.135.248 - - [14/Jul/2017 08:10:49] "GET /user/list HTTP/1.1" 200 -
106.51.135.248 - - [14/Jul/2017 08:10:50] "GET /category/list HTTP/1.1" 200 -
106.51.135.248 - - [14/Jul/2017 08:21:24] "GET /user/list HTTP/1.1" 200 -
106.51.135.248 - - [14/Jul/2017 08:21:24] "GET /category/list HTTP/1.1" 200 -
106.51.135.248 - - [14/Jul/2017 08:22:14] "GET /user/list HTTP/1.1" 200 -
106.51.135.248 - - [14/Jul/2017 08:22:14] "GET /category/list HTTP/1.1" 200 -
106.51.135.248 - - [14/Jul/2017 08:26:38] "GET /user/list HTTP/1.1" 200 -
106.51.135.248 - - [14/Jul/2017 08:26:38] "GET /category/list HTTP/1.1" 200 -
106.51.135.248 - - [14/Jul/2017 08:28:01] "GET /user/list HTTP/1.1" 200 -
106.51.135.248 - - [14/Jul/2017 08:28:01] "GET /category/list HTTP/1.1" 200 -
106.51.135.248 - - [14/Jul/2017 09:13:22] "GET /user/list HTTP/1.1" 200 -
106.51.135.248 - - [14/Jul/2017 09:13:22] "GET /category/list HTTP/1.1" 200 -
106.51.135.248 - - [14/Jul/2017 09:14:56] "GET /user/list HTTP/1.1" 200 -
106.51.135.248 - - [14/Jul/2017 09:14:56] "GET /category/list HTTP/1.1" 200 -
106.51.135.248 - - [14/Jul/2017 09:16:06] "GET /user/list HTTP/1.1" 200 -
106.51.135.248 - - [14/Jul/2017 09:16:06] "GET /category/list HTTP/1.1" 200 -
106.51.135.248 - - [14/Jul/2017 09:20:20] "GET /user/list HTTP/1.1" 200 -
106.51.135.248 - - [14/Jul/2017 09:20:21] "GET /category/list HTTP/1.1" 200 -
106.51.137.168 - - [14/Jul/2017 09:29:19] "GET /user/list HTTP/1.1" 200 -
106.51.137.168 - - [14/Jul/2017 09:29:19] "GET /category/list HTTP/1.1" 200 -
106.51.137.168 - - [14/Jul/2017 09:32:00] "GET /user/list HTTP/1.1" 200 -
106.51.137.168 - - [14/Jul/2017 09:32:00] "GET /category/list HTTP/1.1" 200 -
169.54.233.116 - - [14/Jul/2017 09:44:12] "GET / HTTP/1.1" 404 -
169.54.233.116 - - [14/Jul/2017 09:44:14] "GET / HTTP/1.1" 404 -
169.54.233.116 - - [14/Jul/2017 09:44:16] "GET / HTTP/1.1" 404 -
169.54.233.116 - - [14/Jul/2017 09:44:22] "GET / HTTP/1.1" 404 -
106.51.128.247 - - [14/Jul/2017 10:19:57] "GET /user/list HTTP/1.1" 200 -
106.51.128.247 - - [14/Jul/2017 10:19:57] "GET /category/list HTTP/1.1" 200 -
164.52.0.133 - - [14/Jul/2017 10:41:57] code 400, message Bad HTTP/0.9 request type ('\x16\x03\x01\x01"\x01\x00\x01')
164.52.0.133 - - [14/Jul/2017 10:41:57] "" ùÿ$rJ/È0{ KÑ^òÞä¨"Cß  À0À,À(À$ÀÀ" HTTPStatus.BAD_REQUEST -
164.52.0.133 - - [14/Jul/2017 10:42:00] "GET / HTTP/1.1" 404 -
106.51.128.247 - - [14/Jul/2017 10:52:31] "GET /user/list HTTP/1.1" 200 -
106.51.128.247 - - [14/Jul/2017 10:52:31] "GET /category/list HTTP/1.1" 200 -
106.51.128.247 - - [14/Jul/2017 10:54:34] "GET /user/list HTTP/1.1" 200 -
106.51.128.247 - - [14/Jul/2017 10:54:34] "GET /category/list HTTP/1.1" 200 -
106.51.128.247 - - [14/Jul/2017 10:57:37] "GET /user/list HTTP/1.1" 200 -
106.51.128.247 - - [14/Jul/2017 10:57:37] "GET /category/list HTTP/1.1" 200 -
106.51.128.247 - - [14/Jul/2017 11:00:27] "GET /user/list HTTP/1.1" 200 -
106.51.128.247 - - [14/Jul/2017 11:00:27] "GET /category/list HTTP/1.1" 200 -
106.51.128.247 - - [14/Jul/2017 11:08:31] "GET /user/list HTTP/1.1" 200 -
106.51.128.247 - - [14/Jul/2017 11:08:32] "GET /category/list HTTP/1.1" 200 -
106.51.128.247 - - [14/Jul/2017 11:09:28] "GET /user/list HTTP/1.1" 200 -
106.51.128.247 - - [14/Jul/2017 11:09:28] "GET /category/list HTTP/1.1" 200 -
106.51.128.247 - - [14/Jul/2017 11:10:13] "GET /user/list HTTP/1.1" 200 -
106.51.128.247 - - [14/Jul/2017 11:10:13] "GET /category/list HTTP/1.1" 200 -
106.51.128.247 - - [14/Jul/2017 11:14:45] "GET /user/list HTTP/1.1" 200 -
106.51.128.247 - - [14/Jul/2017 11:14:45] "GET /category/list HTTP/1.1" 200 -
 * Running on http://0.0.0.0:5000/ (Press CTRL+C to quit)
 * Restarting with stat
 * Debugger is active!
 * Debugger PIN: 135-965-059
106.51.128.247 - - [15/Jul/2017 08:23:27] "GET /user/list HTTP/1.1" 200 -
106.51.128.247 - - [15/Jul/2017 08:23:27] "GET /category/list HTTP/1.1" 200 -
106.51.128.247 - - [15/Jul/2017 08:24:15] "GET /category/search?search=lg HTTP/1.1" 200 -
106.51.128.247 - - [15/Jul/2017 08:25:06] "GET /category/search?search=new HTTP/1.1" 200 -
106.51.128.247 - - [15/Jul/2017 08:28:47] "GET /category/search?search=ne HTTP/1.1" 200 -
106.51.128.247 - - [15/Jul/2017 08:28:48] "GET /category/search?search=ne HTTP/1.1" 200 -
66.249.82.192 - - [15/Jul/2017 09:39:16] "GET /user/list HTTP/1.1" 200 -
66.249.82.223 - - [15/Jul/2017 09:39:16] "GET /category/list HTTP/1.1" 200 -
66.249.82.223 - - [15/Jul/2017 09:39:24] "GET /category/search?search=Lg HTTP/1.1" 200 -
5.188.11.103 - - [15/Jul/2017 20:40:50] code 400, message Bad HTTP/0.9 request type ("\x03\x00\x00,'à\x00\x00\x00\x00\x00Cookie:")
5.188.11.103 - - [15/Jul/2017 20:40:50] "  ,'à     Cookie: mstshash=eltons" HTTPStatus.BAD_REQUEST -
103.227.97.36 - - [16/Jul/2017 08:51:00] "GET /user/list HTTP/1.1" 200 -
103.227.97.36 - - [16/Jul/2017 08:51:00] "GET /category/list HTTP/1.1" 200 -
103.227.97.36 - - [16/Jul/2017 08:51:30] "GET /category/search?search=lg HTTP/1.1" 200 -
47.31.2.12 - - [16/Jul/2017 09:20:41] "GET /user/list HTTP/1.1" 200 -
47.31.2.12 - - [16/Jul/2017 09:20:41] "GET /category/list HTTP/1.1" 200 -
